[2024-05-04 18:56:26,847][flwr][INFO] - Starting Flower simulation, config: num_rounds=5, no round_timeout
[2024-05-04 18:56:34,915][flwr][INFO] - Flower VCE: Ray initialized with resources: {'object_store_memory': 713190604.0, 'memory': 1426381211.0, 'node:127.0.0.1': 1.0, 'CPU': 8.0, 'node:__internal_head__': 1.0}
[2024-05-04 18:56:34,915][flwr][INFO] - Optimize your simulation with Flower VCE: https://flower.ai/docs/framework/how-to-run-simulations.html
[2024-05-04 18:56:34,915][flwr][INFO] - Flower VCE: Resources for each Virtual Client: {'num_cpus': 1, 'num_gpus': 0.0}
[2024-05-04 18:56:34,951][flwr][INFO] - Flower VCE: Creating VirtualClientEngineActorPool with 8 actors
[2024-05-04 18:56:34,951][flwr][INFO] - [INIT]
[2024-05-04 18:56:34,951][flwr][INFO] - Requesting initial parameters from one random client
[2024-05-04 18:56:47,656][flwr][INFO] - Received initial parameters from one random client
[2024-05-04 18:56:47,656][flwr][INFO] - Evaluating initial global parameters
[2024-05-04 18:56:51,786][flwr][INFO] - initial parameters (loss, other metrics): 182.12363028526306, {'accuracy': 0.1024}
[2024-05-04 18:56:51,786][flwr][INFO] - 
[2024-05-04 18:56:51,786][flwr][INFO] - [ROUND 1]
[2024-05-04 18:56:51,786][flwr][INFO] - configure_fit: strategy sampled 10 clients (out of 10)
[2024-05-04 18:57:40,654][flwr][ERROR] - Traceback (most recent call last):
  File "C:\Users\HP\anaconda3\envs\FedLearnCD\Lib\site-packages\flwr\simulation\ray_transport\ray_client_proxy.py", line 73, in _submit_job
    out_mssg, updated_context = self.actor_pool.get_client_result(
                                ^^^^^^^^^^^^^^^^^^^^^^^^^^^^^^^^^^
  File "C:\Users\HP\anaconda3\envs\FedLearnCD\Lib\site-packages\flwr\simulation\ray_transport\ray_actor.py", line 399, in get_client_result
    return self._fetch_future_result(cid)
           ^^^^^^^^^^^^^^^^^^^^^^^^^^^^^^
  File "C:\Users\HP\anaconda3\envs\FedLearnCD\Lib\site-packages\flwr\simulation\ray_transport\ray_actor.py", line 280, in _fetch_future_result
    res_cid, out_mssg, updated_context = ray.get(
                                         ^^^^^^^^
  File "C:\Users\HP\anaconda3\envs\FedLearnCD\Lib\site-packages\ray\_private\auto_init_hook.py", line 21, in auto_init_wrapper
    return fn(*args, **kwargs)
           ^^^^^^^^^^^^^^^^^^^
  File "C:\Users\HP\anaconda3\envs\FedLearnCD\Lib\site-packages\ray\_private\client_mode_hook.py", line 103, in wrapper
    return func(*args, **kwargs)
           ^^^^^^^^^^^^^^^^^^^^^
  File "C:\Users\HP\anaconda3\envs\FedLearnCD\Lib\site-packages\ray\_private\worker.py", line 2623, in get
    values, debugger_breakpoint = worker.get_objects(object_refs, timeout=timeout)
                                  ^^^^^^^^^^^^^^^^^^^^^^^^^^^^^^^^^^^^^^^^^^^^^^^^
  File "C:\Users\HP\anaconda3\envs\FedLearnCD\Lib\site-packages\ray\_private\worker.py", line 861, in get_objects
    raise value.as_instanceof_cause()
ray.exceptions.RayTaskError(ClientAppException): [36mray::ClientAppActor.run()[39m (pid=7784, ip=127.0.0.1, actor_id=2cbdc8544e8a8939f585e68b01000000, repr=<flwr.simulation.ray_transport.ray_actor.ClientAppActor object at 0x0000012E68D36350>)
                  ^^^^^^^^^^^^^^^^^^^^^^^^^^^^^^^^^^^^^
  File "C:\Users\HP\anaconda3\envs\FedLearnCD\Lib\site-packages\flwr\client\client_app.py", line 98, in __call__
    return self._call(message, context)
           ^^^^^^^^^^^^^^^^^^^^^^^^^^^^
  File "C:\Users\HP\anaconda3\envs\FedLearnCD\Lib\site-packages\flwr\client\client_app.py", line 81, in ffn
    out_message = handle_legacy_message_from_msgtype(
                  ^^^^^^^^^^^^^^^^^^^^^^^^^^^^^^^^^^^
  File "C:\Users\HP\anaconda3\envs\FedLearnCD\Lib\site-packages\flwr\client\message_handler\message_handler.py", line 130, in handle_legacy_message_from_msgtype
    fit_res = maybe_call_fit(
              ^^^^^^^^^^^^^^^
  File "C:\Users\HP\anaconda3\envs\FedLearnCD\Lib\site-packages\flwr\client\client.py", line 234, in maybe_call_fit
    return client.fit(fit_ins)
           ^^^^^^^^^^^^^^^^^^^
  File "C:\Users\HP\anaconda3\envs\FedLearnCD\Lib\site-packages\flwr\client\numpy_client.py", line 238, in _fit
    results = self.numpy_client.fit(parameters, ins.config)  # type: ignore
              ^^^^^^^^^^^^^^^^^^^^^^^^^^^^^^^^^^^^^^^^^^^^^
  File "C:\Users\HP\Documents\FedAvgWithDrift\client.py", line 48, in fit
    train(self.model, self.trainloader,optim, epochs, self.device)
  File "C:\Users\HP\Documents\FedAvgWithDrift\model.py", line 32, in train
    for images, labels in trainloader:
  File "C:\Users\HP\anaconda3\envs\FedLearnCD\Lib\site-packages\torch\utils\data\dataloader.py", line 439, in __iter__
    return self._get_iterator()
           ^^^^^^^^^^^^^^^^^^^^
  File "C:\Users\HP\anaconda3\envs\FedLearnCD\Lib\site-packages\torch\utils\data\dataloader.py", line 387, in _get_iterator
    return _MultiProcessingDataLoaderIter(self)
           ^^^^^^^^^^^^^^^^^^^^^^^^^^^^^^^^^^^^
  File "C:\Users\HP\anaconda3\envs\FedLearnCD\Lib\site-packages\torch\utils\data\dataloader.py", line 1040, in __init__
    w.start()
  File "C:\Users\HP\anaconda3\envs\FedLearnCD\Lib\multiprocessing\process.py", line 121, in start
    self._popen = self._Popen(self)
                  ^^^^^^^^^^^^^^^^^
  File "C:\Users\HP\anaconda3\envs\FedLearnCD\Lib\multiprocessing\context.py", line 224, in _Popen
    return _default_context.get_context().Process._Popen(process_obj)
           ^^^^^^^^^^^^^^^^^^^^^^^^^^^^^^^^^^^^^^^^^^^^^^^^^^^^^^^^^^
  File "C:\Users\HP\anaconda3\envs\FedLearnCD\Lib\multiprocessing\context.py", line 336, in _Popen
    return Popen(process_obj)
           ^^^^^^^^^^^^^^^^^^
  File "C:\Users\HP\anaconda3\envs\FedLearnCD\Lib\multiprocessing\popen_spawn_win32.py", line 95, in __init__
    reduction.dump(process_obj, to_child)
  File "C:\Users\HP\anaconda3\envs\FedLearnCD\Lib\multiprocessing\reduction.py", line 60, in dump
    ForkingPickler(file, protocol).dump(obj)
OSError: [Errno 22] Invalid argument

The above exception was the direct cause of the following exception:

[36mray::ClientAppActor.run()[39m (pid=7784, ip=127.0.0.1, actor_id=2cbdc8544e8a8939f585e68b01000000, repr=<flwr.simulation.ray_transport.ray_actor.ClientAppActor object at 0x0000012E68D36350>)
  File "python\ray\_raylet.pyx", line 1881, in ray._raylet.execute_task
  File "python\ray\_raylet.pyx", line 1982, in ray._raylet.execute_task
  File "python\ray\_raylet.pyx", line 1887, in ray._raylet.execute_task
  File "python\ray\_raylet.pyx", line 1828, in ray._raylet.execute_task.function_executor
  File "C:\Users\HP\anaconda3\envs\FedLearnCD\Lib\site-packages\ray\_private\function_manager.py", line 691, in actor_method_executor
    return method(__ray_actor, *args, **kwargs)
           ^^^^^^^^^^^^^^^^^^^^^^^^^^^^^^^^^^^^
  File "C:\Users\HP\anaconda3\envs\FedLearnCD\Lib\site-packages\ray\util\tracing\tracing_helper.py", line 467, in _resume_span
    return method(self, *_args, **_kwargs)
           ^^^^^^^^^^^^^^^^^^^^^^^^^^^^^^^
  File "C:\Users\HP\anaconda3\envs\FedLearnCD\Lib\site-packages\flwr\simulation\ray_transport\ray_actor.py", line 64, in run
    raise ClientAppException(str(ex)) from ex
flwr.client.client_app.ClientAppException: 
Exception ClientAppException occurred. Message: [Errno 22] Invalid argument

[2024-05-04 18:57:40,654][flwr][ERROR] - Traceback (most recent call last):
  File "C:\Users\HP\anaconda3\envs\FedLearnCD\Lib\site-packages\flwr\simulation\ray_transport\ray_client_proxy.py", line 73, in _submit_job
    out_mssg, updated_context = self.actor_pool.get_client_result(
                                ^^^^^^^^^^^^^^^^^^^^^^^^^^^^^^^^^^
  File "C:\Users\HP\anaconda3\envs\FedLearnCD\Lib\site-packages\flwr\simulation\ray_transport\ray_actor.py", line 399, in get_client_result
    return self._fetch_future_result(cid)
           ^^^^^^^^^^^^^^^^^^^^^^^^^^^^^^
  File "C:\Users\HP\anaconda3\envs\FedLearnCD\Lib\site-packages\flwr\simulation\ray_transport\ray_actor.py", line 280, in _fetch_future_result
    res_cid, out_mssg, updated_context = ray.get(
                                         ^^^^^^^^
  File "C:\Users\HP\anaconda3\envs\FedLearnCD\Lib\site-packages\ray\_private\auto_init_hook.py", line 21, in auto_init_wrapper
    return fn(*args, **kwargs)
           ^^^^^^^^^^^^^^^^^^^
  File "C:\Users\HP\anaconda3\envs\FedLearnCD\Lib\site-packages\ray\_private\client_mode_hook.py", line 103, in wrapper
    return func(*args, **kwargs)
           ^^^^^^^^^^^^^^^^^^^^^
  File "C:\Users\HP\anaconda3\envs\FedLearnCD\Lib\site-packages\ray\_private\worker.py", line 2623, in get
    values, debugger_breakpoint = worker.get_objects(object_refs, timeout=timeout)
                                  ^^^^^^^^^^^^^^^^^^^^^^^^^^^^^^^^^^^^^^^^^^^^^^^^
  File "C:\Users\HP\anaconda3\envs\FedLearnCD\Lib\site-packages\ray\_private\worker.py", line 861, in get_objects
    raise value.as_instanceof_cause()
ray.exceptions.RayTaskError(ClientAppException): [36mray::ClientAppActor.run()[39m (pid=14776, ip=127.0.0.1, actor_id=4f3d713b9f2eb56d075e233801000000, repr=<flwr.simulation.ray_transport.ray_actor.ClientAppActor object at 0x00000193D8326350>)
                  ^^^^^^^^^^^^^^^^^^^^^^^^^^^^^^^^^^^^^
  File "C:\Users\HP\anaconda3\envs\FedLearnCD\Lib\site-packages\flwr\client\client_app.py", line 98, in __call__
    return self._call(message, context)
           ^^^^^^^^^^^^^^^^^^^^^^^^^^^^
  File "C:\Users\HP\anaconda3\envs\FedLearnCD\Lib\site-packages\flwr\client\client_app.py", line 81, in ffn
    out_message = handle_legacy_message_from_msgtype(
                  ^^^^^^^^^^^^^^^^^^^^^^^^^^^^^^^^^^^
  File "C:\Users\HP\anaconda3\envs\FedLearnCD\Lib\site-packages\flwr\client\message_handler\message_handler.py", line 130, in handle_legacy_message_from_msgtype
    fit_res = maybe_call_fit(
              ^^^^^^^^^^^^^^^
  File "C:\Users\HP\anaconda3\envs\FedLearnCD\Lib\site-packages\flwr\client\client.py", line 234, in maybe_call_fit
    return client.fit(fit_ins)
           ^^^^^^^^^^^^^^^^^^^
  File "C:\Users\HP\anaconda3\envs\FedLearnCD\Lib\site-packages\flwr\client\numpy_client.py", line 238, in _fit
    results = self.numpy_client.fit(parameters, ins.config)  # type: ignore
              ^^^^^^^^^^^^^^^^^^^^^^^^^^^^^^^^^^^^^^^^^^^^^
  File "C:\Users\HP\Documents\FedAvgWithDrift\client.py", line 48, in fit
    train(self.model, self.trainloader,optim, epochs, self.device)
  File "C:\Users\HP\Documents\FedAvgWithDrift\model.py", line 32, in train
    for images, labels in trainloader:
  File "C:\Users\HP\anaconda3\envs\FedLearnCD\Lib\site-packages\torch\utils\data\dataloader.py", line 439, in __iter__
    return self._get_iterator()
           ^^^^^^^^^^^^^^^^^^^^
  File "C:\Users\HP\anaconda3\envs\FedLearnCD\Lib\site-packages\torch\utils\data\dataloader.py", line 387, in _get_iterator
    return _MultiProcessingDataLoaderIter(self)
           ^^^^^^^^^^^^^^^^^^^^^^^^^^^^^^^^^^^^
  File "C:\Users\HP\anaconda3\envs\FedLearnCD\Lib\site-packages\torch\utils\data\dataloader.py", line 1040, in __init__
    w.start()
  File "C:\Users\HP\anaconda3\envs\FedLearnCD\Lib\multiprocessing\process.py", line 121, in start
    self._popen = self._Popen(self)
                  ^^^^^^^^^^^^^^^^^
  File "C:\Users\HP\anaconda3\envs\FedLearnCD\Lib\multiprocessing\context.py", line 224, in _Popen
    return _default_context.get_context().Process._Popen(process_obj)
           ^^^^^^^^^^^^^^^^^^^^^^^^^^^^^^^^^^^^^^^^^^^^^^^^^^^^^^^^^^
  File "C:\Users\HP\anaconda3\envs\FedLearnCD\Lib\multiprocessing\context.py", line 336, in _Popen
    return Popen(process_obj)
           ^^^^^^^^^^^^^^^^^^
  File "C:\Users\HP\anaconda3\envs\FedLearnCD\Lib\multiprocessing\popen_spawn_win32.py", line 95, in __init__
    reduction.dump(process_obj, to_child)
  File "C:\Users\HP\anaconda3\envs\FedLearnCD\Lib\multiprocessing\reduction.py", line 60, in dump
    ForkingPickler(file, protocol).dump(obj)
OSError: [Errno 22] Invalid argument

The above exception was the direct cause of the following exception:

[36mray::ClientAppActor.run()[39m (pid=14776, ip=127.0.0.1, actor_id=4f3d713b9f2eb56d075e233801000000, repr=<flwr.simulation.ray_transport.ray_actor.ClientAppActor object at 0x00000193D8326350>)
  File "python\ray\_raylet.pyx", line 1881, in ray._raylet.execute_task
  File "python\ray\_raylet.pyx", line 1982, in ray._raylet.execute_task
  File "python\ray\_raylet.pyx", line 1887, in ray._raylet.execute_task
  File "python\ray\_raylet.pyx", line 1828, in ray._raylet.execute_task.function_executor
  File "C:\Users\HP\anaconda3\envs\FedLearnCD\Lib\site-packages\ray\_private\function_manager.py", line 691, in actor_method_executor
    return method(__ray_actor, *args, **kwargs)
           ^^^^^^^^^^^^^^^^^^^^^^^^^^^^^^^^^^^^
  File "C:\Users\HP\anaconda3\envs\FedLearnCD\Lib\site-packages\ray\util\tracing\tracing_helper.py", line 467, in _resume_span
    return method(self, *_args, **_kwargs)
           ^^^^^^^^^^^^^^^^^^^^^^^^^^^^^^^
  File "C:\Users\HP\anaconda3\envs\FedLearnCD\Lib\site-packages\flwr\simulation\ray_transport\ray_actor.py", line 64, in run
    raise ClientAppException(str(ex)) from ex
flwr.client.client_app.ClientAppException: 
Exception ClientAppException occurred. Message: [Errno 22] Invalid argument

[2024-05-04 18:57:40,738][flwr][ERROR] - [36mray::ClientAppActor.run()[39m (pid=7784, ip=127.0.0.1, actor_id=2cbdc8544e8a8939f585e68b01000000, repr=<flwr.simulation.ray_transport.ray_actor.ClientAppActor object at 0x0000012E68D36350>)
                  ^^^^^^^^^^^^^^^^^^^^^^^^^^^^^^^^^^^^^
  File "C:\Users\HP\anaconda3\envs\FedLearnCD\Lib\site-packages\flwr\client\client_app.py", line 98, in __call__
    return self._call(message, context)
           ^^^^^^^^^^^^^^^^^^^^^^^^^^^^
  File "C:\Users\HP\anaconda3\envs\FedLearnCD\Lib\site-packages\flwr\client\client_app.py", line 81, in ffn
    out_message = handle_legacy_message_from_msgtype(
                  ^^^^^^^^^^^^^^^^^^^^^^^^^^^^^^^^^^^
  File "C:\Users\HP\anaconda3\envs\FedLearnCD\Lib\site-packages\flwr\client\message_handler\message_handler.py", line 130, in handle_legacy_message_from_msgtype
    fit_res = maybe_call_fit(
              ^^^^^^^^^^^^^^^
  File "C:\Users\HP\anaconda3\envs\FedLearnCD\Lib\site-packages\flwr\client\client.py", line 234, in maybe_call_fit
    return client.fit(fit_ins)
           ^^^^^^^^^^^^^^^^^^^
  File "C:\Users\HP\anaconda3\envs\FedLearnCD\Lib\site-packages\flwr\client\numpy_client.py", line 238, in _fit
    results = self.numpy_client.fit(parameters, ins.config)  # type: ignore
              ^^^^^^^^^^^^^^^^^^^^^^^^^^^^^^^^^^^^^^^^^^^^^
  File "C:\Users\HP\Documents\FedAvgWithDrift\client.py", line 48, in fit
    train(self.model, self.trainloader,optim, epochs, self.device)
  File "C:\Users\HP\Documents\FedAvgWithDrift\model.py", line 32, in train
    for images, labels in trainloader:
  File "C:\Users\HP\anaconda3\envs\FedLearnCD\Lib\site-packages\torch\utils\data\dataloader.py", line 439, in __iter__
    return self._get_iterator()
           ^^^^^^^^^^^^^^^^^^^^
  File "C:\Users\HP\anaconda3\envs\FedLearnCD\Lib\site-packages\torch\utils\data\dataloader.py", line 387, in _get_iterator
    return _MultiProcessingDataLoaderIter(self)
           ^^^^^^^^^^^^^^^^^^^^^^^^^^^^^^^^^^^^
  File "C:\Users\HP\anaconda3\envs\FedLearnCD\Lib\site-packages\torch\utils\data\dataloader.py", line 1040, in __init__
    w.start()
  File "C:\Users\HP\anaconda3\envs\FedLearnCD\Lib\multiprocessing\process.py", line 121, in start
    self._popen = self._Popen(self)
                  ^^^^^^^^^^^^^^^^^
  File "C:\Users\HP\anaconda3\envs\FedLearnCD\Lib\multiprocessing\context.py", line 224, in _Popen
    return _default_context.get_context().Process._Popen(process_obj)
           ^^^^^^^^^^^^^^^^^^^^^^^^^^^^^^^^^^^^^^^^^^^^^^^^^^^^^^^^^^
  File "C:\Users\HP\anaconda3\envs\FedLearnCD\Lib\multiprocessing\context.py", line 336, in _Popen
    return Popen(process_obj)
           ^^^^^^^^^^^^^^^^^^
  File "C:\Users\HP\anaconda3\envs\FedLearnCD\Lib\multiprocessing\popen_spawn_win32.py", line 95, in __init__
    reduction.dump(process_obj, to_child)
  File "C:\Users\HP\anaconda3\envs\FedLearnCD\Lib\multiprocessing\reduction.py", line 60, in dump
    ForkingPickler(file, protocol).dump(obj)
OSError: [Errno 22] Invalid argument

The above exception was the direct cause of the following exception:

[36mray::ClientAppActor.run()[39m (pid=7784, ip=127.0.0.1, actor_id=2cbdc8544e8a8939f585e68b01000000, repr=<flwr.simulation.ray_transport.ray_actor.ClientAppActor object at 0x0000012E68D36350>)
  File "python\ray\_raylet.pyx", line 1881, in ray._raylet.execute_task
  File "python\ray\_raylet.pyx", line 1982, in ray._raylet.execute_task
  File "python\ray\_raylet.pyx", line 1887, in ray._raylet.execute_task
  File "python\ray\_raylet.pyx", line 1828, in ray._raylet.execute_task.function_executor
  File "C:\Users\HP\anaconda3\envs\FedLearnCD\Lib\site-packages\ray\_private\function_manager.py", line 691, in actor_method_executor
    return method(__ray_actor, *args, **kwargs)
           ^^^^^^^^^^^^^^^^^^^^^^^^^^^^^^^^^^^^
  File "C:\Users\HP\anaconda3\envs\FedLearnCD\Lib\site-packages\ray\util\tracing\tracing_helper.py", line 467, in _resume_span
    return method(self, *_args, **_kwargs)
           ^^^^^^^^^^^^^^^^^^^^^^^^^^^^^^^
  File "C:\Users\HP\anaconda3\envs\FedLearnCD\Lib\site-packages\flwr\simulation\ray_transport\ray_actor.py", line 64, in run
    raise ClientAppException(str(ex)) from ex
flwr.client.client_app.ClientAppException: 
Exception ClientAppException occurred. Message: [Errno 22] Invalid argument
[2024-05-04 18:57:40,823][flwr][ERROR] - [36mray::ClientAppActor.run()[39m (pid=14776, ip=127.0.0.1, actor_id=4f3d713b9f2eb56d075e233801000000, repr=<flwr.simulation.ray_transport.ray_actor.ClientAppActor object at 0x00000193D8326350>)
                  ^^^^^^^^^^^^^^^^^^^^^^^^^^^^^^^^^^^^^
  File "C:\Users\HP\anaconda3\envs\FedLearnCD\Lib\site-packages\flwr\client\client_app.py", line 98, in __call__
    return self._call(message, context)
           ^^^^^^^^^^^^^^^^^^^^^^^^^^^^
  File "C:\Users\HP\anaconda3\envs\FedLearnCD\Lib\site-packages\flwr\client\client_app.py", line 81, in ffn
    out_message = handle_legacy_message_from_msgtype(
                  ^^^^^^^^^^^^^^^^^^^^^^^^^^^^^^^^^^^
  File "C:\Users\HP\anaconda3\envs\FedLearnCD\Lib\site-packages\flwr\client\message_handler\message_handler.py", line 130, in handle_legacy_message_from_msgtype
    fit_res = maybe_call_fit(
              ^^^^^^^^^^^^^^^
  File "C:\Users\HP\anaconda3\envs\FedLearnCD\Lib\site-packages\flwr\client\client.py", line 234, in maybe_call_fit
    return client.fit(fit_ins)
           ^^^^^^^^^^^^^^^^^^^
  File "C:\Users\HP\anaconda3\envs\FedLearnCD\Lib\site-packages\flwr\client\numpy_client.py", line 238, in _fit
    results = self.numpy_client.fit(parameters, ins.config)  # type: ignore
              ^^^^^^^^^^^^^^^^^^^^^^^^^^^^^^^^^^^^^^^^^^^^^
  File "C:\Users\HP\Documents\FedAvgWithDrift\client.py", line 48, in fit
    train(self.model, self.trainloader,optim, epochs, self.device)
  File "C:\Users\HP\Documents\FedAvgWithDrift\model.py", line 32, in train
    for images, labels in trainloader:
  File "C:\Users\HP\anaconda3\envs\FedLearnCD\Lib\site-packages\torch\utils\data\dataloader.py", line 439, in __iter__
    return self._get_iterator()
           ^^^^^^^^^^^^^^^^^^^^
  File "C:\Users\HP\anaconda3\envs\FedLearnCD\Lib\site-packages\torch\utils\data\dataloader.py", line 387, in _get_iterator
    return _MultiProcessingDataLoaderIter(self)
           ^^^^^^^^^^^^^^^^^^^^^^^^^^^^^^^^^^^^
  File "C:\Users\HP\anaconda3\envs\FedLearnCD\Lib\site-packages\torch\utils\data\dataloader.py", line 1040, in __init__
    w.start()
  File "C:\Users\HP\anaconda3\envs\FedLearnCD\Lib\multiprocessing\process.py", line 121, in start
    self._popen = self._Popen(self)
                  ^^^^^^^^^^^^^^^^^
  File "C:\Users\HP\anaconda3\envs\FedLearnCD\Lib\multiprocessing\context.py", line 224, in _Popen
    return _default_context.get_context().Process._Popen(process_obj)
           ^^^^^^^^^^^^^^^^^^^^^^^^^^^^^^^^^^^^^^^^^^^^^^^^^^^^^^^^^^
  File "C:\Users\HP\anaconda3\envs\FedLearnCD\Lib\multiprocessing\context.py", line 336, in _Popen
    return Popen(process_obj)
           ^^^^^^^^^^^^^^^^^^
  File "C:\Users\HP\anaconda3\envs\FedLearnCD\Lib\multiprocessing\popen_spawn_win32.py", line 95, in __init__
    reduction.dump(process_obj, to_child)
  File "C:\Users\HP\anaconda3\envs\FedLearnCD\Lib\multiprocessing\reduction.py", line 60, in dump
    ForkingPickler(file, protocol).dump(obj)
OSError: [Errno 22] Invalid argument

The above exception was the direct cause of the following exception:

[36mray::ClientAppActor.run()[39m (pid=14776, ip=127.0.0.1, actor_id=4f3d713b9f2eb56d075e233801000000, repr=<flwr.simulation.ray_transport.ray_actor.ClientAppActor object at 0x00000193D8326350>)
  File "python\ray\_raylet.pyx", line 1881, in ray._raylet.execute_task
  File "python\ray\_raylet.pyx", line 1982, in ray._raylet.execute_task
  File "python\ray\_raylet.pyx", line 1887, in ray._raylet.execute_task
  File "python\ray\_raylet.pyx", line 1828, in ray._raylet.execute_task.function_executor
  File "C:\Users\HP\anaconda3\envs\FedLearnCD\Lib\site-packages\ray\_private\function_manager.py", line 691, in actor_method_executor
    return method(__ray_actor, *args, **kwargs)
           ^^^^^^^^^^^^^^^^^^^^^^^^^^^^^^^^^^^^
  File "C:\Users\HP\anaconda3\envs\FedLearnCD\Lib\site-packages\ray\util\tracing\tracing_helper.py", line 467, in _resume_span
    return method(self, *_args, **_kwargs)
           ^^^^^^^^^^^^^^^^^^^^^^^^^^^^^^^
  File "C:\Users\HP\anaconda3\envs\FedLearnCD\Lib\site-packages\flwr\simulation\ray_transport\ray_actor.py", line 64, in run
    raise ClientAppException(str(ex)) from ex
flwr.client.client_app.ClientAppException: 
Exception ClientAppException occurred. Message: [Errno 22] Invalid argument
[2024-05-04 18:57:51,103][flwr][ERROR] - Traceback (most recent call last):
  File "C:\Users\HP\anaconda3\envs\FedLearnCD\Lib\site-packages\flwr\simulation\ray_transport\ray_client_proxy.py", line 73, in _submit_job
    out_mssg, updated_context = self.actor_pool.get_client_result(
                                ^^^^^^^^^^^^^^^^^^^^^^^^^^^^^^^^^^
  File "C:\Users\HP\anaconda3\envs\FedLearnCD\Lib\site-packages\flwr\simulation\ray_transport\ray_actor.py", line 399, in get_client_result
    return self._fetch_future_result(cid)
           ^^^^^^^^^^^^^^^^^^^^^^^^^^^^^^
  File "C:\Users\HP\anaconda3\envs\FedLearnCD\Lib\site-packages\flwr\simulation\ray_transport\ray_actor.py", line 280, in _fetch_future_result
    res_cid, out_mssg, updated_context = ray.get(
                                         ^^^^^^^^
  File "C:\Users\HP\anaconda3\envs\FedLearnCD\Lib\site-packages\ray\_private\auto_init_hook.py", line 21, in auto_init_wrapper
    return fn(*args, **kwargs)
           ^^^^^^^^^^^^^^^^^^^
  File "C:\Users\HP\anaconda3\envs\FedLearnCD\Lib\site-packages\ray\_private\client_mode_hook.py", line 103, in wrapper
    return func(*args, **kwargs)
           ^^^^^^^^^^^^^^^^^^^^^
  File "C:\Users\HP\anaconda3\envs\FedLearnCD\Lib\site-packages\ray\_private\worker.py", line 2623, in get
    values, debugger_breakpoint = worker.get_objects(object_refs, timeout=timeout)
                                  ^^^^^^^^^^^^^^^^^^^^^^^^^^^^^^^^^^^^^^^^^^^^^^^^
  File "C:\Users\HP\anaconda3\envs\FedLearnCD\Lib\site-packages\ray\_private\worker.py", line 861, in get_objects
    raise value.as_instanceof_cause()
ray.exceptions.RayTaskError(ClientAppException): [36mray::ClientAppActor.run()[39m (pid=14776, ip=127.0.0.1, actor_id=4f3d713b9f2eb56d075e233801000000, repr=<flwr.simulation.ray_transport.ray_actor.ClientAppActor object at 0x00000193D8326350>)
                  ^^^^^^^^^^^^^^^^^^^^^^^^^^^^^^^^^^^^^
  File "C:\Users\HP\anaconda3\envs\FedLearnCD\Lib\site-packages\flwr\client\client_app.py", line 98, in __call__
    return self._call(message, context)
           ^^^^^^^^^^^^^^^^^^^^^^^^^^^^
  File "C:\Users\HP\anaconda3\envs\FedLearnCD\Lib\site-packages\flwr\client\client_app.py", line 81, in ffn
    out_message = handle_legacy_message_from_msgtype(
                  ^^^^^^^^^^^^^^^^^^^^^^^^^^^^^^^^^^^
  File "C:\Users\HP\anaconda3\envs\FedLearnCD\Lib\site-packages\flwr\client\message_handler\message_handler.py", line 130, in handle_legacy_message_from_msgtype
    fit_res = maybe_call_fit(
              ^^^^^^^^^^^^^^^
  File "C:\Users\HP\anaconda3\envs\FedLearnCD\Lib\site-packages\flwr\client\client.py", line 234, in maybe_call_fit
    return client.fit(fit_ins)
           ^^^^^^^^^^^^^^^^^^^
  File "C:\Users\HP\anaconda3\envs\FedLearnCD\Lib\site-packages\flwr\client\numpy_client.py", line 238, in _fit
    results = self.numpy_client.fit(parameters, ins.config)  # type: ignore
              ^^^^^^^^^^^^^^^^^^^^^^^^^^^^^^^^^^^^^^^^^^^^^
  File "C:\Users\HP\Documents\FedAvgWithDrift\client.py", line 48, in fit
    train(self.model, self.trainloader,optim, epochs, self.device)
  File "C:\Users\HP\Documents\FedAvgWithDrift\model.py", line 32, in train
    for images, labels in trainloader:
  File "C:\Users\HP\anaconda3\envs\FedLearnCD\Lib\site-packages\torch\utils\data\dataloader.py", line 439, in __iter__
    return self._get_iterator()
           ^^^^^^^^^^^^^^^^^^^^
  File "C:\Users\HP\anaconda3\envs\FedLearnCD\Lib\site-packages\torch\utils\data\dataloader.py", line 387, in _get_iterator
    return _MultiProcessingDataLoaderIter(self)
           ^^^^^^^^^^^^^^^^^^^^^^^^^^^^^^^^^^^^
  File "C:\Users\HP\anaconda3\envs\FedLearnCD\Lib\site-packages\torch\utils\data\dataloader.py", line 1040, in __init__
    w.start()
  File "C:\Users\HP\anaconda3\envs\FedLearnCD\Lib\multiprocessing\process.py", line 121, in start
    self._popen = self._Popen(self)
                  ^^^^^^^^^^^^^^^^^
  File "C:\Users\HP\anaconda3\envs\FedLearnCD\Lib\multiprocessing\context.py", line 224, in _Popen
    return _default_context.get_context().Process._Popen(process_obj)
           ^^^^^^^^^^^^^^^^^^^^^^^^^^^^^^^^^^^^^^^^^^^^^^^^^^^^^^^^^^
  File "C:\Users\HP\anaconda3\envs\FedLearnCD\Lib\multiprocessing\context.py", line 336, in _Popen
    return Popen(process_obj)
           ^^^^^^^^^^^^^^^^^^
  File "C:\Users\HP\anaconda3\envs\FedLearnCD\Lib\multiprocessing\popen_spawn_win32.py", line 95, in __init__
    reduction.dump(process_obj, to_child)
  File "C:\Users\HP\anaconda3\envs\FedLearnCD\Lib\multiprocessing\reduction.py", line 60, in dump
    ForkingPickler(file, protocol).dump(obj)
OSError: [Errno 22] Invalid argument

The above exception was the direct cause of the following exception:

[36mray::ClientAppActor.run()[39m (pid=14776, ip=127.0.0.1, actor_id=4f3d713b9f2eb56d075e233801000000, repr=<flwr.simulation.ray_transport.ray_actor.ClientAppActor object at 0x00000193D8326350>)
  File "python\ray\_raylet.pyx", line 1881, in ray._raylet.execute_task
  File "python\ray\_raylet.pyx", line 1982, in ray._raylet.execute_task
  File "python\ray\_raylet.pyx", line 1887, in ray._raylet.execute_task
  File "python\ray\_raylet.pyx", line 1828, in ray._raylet.execute_task.function_executor
  File "C:\Users\HP\anaconda3\envs\FedLearnCD\Lib\site-packages\ray\_private\function_manager.py", line 691, in actor_method_executor
    return method(__ray_actor, *args, **kwargs)
           ^^^^^^^^^^^^^^^^^^^^^^^^^^^^^^^^^^^^
  File "C:\Users\HP\anaconda3\envs\FedLearnCD\Lib\site-packages\ray\util\tracing\tracing_helper.py", line 467, in _resume_span
    return method(self, *_args, **_kwargs)
           ^^^^^^^^^^^^^^^^^^^^^^^^^^^^^^^
  File "C:\Users\HP\anaconda3\envs\FedLearnCD\Lib\site-packages\flwr\simulation\ray_transport\ray_actor.py", line 64, in run
    raise ClientAppException(str(ex)) from ex
flwr.client.client_app.ClientAppException: 
Exception ClientAppException occurred. Message: [Errno 22] Invalid argument

[2024-05-04 18:57:51,245][flwr][ERROR] - [36mray::ClientAppActor.run()[39m (pid=14776, ip=127.0.0.1, actor_id=4f3d713b9f2eb56d075e233801000000, repr=<flwr.simulation.ray_transport.ray_actor.ClientAppActor object at 0x00000193D8326350>)
                  ^^^^^^^^^^^^^^^^^^^^^^^^^^^^^^^^^^^^^
  File "C:\Users\HP\anaconda3\envs\FedLearnCD\Lib\site-packages\flwr\client\client_app.py", line 98, in __call__
    return self._call(message, context)
           ^^^^^^^^^^^^^^^^^^^^^^^^^^^^
  File "C:\Users\HP\anaconda3\envs\FedLearnCD\Lib\site-packages\flwr\client\client_app.py", line 81, in ffn
    out_message = handle_legacy_message_from_msgtype(
                  ^^^^^^^^^^^^^^^^^^^^^^^^^^^^^^^^^^^
  File "C:\Users\HP\anaconda3\envs\FedLearnCD\Lib\site-packages\flwr\client\message_handler\message_handler.py", line 130, in handle_legacy_message_from_msgtype
    fit_res = maybe_call_fit(
              ^^^^^^^^^^^^^^^
  File "C:\Users\HP\anaconda3\envs\FedLearnCD\Lib\site-packages\flwr\client\client.py", line 234, in maybe_call_fit
    return client.fit(fit_ins)
           ^^^^^^^^^^^^^^^^^^^
  File "C:\Users\HP\anaconda3\envs\FedLearnCD\Lib\site-packages\flwr\client\numpy_client.py", line 238, in _fit
    results = self.numpy_client.fit(parameters, ins.config)  # type: ignore
              ^^^^^^^^^^^^^^^^^^^^^^^^^^^^^^^^^^^^^^^^^^^^^
  File "C:\Users\HP\Documents\FedAvgWithDrift\client.py", line 48, in fit
    train(self.model, self.trainloader,optim, epochs, self.device)
  File "C:\Users\HP\Documents\FedAvgWithDrift\model.py", line 32, in train
    for images, labels in trainloader:
  File "C:\Users\HP\anaconda3\envs\FedLearnCD\Lib\site-packages\torch\utils\data\dataloader.py", line 439, in __iter__
    return self._get_iterator()
           ^^^^^^^^^^^^^^^^^^^^
  File "C:\Users\HP\anaconda3\envs\FedLearnCD\Lib\site-packages\torch\utils\data\dataloader.py", line 387, in _get_iterator
    return _MultiProcessingDataLoaderIter(self)
           ^^^^^^^^^^^^^^^^^^^^^^^^^^^^^^^^^^^^
  File "C:\Users\HP\anaconda3\envs\FedLearnCD\Lib\site-packages\torch\utils\data\dataloader.py", line 1040, in __init__
    w.start()
  File "C:\Users\HP\anaconda3\envs\FedLearnCD\Lib\multiprocessing\process.py", line 121, in start
    self._popen = self._Popen(self)
                  ^^^^^^^^^^^^^^^^^
  File "C:\Users\HP\anaconda3\envs\FedLearnCD\Lib\multiprocessing\context.py", line 224, in _Popen
    return _default_context.get_context().Process._Popen(process_obj)
           ^^^^^^^^^^^^^^^^^^^^^^^^^^^^^^^^^^^^^^^^^^^^^^^^^^^^^^^^^^
  File "C:\Users\HP\anaconda3\envs\FedLearnCD\Lib\multiprocessing\context.py", line 336, in _Popen
    return Popen(process_obj)
           ^^^^^^^^^^^^^^^^^^
  File "C:\Users\HP\anaconda3\envs\FedLearnCD\Lib\multiprocessing\popen_spawn_win32.py", line 95, in __init__
    reduction.dump(process_obj, to_child)
  File "C:\Users\HP\anaconda3\envs\FedLearnCD\Lib\multiprocessing\reduction.py", line 60, in dump
    ForkingPickler(file, protocol).dump(obj)
OSError: [Errno 22] Invalid argument

The above exception was the direct cause of the following exception:

[36mray::ClientAppActor.run()[39m (pid=14776, ip=127.0.0.1, actor_id=4f3d713b9f2eb56d075e233801000000, repr=<flwr.simulation.ray_transport.ray_actor.ClientAppActor object at 0x00000193D8326350>)
  File "python\ray\_raylet.pyx", line 1881, in ray._raylet.execute_task
  File "python\ray\_raylet.pyx", line 1982, in ray._raylet.execute_task
  File "python\ray\_raylet.pyx", line 1887, in ray._raylet.execute_task
  File "python\ray\_raylet.pyx", line 1828, in ray._raylet.execute_task.function_executor
  File "C:\Users\HP\anaconda3\envs\FedLearnCD\Lib\site-packages\ray\_private\function_manager.py", line 691, in actor_method_executor
    return method(__ray_actor, *args, **kwargs)
           ^^^^^^^^^^^^^^^^^^^^^^^^^^^^^^^^^^^^
  File "C:\Users\HP\anaconda3\envs\FedLearnCD\Lib\site-packages\ray\util\tracing\tracing_helper.py", line 467, in _resume_span
    return method(self, *_args, **_kwargs)
           ^^^^^^^^^^^^^^^^^^^^^^^^^^^^^^^
  File "C:\Users\HP\anaconda3\envs\FedLearnCD\Lib\site-packages\flwr\simulation\ray_transport\ray_actor.py", line 64, in run
    raise ClientAppException(str(ex)) from ex
flwr.client.client_app.ClientAppException: 
Exception ClientAppException occurred. Message: [Errno 22] Invalid argument
[2024-05-04 18:58:23,628][flwr][ERROR] - Traceback (most recent call last):
  File "C:\Users\HP\anaconda3\envs\FedLearnCD\Lib\site-packages\flwr\simulation\ray_transport\ray_client_proxy.py", line 73, in _submit_job
    out_mssg, updated_context = self.actor_pool.get_client_result(
                                ^^^^^^^^^^^^^^^^^^^^^^^^^^^^^^^^^^
  File "C:\Users\HP\anaconda3\envs\FedLearnCD\Lib\site-packages\flwr\simulation\ray_transport\ray_actor.py", line 399, in get_client_result
    return self._fetch_future_result(cid)
           ^^^^^^^^^^^^^^^^^^^^^^^^^^^^^^
  File "C:\Users\HP\anaconda3\envs\FedLearnCD\Lib\site-packages\flwr\simulation\ray_transport\ray_actor.py", line 280, in _fetch_future_result
    res_cid, out_mssg, updated_context = ray.get(
                                         ^^^^^^^^
  File "C:\Users\HP\anaconda3\envs\FedLearnCD\Lib\site-packages\ray\_private\auto_init_hook.py", line 21, in auto_init_wrapper
    return fn(*args, **kwargs)
           ^^^^^^^^^^^^^^^^^^^
  File "C:\Users\HP\anaconda3\envs\FedLearnCD\Lib\site-packages\ray\_private\client_mode_hook.py", line 103, in wrapper
    return func(*args, **kwargs)
           ^^^^^^^^^^^^^^^^^^^^^
  File "C:\Users\HP\anaconda3\envs\FedLearnCD\Lib\site-packages\ray\_private\worker.py", line 2623, in get
    values, debugger_breakpoint = worker.get_objects(object_refs, timeout=timeout)
                                  ^^^^^^^^^^^^^^^^^^^^^^^^^^^^^^^^^^^^^^^^^^^^^^^^
  File "C:\Users\HP\anaconda3\envs\FedLearnCD\Lib\site-packages\ray\_private\worker.py", line 861, in get_objects
    raise value.as_instanceof_cause()
ray.exceptions.RayTaskError(ClientAppException): [36mray::ClientAppActor.run()[39m (pid=6732, ip=127.0.0.1, actor_id=717239a33f56355e105e047201000000, repr=<flwr.simulation.ray_transport.ray_actor.ClientAppActor object at 0x000001F4E96A5050>)
                  ^^^^^^^^^^^^^^^^^^^^^^^^^^^^^^^^^^^^^
  File "C:\Users\HP\anaconda3\envs\FedLearnCD\Lib\site-packages\flwr\client\client_app.py", line 98, in __call__
    return self._call(message, context)
           ^^^^^^^^^^^^^^^^^^^^^^^^^^^^
  File "C:\Users\HP\anaconda3\envs\FedLearnCD\Lib\site-packages\flwr\client\client_app.py", line 81, in ffn
    out_message = handle_legacy_message_from_msgtype(
                  ^^^^^^^^^^^^^^^^^^^^^^^^^^^^^^^^^^^
  File "C:\Users\HP\anaconda3\envs\FedLearnCD\Lib\site-packages\flwr\client\message_handler\message_handler.py", line 130, in handle_legacy_message_from_msgtype
    fit_res = maybe_call_fit(
              ^^^^^^^^^^^^^^^
  File "C:\Users\HP\anaconda3\envs\FedLearnCD\Lib\site-packages\flwr\client\client.py", line 234, in maybe_call_fit
    return client.fit(fit_ins)
           ^^^^^^^^^^^^^^^^^^^
  File "C:\Users\HP\anaconda3\envs\FedLearnCD\Lib\site-packages\flwr\client\numpy_client.py", line 238, in _fit
    results = self.numpy_client.fit(parameters, ins.config)  # type: ignore
              ^^^^^^^^^^^^^^^^^^^^^^^^^^^^^^^^^^^^^^^^^^^^^
  File "C:\Users\HP\Documents\FedAvgWithDrift\client.py", line 48, in fit
    train(self.model, self.trainloader,optim, epochs, self.device)
  File "C:\Users\HP\Documents\FedAvgWithDrift\model.py", line 32, in train
    for images, labels in trainloader:
  File "C:\Users\HP\anaconda3\envs\FedLearnCD\Lib\site-packages\torch\utils\data\dataloader.py", line 439, in __iter__
    return self._get_iterator()
           ^^^^^^^^^^^^^^^^^^^^
  File "C:\Users\HP\anaconda3\envs\FedLearnCD\Lib\site-packages\torch\utils\data\dataloader.py", line 387, in _get_iterator
    return _MultiProcessingDataLoaderIter(self)
           ^^^^^^^^^^^^^^^^^^^^^^^^^^^^^^^^^^^^
  File "C:\Users\HP\anaconda3\envs\FedLearnCD\Lib\site-packages\torch\utils\data\dataloader.py", line 1040, in __init__
    w.start()
  File "C:\Users\HP\anaconda3\envs\FedLearnCD\Lib\multiprocessing\process.py", line 121, in start
    self._popen = self._Popen(self)
                  ^^^^^^^^^^^^^^^^^
  File "C:\Users\HP\anaconda3\envs\FedLearnCD\Lib\multiprocessing\context.py", line 224, in _Popen
    return _default_context.get_context().Process._Popen(process_obj)
           ^^^^^^^^^^^^^^^^^^^^^^^^^^^^^^^^^^^^^^^^^^^^^^^^^^^^^^^^^^
  File "C:\Users\HP\anaconda3\envs\FedLearnCD\Lib\multiprocessing\context.py", line 336, in _Popen
    return Popen(process_obj)
           ^^^^^^^^^^^^^^^^^^
  File "C:\Users\HP\anaconda3\envs\FedLearnCD\Lib\multiprocessing\popen_spawn_win32.py", line 95, in __init__
    reduction.dump(process_obj, to_child)
  File "C:\Users\HP\anaconda3\envs\FedLearnCD\Lib\multiprocessing\reduction.py", line 60, in dump
    ForkingPickler(file, protocol).dump(obj)
OSError: [Errno 22] Invalid argument

The above exception was the direct cause of the following exception:

[36mray::ClientAppActor.run()[39m (pid=6732, ip=127.0.0.1, actor_id=717239a33f56355e105e047201000000, repr=<flwr.simulation.ray_transport.ray_actor.ClientAppActor object at 0x000001F4E96A5050>)
  File "python\ray\_raylet.pyx", line 1881, in ray._raylet.execute_task
  File "python\ray\_raylet.pyx", line 1982, in ray._raylet.execute_task
  File "python\ray\_raylet.pyx", line 1887, in ray._raylet.execute_task
  File "python\ray\_raylet.pyx", line 1828, in ray._raylet.execute_task.function_executor
  File "C:\Users\HP\anaconda3\envs\FedLearnCD\Lib\site-packages\ray\_private\function_manager.py", line 691, in actor_method_executor
    return method(__ray_actor, *args, **kwargs)
           ^^^^^^^^^^^^^^^^^^^^^^^^^^^^^^^^^^^^
  File "C:\Users\HP\anaconda3\envs\FedLearnCD\Lib\site-packages\ray\util\tracing\tracing_helper.py", line 467, in _resume_span
    return method(self, *_args, **_kwargs)
           ^^^^^^^^^^^^^^^^^^^^^^^^^^^^^^^
  File "C:\Users\HP\anaconda3\envs\FedLearnCD\Lib\site-packages\flwr\simulation\ray_transport\ray_actor.py", line 64, in run
    raise ClientAppException(str(ex)) from ex
flwr.client.client_app.ClientAppException: 
Exception ClientAppException occurred. Message: [Errno 22] Invalid argument

[2024-05-04 18:58:23,691][flwr][ERROR] - [36mray::ClientAppActor.run()[39m (pid=6732, ip=127.0.0.1, actor_id=717239a33f56355e105e047201000000, repr=<flwr.simulation.ray_transport.ray_actor.ClientAppActor object at 0x000001F4E96A5050>)
                  ^^^^^^^^^^^^^^^^^^^^^^^^^^^^^^^^^^^^^
  File "C:\Users\HP\anaconda3\envs\FedLearnCD\Lib\site-packages\flwr\client\client_app.py", line 98, in __call__
    return self._call(message, context)
           ^^^^^^^^^^^^^^^^^^^^^^^^^^^^
  File "C:\Users\HP\anaconda3\envs\FedLearnCD\Lib\site-packages\flwr\client\client_app.py", line 81, in ffn
    out_message = handle_legacy_message_from_msgtype(
                  ^^^^^^^^^^^^^^^^^^^^^^^^^^^^^^^^^^^
  File "C:\Users\HP\anaconda3\envs\FedLearnCD\Lib\site-packages\flwr\client\message_handler\message_handler.py", line 130, in handle_legacy_message_from_msgtype
    fit_res = maybe_call_fit(
              ^^^^^^^^^^^^^^^
  File "C:\Users\HP\anaconda3\envs\FedLearnCD\Lib\site-packages\flwr\client\client.py", line 234, in maybe_call_fit
    return client.fit(fit_ins)
           ^^^^^^^^^^^^^^^^^^^
  File "C:\Users\HP\anaconda3\envs\FedLearnCD\Lib\site-packages\flwr\client\numpy_client.py", line 238, in _fit
    results = self.numpy_client.fit(parameters, ins.config)  # type: ignore
              ^^^^^^^^^^^^^^^^^^^^^^^^^^^^^^^^^^^^^^^^^^^^^
  File "C:\Users\HP\Documents\FedAvgWithDrift\client.py", line 48, in fit
    train(self.model, self.trainloader,optim, epochs, self.device)
  File "C:\Users\HP\Documents\FedAvgWithDrift\model.py", line 32, in train
    for images, labels in trainloader:
  File "C:\Users\HP\anaconda3\envs\FedLearnCD\Lib\site-packages\torch\utils\data\dataloader.py", line 439, in __iter__
    return self._get_iterator()
           ^^^^^^^^^^^^^^^^^^^^
  File "C:\Users\HP\anaconda3\envs\FedLearnCD\Lib\site-packages\torch\utils\data\dataloader.py", line 387, in _get_iterator
    return _MultiProcessingDataLoaderIter(self)
           ^^^^^^^^^^^^^^^^^^^^^^^^^^^^^^^^^^^^
  File "C:\Users\HP\anaconda3\envs\FedLearnCD\Lib\site-packages\torch\utils\data\dataloader.py", line 1040, in __init__
    w.start()
  File "C:\Users\HP\anaconda3\envs\FedLearnCD\Lib\multiprocessing\process.py", line 121, in start
    self._popen = self._Popen(self)
                  ^^^^^^^^^^^^^^^^^
  File "C:\Users\HP\anaconda3\envs\FedLearnCD\Lib\multiprocessing\context.py", line 224, in _Popen
    return _default_context.get_context().Process._Popen(process_obj)
           ^^^^^^^^^^^^^^^^^^^^^^^^^^^^^^^^^^^^^^^^^^^^^^^^^^^^^^^^^^
  File "C:\Users\HP\anaconda3\envs\FedLearnCD\Lib\multiprocessing\context.py", line 336, in _Popen
    return Popen(process_obj)
           ^^^^^^^^^^^^^^^^^^
  File "C:\Users\HP\anaconda3\envs\FedLearnCD\Lib\multiprocessing\popen_spawn_win32.py", line 95, in __init__
    reduction.dump(process_obj, to_child)
  File "C:\Users\HP\anaconda3\envs\FedLearnCD\Lib\multiprocessing\reduction.py", line 60, in dump
    ForkingPickler(file, protocol).dump(obj)
OSError: [Errno 22] Invalid argument

The above exception was the direct cause of the following exception:

[36mray::ClientAppActor.run()[39m (pid=6732, ip=127.0.0.1, actor_id=717239a33f56355e105e047201000000, repr=<flwr.simulation.ray_transport.ray_actor.ClientAppActor object at 0x000001F4E96A5050>)
  File "python\ray\_raylet.pyx", line 1881, in ray._raylet.execute_task
  File "python\ray\_raylet.pyx", line 1982, in ray._raylet.execute_task
  File "python\ray\_raylet.pyx", line 1887, in ray._raylet.execute_task
  File "python\ray\_raylet.pyx", line 1828, in ray._raylet.execute_task.function_executor
  File "C:\Users\HP\anaconda3\envs\FedLearnCD\Lib\site-packages\ray\_private\function_manager.py", line 691, in actor_method_executor
    return method(__ray_actor, *args, **kwargs)
           ^^^^^^^^^^^^^^^^^^^^^^^^^^^^^^^^^^^^
  File "C:\Users\HP\anaconda3\envs\FedLearnCD\Lib\site-packages\ray\util\tracing\tracing_helper.py", line 467, in _resume_span
    return method(self, *_args, **_kwargs)
           ^^^^^^^^^^^^^^^^^^^^^^^^^^^^^^^
  File "C:\Users\HP\anaconda3\envs\FedLearnCD\Lib\site-packages\flwr\simulation\ray_transport\ray_actor.py", line 64, in run
    raise ClientAppException(str(ex)) from ex
flwr.client.client_app.ClientAppException: 
Exception ClientAppException occurred. Message: [Errno 22] Invalid argument
[2024-05-04 18:58:30,835][flwr][INFO] - aggregate_fit: received 6 results and 4 failures
[2024-05-04 18:58:30,866][flwr][WARNING] - No fit_metrics_aggregation_fn provided
[2024-05-04 18:58:37,349][flwr][INFO] - fit progress: (1, 167.96564507484436, {'accuracy': 0.2134}, 105.55492480000248)
[2024-05-04 18:58:37,350][flwr][INFO] - configure_evaluate: no clients selected, skipping evaluation
[2024-05-04 18:58:37,351][flwr][INFO] - 
[2024-05-04 18:58:37,352][flwr][INFO] - [ROUND 2]
[2024-05-04 18:58:37,354][flwr][INFO] - configure_fit: strategy sampled 10 clients (out of 10)
[2024-05-04 18:59:41,968][flwr][ERROR] - Traceback (most recent call last):
  File "C:\Users\HP\anaconda3\envs\FedLearnCD\Lib\site-packages\flwr\simulation\ray_transport\ray_client_proxy.py", line 73, in _submit_job
    out_mssg, updated_context = self.actor_pool.get_client_result(
                                ^^^^^^^^^^^^^^^^^^^^^^^^^^^^^^^^^^
  File "C:\Users\HP\anaconda3\envs\FedLearnCD\Lib\site-packages\flwr\simulation\ray_transport\ray_actor.py", line 399, in get_client_result
    return self._fetch_future_result(cid)
           ^^^^^^^^^^^^^^^^^^^^^^^^^^^^^^
  File "C:\Users\HP\anaconda3\envs\FedLearnCD\Lib\site-packages\flwr\simulation\ray_transport\ray_actor.py", line 280, in _fetch_future_result
    res_cid, out_mssg, updated_context = ray.get(
                                         ^^^^^^^^
  File "C:\Users\HP\anaconda3\envs\FedLearnCD\Lib\site-packages\ray\_private\auto_init_hook.py", line 21, in auto_init_wrapper
    return fn(*args, **kwargs)
           ^^^^^^^^^^^^^^^^^^^
  File "C:\Users\HP\anaconda3\envs\FedLearnCD\Lib\site-packages\ray\_private\client_mode_hook.py", line 103, in wrapper
    return func(*args, **kwargs)
           ^^^^^^^^^^^^^^^^^^^^^
  File "C:\Users\HP\anaconda3\envs\FedLearnCD\Lib\site-packages\ray\_private\worker.py", line 2623, in get
    values, debugger_breakpoint = worker.get_objects(object_refs, timeout=timeout)
                                  ^^^^^^^^^^^^^^^^^^^^^^^^^^^^^^^^^^^^^^^^^^^^^^^^
  File "C:\Users\HP\anaconda3\envs\FedLearnCD\Lib\site-packages\ray\_private\worker.py", line 861, in get_objects
    raise value.as_instanceof_cause()
ray.exceptions.RayTaskError(ClientAppException): [36mray::ClientAppActor.run()[39m (pid=6732, ip=127.0.0.1, actor_id=717239a33f56355e105e047201000000, repr=<flwr.simulation.ray_transport.ray_actor.ClientAppActor object at 0x000001F4E96A5050>)
                  ^^^^^^^^^^^^^^^^^^^^^^^^^^^^^^^^^^^^^
  File "C:\Users\HP\anaconda3\envs\FedLearnCD\Lib\site-packages\flwr\client\client_app.py", line 98, in __call__
    return self._call(message, context)
           ^^^^^^^^^^^^^^^^^^^^^^^^^^^^
  File "C:\Users\HP\anaconda3\envs\FedLearnCD\Lib\site-packages\flwr\client\client_app.py", line 81, in ffn
    out_message = handle_legacy_message_from_msgtype(
                  ^^^^^^^^^^^^^^^^^^^^^^^^^^^^^^^^^^^
  File "C:\Users\HP\anaconda3\envs\FedLearnCD\Lib\site-packages\flwr\client\message_handler\message_handler.py", line 130, in handle_legacy_message_from_msgtype
    fit_res = maybe_call_fit(
              ^^^^^^^^^^^^^^^
  File "C:\Users\HP\anaconda3\envs\FedLearnCD\Lib\site-packages\flwr\client\client.py", line 234, in maybe_call_fit
    return client.fit(fit_ins)
           ^^^^^^^^^^^^^^^^^^^
  File "C:\Users\HP\anaconda3\envs\FedLearnCD\Lib\site-packages\flwr\client\numpy_client.py", line 238, in _fit
    results = self.numpy_client.fit(parameters, ins.config)  # type: ignore
              ^^^^^^^^^^^^^^^^^^^^^^^^^^^^^^^^^^^^^^^^^^^^^
  File "C:\Users\HP\Documents\FedAvgWithDrift\client.py", line 48, in fit
    train(self.model, self.trainloader,optim, epochs, self.device)
  File "C:\Users\HP\Documents\FedAvgWithDrift\model.py", line 32, in train
    for images, labels in trainloader:
  File "C:\Users\HP\anaconda3\envs\FedLearnCD\Lib\site-packages\torch\utils\data\dataloader.py", line 439, in __iter__
    return self._get_iterator()
           ^^^^^^^^^^^^^^^^^^^^
  File "C:\Users\HP\anaconda3\envs\FedLearnCD\Lib\site-packages\torch\utils\data\dataloader.py", line 387, in _get_iterator
    return _MultiProcessingDataLoaderIter(self)
           ^^^^^^^^^^^^^^^^^^^^^^^^^^^^^^^^^^^^
  File "C:\Users\HP\anaconda3\envs\FedLearnCD\Lib\site-packages\torch\utils\data\dataloader.py", line 1040, in __init__
    w.start()
  File "C:\Users\HP\anaconda3\envs\FedLearnCD\Lib\multiprocessing\process.py", line 121, in start
    self._popen = self._Popen(self)
                  ^^^^^^^^^^^^^^^^^
  File "C:\Users\HP\anaconda3\envs\FedLearnCD\Lib\multiprocessing\context.py", line 224, in _Popen
    return _default_context.get_context().Process._Popen(process_obj)
           ^^^^^^^^^^^^^^^^^^^^^^^^^^^^^^^^^^^^^^^^^^^^^^^^^^^^^^^^^^
  File "C:\Users\HP\anaconda3\envs\FedLearnCD\Lib\multiprocessing\context.py", line 336, in _Popen
    return Popen(process_obj)
           ^^^^^^^^^^^^^^^^^^
  File "C:\Users\HP\anaconda3\envs\FedLearnCD\Lib\multiprocessing\popen_spawn_win32.py", line 95, in __init__
    reduction.dump(process_obj, to_child)
  File "C:\Users\HP\anaconda3\envs\FedLearnCD\Lib\multiprocessing\reduction.py", line 60, in dump
    ForkingPickler(file, protocol).dump(obj)
OSError: [Errno 22] Invalid argument

The above exception was the direct cause of the following exception:

[36mray::ClientAppActor.run()[39m (pid=6732, ip=127.0.0.1, actor_id=717239a33f56355e105e047201000000, repr=<flwr.simulation.ray_transport.ray_actor.ClientAppActor object at 0x000001F4E96A5050>)
  File "python\ray\_raylet.pyx", line 1881, in ray._raylet.execute_task
  File "python\ray\_raylet.pyx", line 1982, in ray._raylet.execute_task
  File "python\ray\_raylet.pyx", line 1887, in ray._raylet.execute_task
  File "python\ray\_raylet.pyx", line 1828, in ray._raylet.execute_task.function_executor
  File "C:\Users\HP\anaconda3\envs\FedLearnCD\Lib\site-packages\ray\_private\function_manager.py", line 691, in actor_method_executor
    return method(__ray_actor, *args, **kwargs)
           ^^^^^^^^^^^^^^^^^^^^^^^^^^^^^^^^^^^^
  File "C:\Users\HP\anaconda3\envs\FedLearnCD\Lib\site-packages\ray\util\tracing\tracing_helper.py", line 467, in _resume_span
    return method(self, *_args, **_kwargs)
           ^^^^^^^^^^^^^^^^^^^^^^^^^^^^^^^
  File "C:\Users\HP\anaconda3\envs\FedLearnCD\Lib\site-packages\flwr\simulation\ray_transport\ray_actor.py", line 64, in run
    raise ClientAppException(str(ex)) from ex
flwr.client.client_app.ClientAppException: 
Exception ClientAppException occurred. Message: [Errno 22] Invalid argument

[2024-05-04 18:59:47,185][flwr][ERROR] - [36mray::ClientAppActor.run()[39m (pid=6732, ip=127.0.0.1, actor_id=717239a33f56355e105e047201000000, repr=<flwr.simulation.ray_transport.ray_actor.ClientAppActor object at 0x000001F4E96A5050>)
                  ^^^^^^^^^^^^^^^^^^^^^^^^^^^^^^^^^^^^^
  File "C:\Users\HP\anaconda3\envs\FedLearnCD\Lib\site-packages\flwr\client\client_app.py", line 98, in __call__
    return self._call(message, context)
           ^^^^^^^^^^^^^^^^^^^^^^^^^^^^
  File "C:\Users\HP\anaconda3\envs\FedLearnCD\Lib\site-packages\flwr\client\client_app.py", line 81, in ffn
    out_message = handle_legacy_message_from_msgtype(
                  ^^^^^^^^^^^^^^^^^^^^^^^^^^^^^^^^^^^
  File "C:\Users\HP\anaconda3\envs\FedLearnCD\Lib\site-packages\flwr\client\message_handler\message_handler.py", line 130, in handle_legacy_message_from_msgtype
    fit_res = maybe_call_fit(
              ^^^^^^^^^^^^^^^
  File "C:\Users\HP\anaconda3\envs\FedLearnCD\Lib\site-packages\flwr\client\client.py", line 234, in maybe_call_fit
    return client.fit(fit_ins)
           ^^^^^^^^^^^^^^^^^^^
  File "C:\Users\HP\anaconda3\envs\FedLearnCD\Lib\site-packages\flwr\client\numpy_client.py", line 238, in _fit
    results = self.numpy_client.fit(parameters, ins.config)  # type: ignore
              ^^^^^^^^^^^^^^^^^^^^^^^^^^^^^^^^^^^^^^^^^^^^^
  File "C:\Users\HP\Documents\FedAvgWithDrift\client.py", line 48, in fit
    train(self.model, self.trainloader,optim, epochs, self.device)
  File "C:\Users\HP\Documents\FedAvgWithDrift\model.py", line 32, in train
    for images, labels in trainloader:
  File "C:\Users\HP\anaconda3\envs\FedLearnCD\Lib\site-packages\torch\utils\data\dataloader.py", line 439, in __iter__
    return self._get_iterator()
           ^^^^^^^^^^^^^^^^^^^^
  File "C:\Users\HP\anaconda3\envs\FedLearnCD\Lib\site-packages\torch\utils\data\dataloader.py", line 387, in _get_iterator
    return _MultiProcessingDataLoaderIter(self)
           ^^^^^^^^^^^^^^^^^^^^^^^^^^^^^^^^^^^^
  File "C:\Users\HP\anaconda3\envs\FedLearnCD\Lib\site-packages\torch\utils\data\dataloader.py", line 1040, in __init__
    w.start()
  File "C:\Users\HP\anaconda3\envs\FedLearnCD\Lib\multiprocessing\process.py", line 121, in start
    self._popen = self._Popen(self)
                  ^^^^^^^^^^^^^^^^^
  File "C:\Users\HP\anaconda3\envs\FedLearnCD\Lib\multiprocessing\context.py", line 224, in _Popen
    return _default_context.get_context().Process._Popen(process_obj)
           ^^^^^^^^^^^^^^^^^^^^^^^^^^^^^^^^^^^^^^^^^^^^^^^^^^^^^^^^^^
  File "C:\Users\HP\anaconda3\envs\FedLearnCD\Lib\multiprocessing\context.py", line 336, in _Popen
    return Popen(process_obj)
           ^^^^^^^^^^^^^^^^^^
  File "C:\Users\HP\anaconda3\envs\FedLearnCD\Lib\multiprocessing\popen_spawn_win32.py", line 95, in __init__
    reduction.dump(process_obj, to_child)
  File "C:\Users\HP\anaconda3\envs\FedLearnCD\Lib\multiprocessing\reduction.py", line 60, in dump
    ForkingPickler(file, protocol).dump(obj)
OSError: [Errno 22] Invalid argument

The above exception was the direct cause of the following exception:

[36mray::ClientAppActor.run()[39m (pid=6732, ip=127.0.0.1, actor_id=717239a33f56355e105e047201000000, repr=<flwr.simulation.ray_transport.ray_actor.ClientAppActor object at 0x000001F4E96A5050>)
  File "python\ray\_raylet.pyx", line 1881, in ray._raylet.execute_task
  File "python\ray\_raylet.pyx", line 1982, in ray._raylet.execute_task
  File "python\ray\_raylet.pyx", line 1887, in ray._raylet.execute_task
  File "python\ray\_raylet.pyx", line 1828, in ray._raylet.execute_task.function_executor
  File "C:\Users\HP\anaconda3\envs\FedLearnCD\Lib\site-packages\ray\_private\function_manager.py", line 691, in actor_method_executor
    return method(__ray_actor, *args, **kwargs)
           ^^^^^^^^^^^^^^^^^^^^^^^^^^^^^^^^^^^^
  File "C:\Users\HP\anaconda3\envs\FedLearnCD\Lib\site-packages\ray\util\tracing\tracing_helper.py", line 467, in _resume_span
    return method(self, *_args, **_kwargs)
           ^^^^^^^^^^^^^^^^^^^^^^^^^^^^^^^
  File "C:\Users\HP\anaconda3\envs\FedLearnCD\Lib\site-packages\flwr\simulation\ray_transport\ray_actor.py", line 64, in run
    raise ClientAppException(str(ex)) from ex
flwr.client.client_app.ClientAppException: 
Exception ClientAppException occurred. Message: [Errno 22] Invalid argument
