[2024-05-04 17:15:24,109][flwr][INFO] - Starting Flower simulation, config: num_rounds=5, no round_timeout
[2024-05-04 17:15:31,863][flwr][INFO] - Flower VCE: Ray initialized with resources: {'node:__internal_head__': 1.0, 'node:127.0.0.1': 1.0, 'object_store_memory': 447204556.0, 'memory': 894409115.0, 'CPU': 8.0}
[2024-05-04 17:15:31,863][flwr][INFO] - Optimize your simulation with Flower VCE: https://flower.ai/docs/framework/how-to-run-simulations.html
[2024-05-04 17:15:31,863][flwr][INFO] - No `client_resources` specified. Using minimal resources for clients.
[2024-05-04 17:15:31,863][flwr][INFO] - Flower VCE: Resources for each Virtual Client: {'num_cpus': 1, 'num_gpus': 0.0}
[2024-05-04 17:15:31,904][flwr][INFO] - Flower VCE: Creating VirtualClientEngineActorPool with 8 actors
[2024-05-04 17:15:31,907][flwr][INFO] - [INIT]
[2024-05-04 17:15:31,908][flwr][INFO] - Requesting initial parameters from one random client
[2024-05-04 17:15:41,499][flwr][INFO] - Received initial parameters from one random client
[2024-05-04 17:15:41,499][flwr][INFO] - Evaluating initial global parameters
[2024-05-04 17:15:46,537][flwr][INFO] - initial parameters (loss, other metrics): 182.00492143630981, {'accuracy': 0.1114}
[2024-05-04 17:15:46,537][flwr][INFO] - 
[2024-05-04 17:15:46,537][flwr][INFO] - [ROUND 1]
[2024-05-04 17:15:46,537][flwr][INFO] - configure_fit: strategy sampled 10 clients (out of 100)
[2024-05-04 17:18:08,500][flwr][ERROR] - Traceback (most recent call last):
  File "C:\Users\HP\anaconda3\envs\FedLearnCD\Lib\site-packages\flwr\simulation\ray_transport\ray_client_proxy.py", line 73, in _submit_job
    out_mssg, updated_context = self.actor_pool.get_client_result(
                                ^^^^^^^^^^^^^^^^^^^^^^^^^^^^^^^^^^
  File "C:\Users\HP\anaconda3\envs\FedLearnCD\Lib\site-packages\flwr\simulation\ray_transport\ray_actor.py", line 399, in get_client_result
    return self._fetch_future_result(cid)
           ^^^^^^^^^^^^^^^^^^^^^^^^^^^^^^
  File "C:\Users\HP\anaconda3\envs\FedLearnCD\Lib\site-packages\flwr\simulation\ray_transport\ray_actor.py", line 280, in _fetch_future_result
    res_cid, out_mssg, updated_context = ray.get(
                                         ^^^^^^^^
  File "C:\Users\HP\anaconda3\envs\FedLearnCD\Lib\site-packages\ray\_private\auto_init_hook.py", line 21, in auto_init_wrapper
    return fn(*args, **kwargs)
           ^^^^^^^^^^^^^^^^^^^
  File "C:\Users\HP\anaconda3\envs\FedLearnCD\Lib\site-packages\ray\_private\client_mode_hook.py", line 103, in wrapper
    return func(*args, **kwargs)
           ^^^^^^^^^^^^^^^^^^^^^
  File "C:\Users\HP\anaconda3\envs\FedLearnCD\Lib\site-packages\ray\_private\worker.py", line 2623, in get
    values, debugger_breakpoint = worker.get_objects(object_refs, timeout=timeout)
                                  ^^^^^^^^^^^^^^^^^^^^^^^^^^^^^^^^^^^^^^^^^^^^^^^^
  File "C:\Users\HP\anaconda3\envs\FedLearnCD\Lib\site-packages\ray\_private\worker.py", line 861, in get_objects
    raise value.as_instanceof_cause()
ray.exceptions.RayTaskError(ClientAppException): [36mray::ClientAppActor.run()[39m (pid=11684, ip=127.0.0.1, actor_id=3fa14aae79797b3216ec181c01000000, repr=<flwr.simulation.ray_transport.ray_actor.ClientAppActor object at 0x00000214D95DCDD0>)
                  ^^^^^^^^^^^^^^^^^^^^^^^^^^^^^^^^^^^^^
  File "C:\Users\HP\anaconda3\envs\FedLearnCD\Lib\site-packages\flwr\client\client_app.py", line 98, in __call__
    return self._call(message, context)
           ^^^^^^^^^^^^^^^^^^^^^^^^^^^^
  File "C:\Users\HP\anaconda3\envs\FedLearnCD\Lib\site-packages\flwr\client\client_app.py", line 81, in ffn
    out_message = handle_legacy_message_from_msgtype(
                  ^^^^^^^^^^^^^^^^^^^^^^^^^^^^^^^^^^^
  File "C:\Users\HP\anaconda3\envs\FedLearnCD\Lib\site-packages\flwr\client\message_handler\message_handler.py", line 130, in handle_legacy_message_from_msgtype
    fit_res = maybe_call_fit(
              ^^^^^^^^^^^^^^^
  File "C:\Users\HP\anaconda3\envs\FedLearnCD\Lib\site-packages\flwr\client\client.py", line 234, in maybe_call_fit
    return client.fit(fit_ins)
           ^^^^^^^^^^^^^^^^^^^
  File "C:\Users\HP\anaconda3\envs\FedLearnCD\Lib\site-packages\flwr\client\numpy_client.py", line 238, in _fit
    results = self.numpy_client.fit(parameters, ins.config)  # type: ignore
              ^^^^^^^^^^^^^^^^^^^^^^^^^^^^^^^^^^^^^^^^^^^^^
  File "C:\Users\HP\Documents\FedAvgWithDrift\client.py", line 48, in fit
    train(self.model, self.trainloader,optim, epochs, self.device)
  File "C:\Users\HP\Documents\FedAvgWithDrift\model.py", line 32, in train
    for images, labels in trainloader:
  File "C:\Users\HP\anaconda3\envs\FedLearnCD\Lib\site-packages\torch\utils\data\dataloader.py", line 439, in __iter__
    return self._get_iterator()
           ^^^^^^^^^^^^^^^^^^^^
  File "C:\Users\HP\anaconda3\envs\FedLearnCD\Lib\site-packages\torch\utils\data\dataloader.py", line 387, in _get_iterator
    return _MultiProcessingDataLoaderIter(self)
           ^^^^^^^^^^^^^^^^^^^^^^^^^^^^^^^^^^^^
  File "C:\Users\HP\anaconda3\envs\FedLearnCD\Lib\site-packages\torch\utils\data\dataloader.py", line 1040, in __init__
    w.start()
  File "C:\Users\HP\anaconda3\envs\FedLearnCD\Lib\multiprocessing\process.py", line 121, in start
    self._popen = self._Popen(self)
                  ^^^^^^^^^^^^^^^^^
  File "C:\Users\HP\anaconda3\envs\FedLearnCD\Lib\multiprocessing\context.py", line 224, in _Popen
    return _default_context.get_context().Process._Popen(process_obj)
           ^^^^^^^^^^^^^^^^^^^^^^^^^^^^^^^^^^^^^^^^^^^^^^^^^^^^^^^^^^
  File "C:\Users\HP\anaconda3\envs\FedLearnCD\Lib\multiprocessing\context.py", line 336, in _Popen
    return Popen(process_obj)
           ^^^^^^^^^^^^^^^^^^
  File "C:\Users\HP\anaconda3\envs\FedLearnCD\Lib\multiprocessing\popen_spawn_win32.py", line 95, in __init__
    reduction.dump(process_obj, to_child)
  File "C:\Users\HP\anaconda3\envs\FedLearnCD\Lib\multiprocessing\reduction.py", line 60, in dump
    ForkingPickler(file, protocol).dump(obj)
OSError: [Errno 22] Invalid argument

The above exception was the direct cause of the following exception:

[36mray::ClientAppActor.run()[39m (pid=11684, ip=127.0.0.1, actor_id=3fa14aae79797b3216ec181c01000000, repr=<flwr.simulation.ray_transport.ray_actor.ClientAppActor object at 0x00000214D95DCDD0>)
  File "python\ray\_raylet.pyx", line 1881, in ray._raylet.execute_task
  File "python\ray\_raylet.pyx", line 1982, in ray._raylet.execute_task
  File "python\ray\_raylet.pyx", line 1887, in ray._raylet.execute_task
  File "python\ray\_raylet.pyx", line 1828, in ray._raylet.execute_task.function_executor
  File "C:\Users\HP\anaconda3\envs\FedLearnCD\Lib\site-packages\ray\_private\function_manager.py", line 691, in actor_method_executor
    return method(__ray_actor, *args, **kwargs)
           ^^^^^^^^^^^^^^^^^^^^^^^^^^^^^^^^^^^^
  File "C:\Users\HP\anaconda3\envs\FedLearnCD\Lib\site-packages\ray\util\tracing\tracing_helper.py", line 467, in _resume_span
    return method(self, *_args, **_kwargs)
           ^^^^^^^^^^^^^^^^^^^^^^^^^^^^^^^
  File "C:\Users\HP\anaconda3\envs\FedLearnCD\Lib\site-packages\flwr\simulation\ray_transport\ray_actor.py", line 64, in run
    raise ClientAppException(str(ex)) from ex
flwr.client.client_app.ClientAppException: 
Exception ClientAppException occurred. Message: [Errno 22] Invalid argument

[2024-05-04 17:18:08,705][flwr][ERROR] - [36mray::ClientAppActor.run()[39m (pid=11684, ip=127.0.0.1, actor_id=3fa14aae79797b3216ec181c01000000, repr=<flwr.simulation.ray_transport.ray_actor.ClientAppActor object at 0x00000214D95DCDD0>)
                  ^^^^^^^^^^^^^^^^^^^^^^^^^^^^^^^^^^^^^
  File "C:\Users\HP\anaconda3\envs\FedLearnCD\Lib\site-packages\flwr\client\client_app.py", line 98, in __call__
    return self._call(message, context)
           ^^^^^^^^^^^^^^^^^^^^^^^^^^^^
  File "C:\Users\HP\anaconda3\envs\FedLearnCD\Lib\site-packages\flwr\client\client_app.py", line 81, in ffn
    out_message = handle_legacy_message_from_msgtype(
                  ^^^^^^^^^^^^^^^^^^^^^^^^^^^^^^^^^^^
  File "C:\Users\HP\anaconda3\envs\FedLearnCD\Lib\site-packages\flwr\client\message_handler\message_handler.py", line 130, in handle_legacy_message_from_msgtype
    fit_res = maybe_call_fit(
              ^^^^^^^^^^^^^^^
  File "C:\Users\HP\anaconda3\envs\FedLearnCD\Lib\site-packages\flwr\client\client.py", line 234, in maybe_call_fit
    return client.fit(fit_ins)
           ^^^^^^^^^^^^^^^^^^^
  File "C:\Users\HP\anaconda3\envs\FedLearnCD\Lib\site-packages\flwr\client\numpy_client.py", line 238, in _fit
    results = self.numpy_client.fit(parameters, ins.config)  # type: ignore
              ^^^^^^^^^^^^^^^^^^^^^^^^^^^^^^^^^^^^^^^^^^^^^
  File "C:\Users\HP\Documents\FedAvgWithDrift\client.py", line 48, in fit
    train(self.model, self.trainloader,optim, epochs, self.device)
  File "C:\Users\HP\Documents\FedAvgWithDrift\model.py", line 32, in train
    for images, labels in trainloader:
  File "C:\Users\HP\anaconda3\envs\FedLearnCD\Lib\site-packages\torch\utils\data\dataloader.py", line 439, in __iter__
    return self._get_iterator()
           ^^^^^^^^^^^^^^^^^^^^
  File "C:\Users\HP\anaconda3\envs\FedLearnCD\Lib\site-packages\torch\utils\data\dataloader.py", line 387, in _get_iterator
    return _MultiProcessingDataLoaderIter(self)
           ^^^^^^^^^^^^^^^^^^^^^^^^^^^^^^^^^^^^
  File "C:\Users\HP\anaconda3\envs\FedLearnCD\Lib\site-packages\torch\utils\data\dataloader.py", line 1040, in __init__
    w.start()
  File "C:\Users\HP\anaconda3\envs\FedLearnCD\Lib\multiprocessing\process.py", line 121, in start
    self._popen = self._Popen(self)
                  ^^^^^^^^^^^^^^^^^
  File "C:\Users\HP\anaconda3\envs\FedLearnCD\Lib\multiprocessing\context.py", line 224, in _Popen
    return _default_context.get_context().Process._Popen(process_obj)
           ^^^^^^^^^^^^^^^^^^^^^^^^^^^^^^^^^^^^^^^^^^^^^^^^^^^^^^^^^^
  File "C:\Users\HP\anaconda3\envs\FedLearnCD\Lib\multiprocessing\context.py", line 336, in _Popen
    return Popen(process_obj)
           ^^^^^^^^^^^^^^^^^^
  File "C:\Users\HP\anaconda3\envs\FedLearnCD\Lib\multiprocessing\popen_spawn_win32.py", line 95, in __init__
    reduction.dump(process_obj, to_child)
  File "C:\Users\HP\anaconda3\envs\FedLearnCD\Lib\multiprocessing\reduction.py", line 60, in dump
    ForkingPickler(file, protocol).dump(obj)
OSError: [Errno 22] Invalid argument

The above exception was the direct cause of the following exception:

[36mray::ClientAppActor.run()[39m (pid=11684, ip=127.0.0.1, actor_id=3fa14aae79797b3216ec181c01000000, repr=<flwr.simulation.ray_transport.ray_actor.ClientAppActor object at 0x00000214D95DCDD0>)
  File "python\ray\_raylet.pyx", line 1881, in ray._raylet.execute_task
  File "python\ray\_raylet.pyx", line 1982, in ray._raylet.execute_task
  File "python\ray\_raylet.pyx", line 1887, in ray._raylet.execute_task
  File "python\ray\_raylet.pyx", line 1828, in ray._raylet.execute_task.function_executor
  File "C:\Users\HP\anaconda3\envs\FedLearnCD\Lib\site-packages\ray\_private\function_manager.py", line 691, in actor_method_executor
    return method(__ray_actor, *args, **kwargs)
           ^^^^^^^^^^^^^^^^^^^^^^^^^^^^^^^^^^^^
  File "C:\Users\HP\anaconda3\envs\FedLearnCD\Lib\site-packages\ray\util\tracing\tracing_helper.py", line 467, in _resume_span
    return method(self, *_args, **_kwargs)
           ^^^^^^^^^^^^^^^^^^^^^^^^^^^^^^^
  File "C:\Users\HP\anaconda3\envs\FedLearnCD\Lib\site-packages\flwr\simulation\ray_transport\ray_actor.py", line 64, in run
    raise ClientAppException(str(ex)) from ex
flwr.client.client_app.ClientAppException: 
Exception ClientAppException occurred. Message: [Errno 22] Invalid argument
[2024-05-04 17:18:29,634][flwr][INFO] - aggregate_fit: received 9 results and 1 failures
[2024-05-04 17:18:29,688][flwr][WARNING] - No fit_metrics_aggregation_fn provided
[2024-05-04 17:18:36,243][flwr][INFO] - fit progress: (1, 181.75206804275513, {'accuracy': 0.1286}, 169.71951339999214)
[2024-05-04 17:18:36,258][flwr][INFO] - configure_evaluate: strategy sampled 25 clients (out of 100)
