[2024-05-04 17:36:10,869][flwr][INFO] - Starting Flower simulation, config: num_rounds=5, no round_timeout
[2024-05-04 17:36:24,835][flwr][INFO] - Flower VCE: Ray initialized with resources: {'CPU': 8.0, 'object_store_memory': 271215820.0, 'memory': 542431643.0, 'node:127.0.0.1': 1.0, 'node:__internal_head__': 1.0}
[2024-05-04 17:36:24,835][flwr][INFO] - Optimize your simulation with Flower VCE: https://flower.ai/docs/framework/how-to-run-simulations.html
[2024-05-04 17:36:24,835][flwr][INFO] - No `client_resources` specified. Using minimal resources for clients.
[2024-05-04 17:36:24,835][flwr][INFO] - Flower VCE: Resources for each Virtual Client: {'num_cpus': 1, 'num_gpus': 0.0}
[2024-05-04 17:36:24,866][flwr][INFO] - Flower VCE: Creating VirtualClientEngineActorPool with 8 actors
[2024-05-04 17:36:24,872][flwr][INFO] - [INIT]
[2024-05-04 17:36:24,872][flwr][INFO] - Requesting initial parameters from one random client
[2024-05-04 17:36:37,847][flwr][INFO] - Received initial parameters from one random client
[2024-05-04 17:36:37,847][flwr][INFO] - Evaluating initial global parameters
[2024-05-04 17:36:43,261][flwr][INFO] - initial parameters (loss, other metrics): 182.02914953231812, {'accuracy': 0.1005}
[2024-05-04 17:36:43,261][flwr][INFO] - 
[2024-05-04 17:36:43,261][flwr][INFO] - [ROUND 1]
[2024-05-04 17:36:43,261][flwr][INFO] - configure_fit: strategy sampled 10 clients (out of 50)
[2024-05-04 17:38:19,893][flwr][ERROR] - Traceback (most recent call last):
  File "C:\Users\HP\anaconda3\envs\FedLearnCD\Lib\site-packages\flwr\simulation\ray_transport\ray_client_proxy.py", line 73, in _submit_job
    out_mssg, updated_context = self.actor_pool.get_client_result(
                                ^^^^^^^^^^^^^^^^^^^^^^^^^^^^^^^^^^
  File "C:\Users\HP\anaconda3\envs\FedLearnCD\Lib\site-packages\flwr\simulation\ray_transport\ray_actor.py", line 399, in get_client_result
    return self._fetch_future_result(cid)
           ^^^^^^^^^^^^^^^^^^^^^^^^^^^^^^
  File "C:\Users\HP\anaconda3\envs\FedLearnCD\Lib\site-packages\flwr\simulation\ray_transport\ray_actor.py", line 280, in _fetch_future_result
    res_cid, out_mssg, updated_context = ray.get(
                                         ^^^^^^^^
  File "C:\Users\HP\anaconda3\envs\FedLearnCD\Lib\site-packages\ray\_private\auto_init_hook.py", line 24, in auto_init_wrapper
    return fn(*args, **kwargs)
           ^^^^^^^^^^^^^^^^^^^
  File "C:\Users\HP\anaconda3\envs\FedLearnCD\Lib\site-packages\ray\_private\client_mode_hook.py", line 103, in wrapper
    return func(*args, **kwargs)
           ^^^^^^^^^^^^^^^^^^^^^
  File "C:\Users\HP\anaconda3\envs\FedLearnCD\Lib\site-packages\ray\_private\worker.py", line 2524, in get
    raise value.as_instanceof_cause()
ray.exceptions.RayTaskError(ClientAppException): [36mray::ClientAppActor.run()[39m (pid=14104, ip=127.0.0.1, actor_id=ec85611a48f4ac4cc9625ad701000000, repr=<flwr.simulation.ray_transport.ray_actor.ClientAppActor object at 0x00000279798B3F50>)
                  ^^^^^^^^^^^^^^^^^^^^^^^^^^^^^^^^^^^^^
  File "C:\Users\HP\anaconda3\envs\FedLearnCD\Lib\site-packages\flwr\client\client_app.py", line 98, in __call__
    return self._call(message, context)
           ^^^^^^^^^^^^^^^^^^^^^^^^^^^^
  File "C:\Users\HP\anaconda3\envs\FedLearnCD\Lib\site-packages\flwr\client\client_app.py", line 81, in ffn
    out_message = handle_legacy_message_from_msgtype(
                  ^^^^^^^^^^^^^^^^^^^^^^^^^^^^^^^^^^^
  File "C:\Users\HP\anaconda3\envs\FedLearnCD\Lib\site-packages\flwr\client\message_handler\message_handler.py", line 130, in handle_legacy_message_from_msgtype
    fit_res = maybe_call_fit(
              ^^^^^^^^^^^^^^^
  File "C:\Users\HP\anaconda3\envs\FedLearnCD\Lib\site-packages\flwr\client\client.py", line 234, in maybe_call_fit
    return client.fit(fit_ins)
           ^^^^^^^^^^^^^^^^^^^
  File "C:\Users\HP\anaconda3\envs\FedLearnCD\Lib\site-packages\flwr\client\numpy_client.py", line 238, in _fit
    results = self.numpy_client.fit(parameters, ins.config)  # type: ignore
              ^^^^^^^^^^^^^^^^^^^^^^^^^^^^^^^^^^^^^^^^^^^^^
  File "C:\Users\HP\Documents\FedAvgWithDrift\client.py", line 48, in fit
    train(self.model, self.trainloader,optim, epochs, self.device)
  File "C:\Users\HP\Documents\FedAvgWithDrift\model.py", line 32, in train
    for images, labels in trainloader:
  File "C:\Users\HP\anaconda3\envs\FedLearnCD\Lib\site-packages\torch\utils\data\dataloader.py", line 439, in __iter__
    return self._get_iterator()
           ^^^^^^^^^^^^^^^^^^^^
  File "C:\Users\HP\anaconda3\envs\FedLearnCD\Lib\site-packages\torch\utils\data\dataloader.py", line 387, in _get_iterator
    return _MultiProcessingDataLoaderIter(self)
           ^^^^^^^^^^^^^^^^^^^^^^^^^^^^^^^^^^^^
  File "C:\Users\HP\anaconda3\envs\FedLearnCD\Lib\site-packages\torch\utils\data\dataloader.py", line 1040, in __init__
    w.start()
  File "C:\Users\HP\anaconda3\envs\FedLearnCD\Lib\multiprocessing\process.py", line 121, in start
    self._popen = self._Popen(self)
                  ^^^^^^^^^^^^^^^^^
  File "C:\Users\HP\anaconda3\envs\FedLearnCD\Lib\multiprocessing\context.py", line 224, in _Popen
    return _default_context.get_context().Process._Popen(process_obj)
           ^^^^^^^^^^^^^^^^^^^^^^^^^^^^^^^^^^^^^^^^^^^^^^^^^^^^^^^^^^
  File "C:\Users\HP\anaconda3\envs\FedLearnCD\Lib\multiprocessing\context.py", line 336, in _Popen
    return Popen(process_obj)
           ^^^^^^^^^^^^^^^^^^
  File "C:\Users\HP\anaconda3\envs\FedLearnCD\Lib\multiprocessing\popen_spawn_win32.py", line 95, in __init__
    reduction.dump(process_obj, to_child)
  File "C:\Users\HP\anaconda3\envs\FedLearnCD\Lib\multiprocessing\reduction.py", line 60, in dump
    ForkingPickler(file, protocol).dump(obj)
OSError: [Errno 22] Invalid argument

The above exception was the direct cause of the following exception:

[36mray::ClientAppActor.run()[39m (pid=14104, ip=127.0.0.1, actor_id=ec85611a48f4ac4cc9625ad701000000, repr=<flwr.simulation.ray_transport.ray_actor.ClientAppActor object at 0x00000279798B3F50>)
  File "python\ray\_raylet.pyx", line 1418, in ray._raylet.execute_task
  File "python\ray\_raylet.pyx", line 1498, in ray._raylet.execute_task
  File "python\ray\_raylet.pyx", line 1424, in ray._raylet.execute_task
  File "python\ray\_raylet.pyx", line 1364, in ray._raylet.execute_task.function_executor
  File "C:\Users\HP\anaconda3\envs\FedLearnCD\Lib\site-packages\ray\_private\function_manager.py", line 726, in actor_method_executor
    return method(__ray_actor, *args, **kwargs)
           ^^^^^^^^^^^^^^^^^^^^^^^^^^^^^^^^^^^^
  File "C:\Users\HP\anaconda3\envs\FedLearnCD\Lib\site-packages\ray\util\tracing\tracing_helper.py", line 464, in _resume_span
    return method(self, *_args, **_kwargs)
           ^^^^^^^^^^^^^^^^^^^^^^^^^^^^^^^
  File "C:\Users\HP\anaconda3\envs\FedLearnCD\Lib\site-packages\flwr\simulation\ray_transport\ray_actor.py", line 64, in run
    raise ClientAppException(str(ex)) from ex
flwr.client.client_app.ClientAppException: 
Exception ClientAppException occurred. Message: [Errno 22] Invalid argument

[2024-05-04 17:38:20,159][flwr][ERROR] - [36mray::ClientAppActor.run()[39m (pid=14104, ip=127.0.0.1, actor_id=ec85611a48f4ac4cc9625ad701000000, repr=<flwr.simulation.ray_transport.ray_actor.ClientAppActor object at 0x00000279798B3F50>)
                  ^^^^^^^^^^^^^^^^^^^^^^^^^^^^^^^^^^^^^
  File "C:\Users\HP\anaconda3\envs\FedLearnCD\Lib\site-packages\flwr\client\client_app.py", line 98, in __call__
    return self._call(message, context)
           ^^^^^^^^^^^^^^^^^^^^^^^^^^^^
  File "C:\Users\HP\anaconda3\envs\FedLearnCD\Lib\site-packages\flwr\client\client_app.py", line 81, in ffn
    out_message = handle_legacy_message_from_msgtype(
                  ^^^^^^^^^^^^^^^^^^^^^^^^^^^^^^^^^^^
  File "C:\Users\HP\anaconda3\envs\FedLearnCD\Lib\site-packages\flwr\client\message_handler\message_handler.py", line 130, in handle_legacy_message_from_msgtype
    fit_res = maybe_call_fit(
              ^^^^^^^^^^^^^^^
  File "C:\Users\HP\anaconda3\envs\FedLearnCD\Lib\site-packages\flwr\client\client.py", line 234, in maybe_call_fit
    return client.fit(fit_ins)
           ^^^^^^^^^^^^^^^^^^^
  File "C:\Users\HP\anaconda3\envs\FedLearnCD\Lib\site-packages\flwr\client\numpy_client.py", line 238, in _fit
    results = self.numpy_client.fit(parameters, ins.config)  # type: ignore
              ^^^^^^^^^^^^^^^^^^^^^^^^^^^^^^^^^^^^^^^^^^^^^
  File "C:\Users\HP\Documents\FedAvgWithDrift\client.py", line 48, in fit
    train(self.model, self.trainloader,optim, epochs, self.device)
  File "C:\Users\HP\Documents\FedAvgWithDrift\model.py", line 32, in train
    for images, labels in trainloader:
  File "C:\Users\HP\anaconda3\envs\FedLearnCD\Lib\site-packages\torch\utils\data\dataloader.py", line 439, in __iter__
    return self._get_iterator()
           ^^^^^^^^^^^^^^^^^^^^
  File "C:\Users\HP\anaconda3\envs\FedLearnCD\Lib\site-packages\torch\utils\data\dataloader.py", line 387, in _get_iterator
    return _MultiProcessingDataLoaderIter(self)
           ^^^^^^^^^^^^^^^^^^^^^^^^^^^^^^^^^^^^
  File "C:\Users\HP\anaconda3\envs\FedLearnCD\Lib\site-packages\torch\utils\data\dataloader.py", line 1040, in __init__
    w.start()
  File "C:\Users\HP\anaconda3\envs\FedLearnCD\Lib\multiprocessing\process.py", line 121, in start
    self._popen = self._Popen(self)
                  ^^^^^^^^^^^^^^^^^
  File "C:\Users\HP\anaconda3\envs\FedLearnCD\Lib\multiprocessing\context.py", line 224, in _Popen
    return _default_context.get_context().Process._Popen(process_obj)
           ^^^^^^^^^^^^^^^^^^^^^^^^^^^^^^^^^^^^^^^^^^^^^^^^^^^^^^^^^^
  File "C:\Users\HP\anaconda3\envs\FedLearnCD\Lib\multiprocessing\context.py", line 336, in _Popen
    return Popen(process_obj)
           ^^^^^^^^^^^^^^^^^^
  File "C:\Users\HP\anaconda3\envs\FedLearnCD\Lib\multiprocessing\popen_spawn_win32.py", line 95, in __init__
    reduction.dump(process_obj, to_child)
  File "C:\Users\HP\anaconda3\envs\FedLearnCD\Lib\multiprocessing\reduction.py", line 60, in dump
    ForkingPickler(file, protocol).dump(obj)
OSError: [Errno 22] Invalid argument

The above exception was the direct cause of the following exception:

[36mray::ClientAppActor.run()[39m (pid=14104, ip=127.0.0.1, actor_id=ec85611a48f4ac4cc9625ad701000000, repr=<flwr.simulation.ray_transport.ray_actor.ClientAppActor object at 0x00000279798B3F50>)
  File "python\ray\_raylet.pyx", line 1418, in ray._raylet.execute_task
  File "python\ray\_raylet.pyx", line 1498, in ray._raylet.execute_task
  File "python\ray\_raylet.pyx", line 1424, in ray._raylet.execute_task
  File "python\ray\_raylet.pyx", line 1364, in ray._raylet.execute_task.function_executor
  File "C:\Users\HP\anaconda3\envs\FedLearnCD\Lib\site-packages\ray\_private\function_manager.py", line 726, in actor_method_executor
    return method(__ray_actor, *args, **kwargs)
           ^^^^^^^^^^^^^^^^^^^^^^^^^^^^^^^^^^^^
  File "C:\Users\HP\anaconda3\envs\FedLearnCD\Lib\site-packages\ray\util\tracing\tracing_helper.py", line 464, in _resume_span
    return method(self, *_args, **_kwargs)
           ^^^^^^^^^^^^^^^^^^^^^^^^^^^^^^^
  File "C:\Users\HP\anaconda3\envs\FedLearnCD\Lib\site-packages\flwr\simulation\ray_transport\ray_actor.py", line 64, in run
    raise ClientAppException(str(ex)) from ex
flwr.client.client_app.ClientAppException: 
Exception ClientAppException occurred. Message: [Errno 22] Invalid argument
[2024-05-04 17:38:36,987][flwr][ERROR] - Traceback (most recent call last):
  File "C:\Users\HP\anaconda3\envs\FedLearnCD\Lib\site-packages\flwr\simulation\ray_transport\ray_client_proxy.py", line 73, in _submit_job
    out_mssg, updated_context = self.actor_pool.get_client_result(
                                ^^^^^^^^^^^^^^^^^^^^^^^^^^^^^^^^^^
  File "C:\Users\HP\anaconda3\envs\FedLearnCD\Lib\site-packages\flwr\simulation\ray_transport\ray_actor.py", line 399, in get_client_result
    return self._fetch_future_result(cid)
           ^^^^^^^^^^^^^^^^^^^^^^^^^^^^^^
  File "C:\Users\HP\anaconda3\envs\FedLearnCD\Lib\site-packages\flwr\simulation\ray_transport\ray_actor.py", line 280, in _fetch_future_result
    res_cid, out_mssg, updated_context = ray.get(
                                         ^^^^^^^^
  File "C:\Users\HP\anaconda3\envs\FedLearnCD\Lib\site-packages\ray\_private\auto_init_hook.py", line 24, in auto_init_wrapper
    return fn(*args, **kwargs)
           ^^^^^^^^^^^^^^^^^^^
  File "C:\Users\HP\anaconda3\envs\FedLearnCD\Lib\site-packages\ray\_private\client_mode_hook.py", line 103, in wrapper
    return func(*args, **kwargs)
           ^^^^^^^^^^^^^^^^^^^^^
  File "C:\Users\HP\anaconda3\envs\FedLearnCD\Lib\site-packages\ray\_private\worker.py", line 2524, in get
    raise value.as_instanceof_cause()
ray.exceptions.RayTaskError(ClientAppException): [36mray::ClientAppActor.run()[39m (pid=5448, ip=127.0.0.1, actor_id=00ec7c825b46d603a9313e3201000000, repr=<flwr.simulation.ray_transport.ray_actor.ClientAppActor object at 0x000001EB7A76D690>)
                  ^^^^^^^^^^^^^^^^^^^^^^^^^^^^^^^^^^^^^
  File "C:\Users\HP\anaconda3\envs\FedLearnCD\Lib\site-packages\flwr\client\client_app.py", line 98, in __call__
    return self._call(message, context)
           ^^^^^^^^^^^^^^^^^^^^^^^^^^^^
  File "C:\Users\HP\anaconda3\envs\FedLearnCD\Lib\site-packages\flwr\client\client_app.py", line 81, in ffn
    out_message = handle_legacy_message_from_msgtype(
                  ^^^^^^^^^^^^^^^^^^^^^^^^^^^^^^^^^^^
  File "C:\Users\HP\anaconda3\envs\FedLearnCD\Lib\site-packages\flwr\client\message_handler\message_handler.py", line 130, in handle_legacy_message_from_msgtype
    fit_res = maybe_call_fit(
              ^^^^^^^^^^^^^^^
  File "C:\Users\HP\anaconda3\envs\FedLearnCD\Lib\site-packages\flwr\client\client.py", line 234, in maybe_call_fit
    return client.fit(fit_ins)
           ^^^^^^^^^^^^^^^^^^^
  File "C:\Users\HP\anaconda3\envs\FedLearnCD\Lib\site-packages\flwr\client\numpy_client.py", line 238, in _fit
    results = self.numpy_client.fit(parameters, ins.config)  # type: ignore
              ^^^^^^^^^^^^^^^^^^^^^^^^^^^^^^^^^^^^^^^^^^^^^
  File "C:\Users\HP\Documents\FedAvgWithDrift\client.py", line 48, in fit
    train(self.model, self.trainloader,optim, epochs, self.device)
  File "C:\Users\HP\Documents\FedAvgWithDrift\model.py", line 32, in train
    for images, labels in trainloader:
  File "C:\Users\HP\anaconda3\envs\FedLearnCD\Lib\site-packages\torch\utils\data\dataloader.py", line 439, in __iter__
    return self._get_iterator()
           ^^^^^^^^^^^^^^^^^^^^
  File "C:\Users\HP\anaconda3\envs\FedLearnCD\Lib\site-packages\torch\utils\data\dataloader.py", line 387, in _get_iterator
    return _MultiProcessingDataLoaderIter(self)
           ^^^^^^^^^^^^^^^^^^^^^^^^^^^^^^^^^^^^
  File "C:\Users\HP\anaconda3\envs\FedLearnCD\Lib\site-packages\torch\utils\data\dataloader.py", line 1040, in __init__
    w.start()
  File "C:\Users\HP\anaconda3\envs\FedLearnCD\Lib\multiprocessing\process.py", line 121, in start
    self._popen = self._Popen(self)
                  ^^^^^^^^^^^^^^^^^
  File "C:\Users\HP\anaconda3\envs\FedLearnCD\Lib\multiprocessing\context.py", line 224, in _Popen
    return _default_context.get_context().Process._Popen(process_obj)
           ^^^^^^^^^^^^^^^^^^^^^^^^^^^^^^^^^^^^^^^^^^^^^^^^^^^^^^^^^^
  File "C:\Users\HP\anaconda3\envs\FedLearnCD\Lib\multiprocessing\context.py", line 336, in _Popen
    return Popen(process_obj)
           ^^^^^^^^^^^^^^^^^^
  File "C:\Users\HP\anaconda3\envs\FedLearnCD\Lib\multiprocessing\popen_spawn_win32.py", line 95, in __init__
    reduction.dump(process_obj, to_child)
  File "C:\Users\HP\anaconda3\envs\FedLearnCD\Lib\multiprocessing\reduction.py", line 60, in dump
    ForkingPickler(file, protocol).dump(obj)
OSError: [Errno 22] Invalid argument

The above exception was the direct cause of the following exception:

[36mray::ClientAppActor.run()[39m (pid=5448, ip=127.0.0.1, actor_id=00ec7c825b46d603a9313e3201000000, repr=<flwr.simulation.ray_transport.ray_actor.ClientAppActor object at 0x000001EB7A76D690>)
  File "python\ray\_raylet.pyx", line 1418, in ray._raylet.execute_task
  File "python\ray\_raylet.pyx", line 1498, in ray._raylet.execute_task
  File "python\ray\_raylet.pyx", line 1424, in ray._raylet.execute_task
  File "python\ray\_raylet.pyx", line 1364, in ray._raylet.execute_task.function_executor
  File "C:\Users\HP\anaconda3\envs\FedLearnCD\Lib\site-packages\ray\_private\function_manager.py", line 726, in actor_method_executor
    return method(__ray_actor, *args, **kwargs)
           ^^^^^^^^^^^^^^^^^^^^^^^^^^^^^^^^^^^^
  File "C:\Users\HP\anaconda3\envs\FedLearnCD\Lib\site-packages\ray\util\tracing\tracing_helper.py", line 464, in _resume_span
    return method(self, *_args, **_kwargs)
           ^^^^^^^^^^^^^^^^^^^^^^^^^^^^^^^
  File "C:\Users\HP\anaconda3\envs\FedLearnCD\Lib\site-packages\flwr\simulation\ray_transport\ray_actor.py", line 64, in run
    raise ClientAppException(str(ex)) from ex
flwr.client.client_app.ClientAppException: 
Exception ClientAppException occurred. Message: [Errno 22] Invalid argument

[2024-05-04 17:38:37,215][flwr][ERROR] - [36mray::ClientAppActor.run()[39m (pid=5448, ip=127.0.0.1, actor_id=00ec7c825b46d603a9313e3201000000, repr=<flwr.simulation.ray_transport.ray_actor.ClientAppActor object at 0x000001EB7A76D690>)
                  ^^^^^^^^^^^^^^^^^^^^^^^^^^^^^^^^^^^^^
  File "C:\Users\HP\anaconda3\envs\FedLearnCD\Lib\site-packages\flwr\client\client_app.py", line 98, in __call__
    return self._call(message, context)
           ^^^^^^^^^^^^^^^^^^^^^^^^^^^^
  File "C:\Users\HP\anaconda3\envs\FedLearnCD\Lib\site-packages\flwr\client\client_app.py", line 81, in ffn
    out_message = handle_legacy_message_from_msgtype(
                  ^^^^^^^^^^^^^^^^^^^^^^^^^^^^^^^^^^^
  File "C:\Users\HP\anaconda3\envs\FedLearnCD\Lib\site-packages\flwr\client\message_handler\message_handler.py", line 130, in handle_legacy_message_from_msgtype
    fit_res = maybe_call_fit(
              ^^^^^^^^^^^^^^^
  File "C:\Users\HP\anaconda3\envs\FedLearnCD\Lib\site-packages\flwr\client\client.py", line 234, in maybe_call_fit
    return client.fit(fit_ins)
           ^^^^^^^^^^^^^^^^^^^
  File "C:\Users\HP\anaconda3\envs\FedLearnCD\Lib\site-packages\flwr\client\numpy_client.py", line 238, in _fit
    results = self.numpy_client.fit(parameters, ins.config)  # type: ignore
              ^^^^^^^^^^^^^^^^^^^^^^^^^^^^^^^^^^^^^^^^^^^^^
  File "C:\Users\HP\Documents\FedAvgWithDrift\client.py", line 48, in fit
    train(self.model, self.trainloader,optim, epochs, self.device)
  File "C:\Users\HP\Documents\FedAvgWithDrift\model.py", line 32, in train
    for images, labels in trainloader:
  File "C:\Users\HP\anaconda3\envs\FedLearnCD\Lib\site-packages\torch\utils\data\dataloader.py", line 439, in __iter__
    return self._get_iterator()
           ^^^^^^^^^^^^^^^^^^^^
  File "C:\Users\HP\anaconda3\envs\FedLearnCD\Lib\site-packages\torch\utils\data\dataloader.py", line 387, in _get_iterator
    return _MultiProcessingDataLoaderIter(self)
           ^^^^^^^^^^^^^^^^^^^^^^^^^^^^^^^^^^^^
  File "C:\Users\HP\anaconda3\envs\FedLearnCD\Lib\site-packages\torch\utils\data\dataloader.py", line 1040, in __init__
    w.start()
  File "C:\Users\HP\anaconda3\envs\FedLearnCD\Lib\multiprocessing\process.py", line 121, in start
    self._popen = self._Popen(self)
                  ^^^^^^^^^^^^^^^^^
  File "C:\Users\HP\anaconda3\envs\FedLearnCD\Lib\multiprocessing\context.py", line 224, in _Popen
    return _default_context.get_context().Process._Popen(process_obj)
           ^^^^^^^^^^^^^^^^^^^^^^^^^^^^^^^^^^^^^^^^^^^^^^^^^^^^^^^^^^
  File "C:\Users\HP\anaconda3\envs\FedLearnCD\Lib\multiprocessing\context.py", line 336, in _Popen
    return Popen(process_obj)
           ^^^^^^^^^^^^^^^^^^
  File "C:\Users\HP\anaconda3\envs\FedLearnCD\Lib\multiprocessing\popen_spawn_win32.py", line 95, in __init__
    reduction.dump(process_obj, to_child)
  File "C:\Users\HP\anaconda3\envs\FedLearnCD\Lib\multiprocessing\reduction.py", line 60, in dump
    ForkingPickler(file, protocol).dump(obj)
OSError: [Errno 22] Invalid argument

The above exception was the direct cause of the following exception:

[36mray::ClientAppActor.run()[39m (pid=5448, ip=127.0.0.1, actor_id=00ec7c825b46d603a9313e3201000000, repr=<flwr.simulation.ray_transport.ray_actor.ClientAppActor object at 0x000001EB7A76D690>)
  File "python\ray\_raylet.pyx", line 1418, in ray._raylet.execute_task
  File "python\ray\_raylet.pyx", line 1498, in ray._raylet.execute_task
  File "python\ray\_raylet.pyx", line 1424, in ray._raylet.execute_task
  File "python\ray\_raylet.pyx", line 1364, in ray._raylet.execute_task.function_executor
  File "C:\Users\HP\anaconda3\envs\FedLearnCD\Lib\site-packages\ray\_private\function_manager.py", line 726, in actor_method_executor
    return method(__ray_actor, *args, **kwargs)
           ^^^^^^^^^^^^^^^^^^^^^^^^^^^^^^^^^^^^
  File "C:\Users\HP\anaconda3\envs\FedLearnCD\Lib\site-packages\ray\util\tracing\tracing_helper.py", line 464, in _resume_span
    return method(self, *_args, **_kwargs)
           ^^^^^^^^^^^^^^^^^^^^^^^^^^^^^^^
  File "C:\Users\HP\anaconda3\envs\FedLearnCD\Lib\site-packages\flwr\simulation\ray_transport\ray_actor.py", line 64, in run
    raise ClientAppException(str(ex)) from ex
flwr.client.client_app.ClientAppException: 
Exception ClientAppException occurred. Message: [Errno 22] Invalid argument
[2024-05-04 17:38:55,237][flwr][INFO] - aggregate_fit: received 8 results and 2 failures
[2024-05-04 17:38:55,270][flwr][WARNING] - No fit_metrics_aggregation_fn provided
[2024-05-04 17:38:59,993][flwr][INFO] - fit progress: (1, 181.2547960281372, {'accuracy': 0.1084}, 136.72678440000163)
[2024-05-04 17:38:59,993][flwr][INFO] - configure_evaluate: strategy sampled 25 clients (out of 50)
