[2024-05-04 19:04:51,586][flwr][WARNING] - 
Setting `min_available_clients` lower than `min_fit_clients` or
`min_evaluate_clients` can cause the server to fail when there are too few clients
connected to the server. `min_available_clients` must be set to a value larger
than or equal to the values of `min_fit_clients` and `min_evaluate_clients`.

[2024-05-04 19:04:51,586][flwr][INFO] - Starting Flower simulation, config: num_rounds=5, no round_timeout
[2024-05-04 19:05:03,079][flwr][INFO] - Flower VCE: Ray initialized with resources: {'memory': 1299514983.0, 'node:127.0.0.1': 1.0, 'object_store_memory': 649757491.0, 'CPU': 8.0, 'node:__internal_head__': 1.0}
[2024-05-04 19:05:03,079][flwr][INFO] - Optimize your simulation with Flower VCE: https://flower.ai/docs/framework/how-to-run-simulations.html
[2024-05-04 19:05:03,079][flwr][INFO] - Flower VCE: Resources for each Virtual Client: {'num_cpus': 1, 'num_gpus': 0.0}
[2024-05-04 19:05:03,109][flwr][INFO] - Flower VCE: Creating VirtualClientEngineActorPool with 8 actors
[2024-05-04 19:05:03,109][flwr][INFO] - [INIT]
[2024-05-04 19:05:03,109][flwr][INFO] - Requesting initial parameters from one random client
[2024-05-04 19:05:12,352][flwr][INFO] - Received initial parameters from one random client
[2024-05-04 19:05:12,352][flwr][INFO] - Evaluating initial global parameters
[2024-05-04 19:05:16,735][flwr][INFO] - initial parameters (loss, other metrics): 182.11450600624084, {'accuracy': 0.1}
[2024-05-04 19:05:16,735][flwr][INFO] - 
[2024-05-04 19:05:16,735][flwr][INFO] - [ROUND 1]
[2024-05-04 19:05:16,735][flwr][INFO] - Sampling failed: number of available clients (5) is less than number of requested clients (10).
[2024-05-04 19:05:16,735][flwr][INFO] - configure_fit: no clients selected, cancel
[2024-05-04 19:05:21,069][flwr][INFO] - fit progress: (1, 182.11450600624084, {'accuracy': 0.1}, 4.334631600009743)
[2024-05-04 19:05:21,069][flwr][INFO] - configure_evaluate: strategy sampled 5 clients (out of 5)
[2024-05-04 19:05:47,989][flwr][ERROR] - Traceback (most recent call last):
  File "C:\Users\HP\anaconda3\envs\FedLearnCD\Lib\site-packages\flwr\simulation\ray_transport\ray_client_proxy.py", line 73, in _submit_job
    out_mssg, updated_context = self.actor_pool.get_client_result(
                                ^^^^^^^^^^^^^^^^^^^^^^^^^^^^^^^^^^
  File "C:\Users\HP\anaconda3\envs\FedLearnCD\Lib\site-packages\flwr\simulation\ray_transport\ray_actor.py", line 399, in get_client_result
    return self._fetch_future_result(cid)
           ^^^^^^^^^^^^^^^^^^^^^^^^^^^^^^
  File "C:\Users\HP\anaconda3\envs\FedLearnCD\Lib\site-packages\flwr\simulation\ray_transport\ray_actor.py", line 280, in _fetch_future_result
    res_cid, out_mssg, updated_context = ray.get(
                                         ^^^^^^^^
  File "C:\Users\HP\anaconda3\envs\FedLearnCD\Lib\site-packages\ray\_private\auto_init_hook.py", line 21, in auto_init_wrapper
    return fn(*args, **kwargs)
           ^^^^^^^^^^^^^^^^^^^
  File "C:\Users\HP\anaconda3\envs\FedLearnCD\Lib\site-packages\ray\_private\client_mode_hook.py", line 103, in wrapper
    return func(*args, **kwargs)
           ^^^^^^^^^^^^^^^^^^^^^
  File "C:\Users\HP\anaconda3\envs\FedLearnCD\Lib\site-packages\ray\_private\worker.py", line 2623, in get
    values, debugger_breakpoint = worker.get_objects(object_refs, timeout=timeout)
                                  ^^^^^^^^^^^^^^^^^^^^^^^^^^^^^^^^^^^^^^^^^^^^^^^^
  File "C:\Users\HP\anaconda3\envs\FedLearnCD\Lib\site-packages\ray\_private\worker.py", line 861, in get_objects
    raise value.as_instanceof_cause()
ray.exceptions.RayTaskError(ClientAppException): [36mray::ClientAppActor.run()[39m (pid=15152, ip=127.0.0.1, actor_id=71dd2c767790f01f0571c8c701000000, repr=<flwr.simulation.ray_transport.ray_actor.ClientAppActor object at 0x000001CAD7736850>)
                  ^^^^^^^^^^^^^^^^^^^^^^^^^^^^^^^^^^^^^
  File "C:\Users\HP\anaconda3\envs\FedLearnCD\Lib\site-packages\flwr\client\client_app.py", line 98, in __call__
    return self._call(message, context)
           ^^^^^^^^^^^^^^^^^^^^^^^^^^^^
  File "C:\Users\HP\anaconda3\envs\FedLearnCD\Lib\site-packages\flwr\client\client_app.py", line 81, in ffn
    out_message = handle_legacy_message_from_msgtype(
                  ^^^^^^^^^^^^^^^^^^^^^^^^^^^^^^^^^^^
  File "C:\Users\HP\anaconda3\envs\FedLearnCD\Lib\site-packages\flwr\client\message_handler\message_handler.py", line 137, in handle_legacy_message_from_msgtype
    evaluate_res = maybe_call_evaluate(
                   ^^^^^^^^^^^^^^^^^^^^
  File "C:\Users\HP\anaconda3\envs\FedLearnCD\Lib\site-packages\flwr\client\client.py", line 254, in maybe_call_evaluate
    return client.evaluate(evaluate_ins)
           ^^^^^^^^^^^^^^^^^^^^^^^^^^^^^
  File "C:\Users\HP\anaconda3\envs\FedLearnCD\Lib\site-packages\flwr\client\numpy_client.py", line 262, in _evaluate
    results = self.numpy_client.evaluate(parameters, ins.config)  # type: ignore
              ^^^^^^^^^^^^^^^^^^^^^^^^^^^^^^^^^^^^^^^^^^^^^^^^^^
  File "C:\Users\HP\Documents\FedAvgWithDrift\client.py", line 61, in evaluate
    return float(loss), len(self.valloadders), {'accurcay':accuracy}
                            ^^^^^^^^^^^^^^^^
AttributeError: 'FlowerClient' object has no attribute 'valloadders'

The above exception was the direct cause of the following exception:

[36mray::ClientAppActor.run()[39m (pid=15152, ip=127.0.0.1, actor_id=71dd2c767790f01f0571c8c701000000, repr=<flwr.simulation.ray_transport.ray_actor.ClientAppActor object at 0x000001CAD7736850>)
  File "python\ray\_raylet.pyx", line 1881, in ray._raylet.execute_task
  File "python\ray\_raylet.pyx", line 1982, in ray._raylet.execute_task
  File "python\ray\_raylet.pyx", line 1887, in ray._raylet.execute_task
  File "python\ray\_raylet.pyx", line 1828, in ray._raylet.execute_task.function_executor
  File "C:\Users\HP\anaconda3\envs\FedLearnCD\Lib\site-packages\ray\_private\function_manager.py", line 691, in actor_method_executor
    return method(__ray_actor, *args, **kwargs)
           ^^^^^^^^^^^^^^^^^^^^^^^^^^^^^^^^^^^^
  File "C:\Users\HP\anaconda3\envs\FedLearnCD\Lib\site-packages\ray\util\tracing\tracing_helper.py", line 467, in _resume_span
    return method(self, *_args, **_kwargs)
           ^^^^^^^^^^^^^^^^^^^^^^^^^^^^^^^
  File "C:\Users\HP\anaconda3\envs\FedLearnCD\Lib\site-packages\flwr\simulation\ray_transport\ray_actor.py", line 64, in run
    raise ClientAppException(str(ex)) from ex
flwr.client.client_app.ClientAppException: 
Exception ClientAppException occurred. Message: 'FlowerClient' object has no attribute 'valloadders'

[2024-05-04 19:05:48,063][flwr][ERROR] - [36mray::ClientAppActor.run()[39m (pid=15152, ip=127.0.0.1, actor_id=71dd2c767790f01f0571c8c701000000, repr=<flwr.simulation.ray_transport.ray_actor.ClientAppActor object at 0x000001CAD7736850>)
                  ^^^^^^^^^^^^^^^^^^^^^^^^^^^^^^^^^^^^^
  File "C:\Users\HP\anaconda3\envs\FedLearnCD\Lib\site-packages\flwr\client\client_app.py", line 98, in __call__
    return self._call(message, context)
           ^^^^^^^^^^^^^^^^^^^^^^^^^^^^
  File "C:\Users\HP\anaconda3\envs\FedLearnCD\Lib\site-packages\flwr\client\client_app.py", line 81, in ffn
    out_message = handle_legacy_message_from_msgtype(
                  ^^^^^^^^^^^^^^^^^^^^^^^^^^^^^^^^^^^
  File "C:\Users\HP\anaconda3\envs\FedLearnCD\Lib\site-packages\flwr\client\message_handler\message_handler.py", line 137, in handle_legacy_message_from_msgtype
    evaluate_res = maybe_call_evaluate(
                   ^^^^^^^^^^^^^^^^^^^^
  File "C:\Users\HP\anaconda3\envs\FedLearnCD\Lib\site-packages\flwr\client\client.py", line 254, in maybe_call_evaluate
    return client.evaluate(evaluate_ins)
           ^^^^^^^^^^^^^^^^^^^^^^^^^^^^^
  File "C:\Users\HP\anaconda3\envs\FedLearnCD\Lib\site-packages\flwr\client\numpy_client.py", line 262, in _evaluate
    results = self.numpy_client.evaluate(parameters, ins.config)  # type: ignore
              ^^^^^^^^^^^^^^^^^^^^^^^^^^^^^^^^^^^^^^^^^^^^^^^^^^
  File "C:\Users\HP\Documents\FedAvgWithDrift\client.py", line 61, in evaluate
    return float(loss), len(self.valloadders), {'accurcay':accuracy}
                            ^^^^^^^^^^^^^^^^
AttributeError: 'FlowerClient' object has no attribute 'valloadders'

The above exception was the direct cause of the following exception:

[36mray::ClientAppActor.run()[39m (pid=15152, ip=127.0.0.1, actor_id=71dd2c767790f01f0571c8c701000000, repr=<flwr.simulation.ray_transport.ray_actor.ClientAppActor object at 0x000001CAD7736850>)
  File "python\ray\_raylet.pyx", line 1881, in ray._raylet.execute_task
  File "python\ray\_raylet.pyx", line 1982, in ray._raylet.execute_task
  File "python\ray\_raylet.pyx", line 1887, in ray._raylet.execute_task
  File "python\ray\_raylet.pyx", line 1828, in ray._raylet.execute_task.function_executor
  File "C:\Users\HP\anaconda3\envs\FedLearnCD\Lib\site-packages\ray\_private\function_manager.py", line 691, in actor_method_executor
    return method(__ray_actor, *args, **kwargs)
           ^^^^^^^^^^^^^^^^^^^^^^^^^^^^^^^^^^^^
  File "C:\Users\HP\anaconda3\envs\FedLearnCD\Lib\site-packages\ray\util\tracing\tracing_helper.py", line 467, in _resume_span
    return method(self, *_args, **_kwargs)
           ^^^^^^^^^^^^^^^^^^^^^^^^^^^^^^^
  File "C:\Users\HP\anaconda3\envs\FedLearnCD\Lib\site-packages\flwr\simulation\ray_transport\ray_actor.py", line 64, in run
    raise ClientAppException(str(ex)) from ex
flwr.client.client_app.ClientAppException: 
Exception ClientAppException occurred. Message: 'FlowerClient' object has no attribute 'valloadders'
[2024-05-04 19:06:04,072][flwr][ERROR] - Traceback (most recent call last):
  File "C:\Users\HP\anaconda3\envs\FedLearnCD\Lib\site-packages\flwr\simulation\ray_transport\ray_client_proxy.py", line 73, in _submit_job
    out_mssg, updated_context = self.actor_pool.get_client_result(
                                ^^^^^^^^^^^^^^^^^^^^^^^^^^^^^^^^^^
  File "C:\Users\HP\anaconda3\envs\FedLearnCD\Lib\site-packages\flwr\simulation\ray_transport\ray_actor.py", line 399, in get_client_result
    return self._fetch_future_result(cid)
           ^^^^^^^^^^^^^^^^^^^^^^^^^^^^^^
  File "C:\Users\HP\anaconda3\envs\FedLearnCD\Lib\site-packages\flwr\simulation\ray_transport\ray_actor.py", line 280, in _fetch_future_result
    res_cid, out_mssg, updated_context = ray.get(
                                         ^^^^^^^^
  File "C:\Users\HP\anaconda3\envs\FedLearnCD\Lib\site-packages\ray\_private\auto_init_hook.py", line 21, in auto_init_wrapper
    return fn(*args, **kwargs)
           ^^^^^^^^^^^^^^^^^^^
  File "C:\Users\HP\anaconda3\envs\FedLearnCD\Lib\site-packages\ray\_private\client_mode_hook.py", line 103, in wrapper
    return func(*args, **kwargs)
           ^^^^^^^^^^^^^^^^^^^^^
  File "C:\Users\HP\anaconda3\envs\FedLearnCD\Lib\site-packages\ray\_private\worker.py", line 2623, in get
    values, debugger_breakpoint = worker.get_objects(object_refs, timeout=timeout)
                                  ^^^^^^^^^^^^^^^^^^^^^^^^^^^^^^^^^^^^^^^^^^^^^^^^
  File "C:\Users\HP\anaconda3\envs\FedLearnCD\Lib\site-packages\ray\_private\worker.py", line 861, in get_objects
    raise value.as_instanceof_cause()
ray.exceptions.RayTaskError(ClientAppException): [36mray::ClientAppActor.run()[39m (pid=5088, ip=127.0.0.1, actor_id=201d4d61ad7bdf07591019d601000000, repr=<flwr.simulation.ray_transport.ray_actor.ClientAppActor object at 0x0000021AFA356350>)
                  ^^^^^^^^^^^^^^^^^^^^^^^^^^^^^^^^^^^^^
  File "C:\Users\HP\anaconda3\envs\FedLearnCD\Lib\site-packages\flwr\client\client_app.py", line 98, in __call__
    return self._call(message, context)
           ^^^^^^^^^^^^^^^^^^^^^^^^^^^^
  File "C:\Users\HP\anaconda3\envs\FedLearnCD\Lib\site-packages\flwr\client\client_app.py", line 81, in ffn
    out_message = handle_legacy_message_from_msgtype(
                  ^^^^^^^^^^^^^^^^^^^^^^^^^^^^^^^^^^^
  File "C:\Users\HP\anaconda3\envs\FedLearnCD\Lib\site-packages\flwr\client\message_handler\message_handler.py", line 137, in handle_legacy_message_from_msgtype
    evaluate_res = maybe_call_evaluate(
                   ^^^^^^^^^^^^^^^^^^^^
  File "C:\Users\HP\anaconda3\envs\FedLearnCD\Lib\site-packages\flwr\client\client.py", line 254, in maybe_call_evaluate
    return client.evaluate(evaluate_ins)
           ^^^^^^^^^^^^^^^^^^^^^^^^^^^^^
  File "C:\Users\HP\anaconda3\envs\FedLearnCD\Lib\site-packages\flwr\client\numpy_client.py", line 262, in _evaluate
    results = self.numpy_client.evaluate(parameters, ins.config)  # type: ignore
              ^^^^^^^^^^^^^^^^^^^^^^^^^^^^^^^^^^^^^^^^^^^^^^^^^^
  File "C:\Users\HP\Documents\FedAvgWithDrift\client.py", line 61, in evaluate
    return float(loss), len(self.valloadders), {'accurcay':accuracy}
                            ^^^^^^^^^^^^^^^^
AttributeError: 'FlowerClient' object has no attribute 'valloadders'

The above exception was the direct cause of the following exception:

[36mray::ClientAppActor.run()[39m (pid=5088, ip=127.0.0.1, actor_id=201d4d61ad7bdf07591019d601000000, repr=<flwr.simulation.ray_transport.ray_actor.ClientAppActor object at 0x0000021AFA356350>)
  File "python\ray\_raylet.pyx", line 1881, in ray._raylet.execute_task
  File "python\ray\_raylet.pyx", line 1982, in ray._raylet.execute_task
  File "python\ray\_raylet.pyx", line 1887, in ray._raylet.execute_task
  File "python\ray\_raylet.pyx", line 1828, in ray._raylet.execute_task.function_executor
  File "C:\Users\HP\anaconda3\envs\FedLearnCD\Lib\site-packages\ray\_private\function_manager.py", line 691, in actor_method_executor
    return method(__ray_actor, *args, **kwargs)
           ^^^^^^^^^^^^^^^^^^^^^^^^^^^^^^^^^^^^
  File "C:\Users\HP\anaconda3\envs\FedLearnCD\Lib\site-packages\ray\util\tracing\tracing_helper.py", line 467, in _resume_span
    return method(self, *_args, **_kwargs)
           ^^^^^^^^^^^^^^^^^^^^^^^^^^^^^^^
  File "C:\Users\HP\anaconda3\envs\FedLearnCD\Lib\site-packages\flwr\simulation\ray_transport\ray_actor.py", line 64, in run
    raise ClientAppException(str(ex)) from ex
flwr.client.client_app.ClientAppException: 
Exception ClientAppException occurred. Message: 'FlowerClient' object has no attribute 'valloadders'

[2024-05-04 19:06:04,133][flwr][ERROR] - [36mray::ClientAppActor.run()[39m (pid=5088, ip=127.0.0.1, actor_id=201d4d61ad7bdf07591019d601000000, repr=<flwr.simulation.ray_transport.ray_actor.ClientAppActor object at 0x0000021AFA356350>)
                  ^^^^^^^^^^^^^^^^^^^^^^^^^^^^^^^^^^^^^
  File "C:\Users\HP\anaconda3\envs\FedLearnCD\Lib\site-packages\flwr\client\client_app.py", line 98, in __call__
    return self._call(message, context)
           ^^^^^^^^^^^^^^^^^^^^^^^^^^^^
  File "C:\Users\HP\anaconda3\envs\FedLearnCD\Lib\site-packages\flwr\client\client_app.py", line 81, in ffn
    out_message = handle_legacy_message_from_msgtype(
                  ^^^^^^^^^^^^^^^^^^^^^^^^^^^^^^^^^^^
  File "C:\Users\HP\anaconda3\envs\FedLearnCD\Lib\site-packages\flwr\client\message_handler\message_handler.py", line 137, in handle_legacy_message_from_msgtype
    evaluate_res = maybe_call_evaluate(
                   ^^^^^^^^^^^^^^^^^^^^
  File "C:\Users\HP\anaconda3\envs\FedLearnCD\Lib\site-packages\flwr\client\client.py", line 254, in maybe_call_evaluate
    return client.evaluate(evaluate_ins)
           ^^^^^^^^^^^^^^^^^^^^^^^^^^^^^
  File "C:\Users\HP\anaconda3\envs\FedLearnCD\Lib\site-packages\flwr\client\numpy_client.py", line 262, in _evaluate
    results = self.numpy_client.evaluate(parameters, ins.config)  # type: ignore
              ^^^^^^^^^^^^^^^^^^^^^^^^^^^^^^^^^^^^^^^^^^^^^^^^^^
  File "C:\Users\HP\Documents\FedAvgWithDrift\client.py", line 61, in evaluate
    return float(loss), len(self.valloadders), {'accurcay':accuracy}
                            ^^^^^^^^^^^^^^^^
AttributeError: 'FlowerClient' object has no attribute 'valloadders'

The above exception was the direct cause of the following exception:

[36mray::ClientAppActor.run()[39m (pid=5088, ip=127.0.0.1, actor_id=201d4d61ad7bdf07591019d601000000, repr=<flwr.simulation.ray_transport.ray_actor.ClientAppActor object at 0x0000021AFA356350>)
  File "python\ray\_raylet.pyx", line 1881, in ray._raylet.execute_task
  File "python\ray\_raylet.pyx", line 1982, in ray._raylet.execute_task
  File "python\ray\_raylet.pyx", line 1887, in ray._raylet.execute_task
  File "python\ray\_raylet.pyx", line 1828, in ray._raylet.execute_task.function_executor
  File "C:\Users\HP\anaconda3\envs\FedLearnCD\Lib\site-packages\ray\_private\function_manager.py", line 691, in actor_method_executor
    return method(__ray_actor, *args, **kwargs)
           ^^^^^^^^^^^^^^^^^^^^^^^^^^^^^^^^^^^^
  File "C:\Users\HP\anaconda3\envs\FedLearnCD\Lib\site-packages\ray\util\tracing\tracing_helper.py", line 467, in _resume_span
    return method(self, *_args, **_kwargs)
           ^^^^^^^^^^^^^^^^^^^^^^^^^^^^^^^
  File "C:\Users\HP\anaconda3\envs\FedLearnCD\Lib\site-packages\flwr\simulation\ray_transport\ray_actor.py", line 64, in run
    raise ClientAppException(str(ex)) from ex
flwr.client.client_app.ClientAppException: 
Exception ClientAppException occurred. Message: 'FlowerClient' object has no attribute 'valloadders'
[2024-05-04 19:06:09,414][flwr][ERROR] - Traceback (most recent call last):
  File "C:\Users\HP\anaconda3\envs\FedLearnCD\Lib\site-packages\flwr\simulation\ray_transport\ray_client_proxy.py", line 73, in _submit_job
    out_mssg, updated_context = self.actor_pool.get_client_result(
                                ^^^^^^^^^^^^^^^^^^^^^^^^^^^^^^^^^^
  File "C:\Users\HP\anaconda3\envs\FedLearnCD\Lib\site-packages\flwr\simulation\ray_transport\ray_actor.py", line 399, in get_client_result
    return self._fetch_future_result(cid)
           ^^^^^^^^^^^^^^^^^^^^^^^^^^^^^^
  File "C:\Users\HP\anaconda3\envs\FedLearnCD\Lib\site-packages\flwr\simulation\ray_transport\ray_actor.py", line 280, in _fetch_future_result
    res_cid, out_mssg, updated_context = ray.get(
                                         ^^^^^^^^
  File "C:\Users\HP\anaconda3\envs\FedLearnCD\Lib\site-packages\ray\_private\auto_init_hook.py", line 21, in auto_init_wrapper
    return fn(*args, **kwargs)
           ^^^^^^^^^^^^^^^^^^^
  File "C:\Users\HP\anaconda3\envs\FedLearnCD\Lib\site-packages\ray\_private\client_mode_hook.py", line 103, in wrapper
    return func(*args, **kwargs)
           ^^^^^^^^^^^^^^^^^^^^^
  File "C:\Users\HP\anaconda3\envs\FedLearnCD\Lib\site-packages\ray\_private\worker.py", line 2623, in get
    values, debugger_breakpoint = worker.get_objects(object_refs, timeout=timeout)
                                  ^^^^^^^^^^^^^^^^^^^^^^^^^^^^^^^^^^^^^^^^^^^^^^^^
  File "C:\Users\HP\anaconda3\envs\FedLearnCD\Lib\site-packages\ray\_private\worker.py", line 861, in get_objects
    raise value.as_instanceof_cause()
ray.exceptions.RayTaskError(ClientAppException): [36mray::ClientAppActor.run()[39m (pid=6536, ip=127.0.0.1, actor_id=14f677eaa3c4366b55bf407501000000, repr=<flwr.simulation.ray_transport.ray_actor.ClientAppActor object at 0x000001D1AFF26290>)
                  ^^^^^^^^^^^^^^^^^^^^^^^^^^^^^^^^^^^^^
  File "C:\Users\HP\anaconda3\envs\FedLearnCD\Lib\site-packages\flwr\client\client_app.py", line 98, in __call__
    return self._call(message, context)
           ^^^^^^^^^^^^^^^^^^^^^^^^^^^^
  File "C:\Users\HP\anaconda3\envs\FedLearnCD\Lib\site-packages\flwr\client\client_app.py", line 81, in ffn
    out_message = handle_legacy_message_from_msgtype(
                  ^^^^^^^^^^^^^^^^^^^^^^^^^^^^^^^^^^^
  File "C:\Users\HP\anaconda3\envs\FedLearnCD\Lib\site-packages\flwr\client\message_handler\message_handler.py", line 137, in handle_legacy_message_from_msgtype
    evaluate_res = maybe_call_evaluate(
                   ^^^^^^^^^^^^^^^^^^^^
  File "C:\Users\HP\anaconda3\envs\FedLearnCD\Lib\site-packages\flwr\client\client.py", line 254, in maybe_call_evaluate
    return client.evaluate(evaluate_ins)
           ^^^^^^^^^^^^^^^^^^^^^^^^^^^^^
  File "C:\Users\HP\anaconda3\envs\FedLearnCD\Lib\site-packages\flwr\client\numpy_client.py", line 262, in _evaluate
    results = self.numpy_client.evaluate(parameters, ins.config)  # type: ignore
              ^^^^^^^^^^^^^^^^^^^^^^^^^^^^^^^^^^^^^^^^^^^^^^^^^^
  File "C:\Users\HP\Documents\FedAvgWithDrift\client.py", line 61, in evaluate
    return float(loss), len(self.valloadders), {'accurcay':accuracy}
                            ^^^^^^^^^^^^^^^^
AttributeError: 'FlowerClient' object has no attribute 'valloadders'

The above exception was the direct cause of the following exception:

[36mray::ClientAppActor.run()[39m (pid=6536, ip=127.0.0.1, actor_id=14f677eaa3c4366b55bf407501000000, repr=<flwr.simulation.ray_transport.ray_actor.ClientAppActor object at 0x000001D1AFF26290>)
  File "python\ray\_raylet.pyx", line 1881, in ray._raylet.execute_task
  File "python\ray\_raylet.pyx", line 1982, in ray._raylet.execute_task
  File "python\ray\_raylet.pyx", line 1887, in ray._raylet.execute_task
  File "python\ray\_raylet.pyx", line 1828, in ray._raylet.execute_task.function_executor
  File "C:\Users\HP\anaconda3\envs\FedLearnCD\Lib\site-packages\ray\_private\function_manager.py", line 691, in actor_method_executor
    return method(__ray_actor, *args, **kwargs)
           ^^^^^^^^^^^^^^^^^^^^^^^^^^^^^^^^^^^^
  File "C:\Users\HP\anaconda3\envs\FedLearnCD\Lib\site-packages\ray\util\tracing\tracing_helper.py", line 467, in _resume_span
    return method(self, *_args, **_kwargs)
           ^^^^^^^^^^^^^^^^^^^^^^^^^^^^^^^
  File "C:\Users\HP\anaconda3\envs\FedLearnCD\Lib\site-packages\flwr\simulation\ray_transport\ray_actor.py", line 64, in run
    raise ClientAppException(str(ex)) from ex
flwr.client.client_app.ClientAppException: 
Exception ClientAppException occurred. Message: 'FlowerClient' object has no attribute 'valloadders'

[2024-05-04 19:06:09,452][flwr][ERROR] - [36mray::ClientAppActor.run()[39m (pid=6536, ip=127.0.0.1, actor_id=14f677eaa3c4366b55bf407501000000, repr=<flwr.simulation.ray_transport.ray_actor.ClientAppActor object at 0x000001D1AFF26290>)
                  ^^^^^^^^^^^^^^^^^^^^^^^^^^^^^^^^^^^^^
  File "C:\Users\HP\anaconda3\envs\FedLearnCD\Lib\site-packages\flwr\client\client_app.py", line 98, in __call__
    return self._call(message, context)
           ^^^^^^^^^^^^^^^^^^^^^^^^^^^^
  File "C:\Users\HP\anaconda3\envs\FedLearnCD\Lib\site-packages\flwr\client\client_app.py", line 81, in ffn
    out_message = handle_legacy_message_from_msgtype(
                  ^^^^^^^^^^^^^^^^^^^^^^^^^^^^^^^^^^^
  File "C:\Users\HP\anaconda3\envs\FedLearnCD\Lib\site-packages\flwr\client\message_handler\message_handler.py", line 137, in handle_legacy_message_from_msgtype
    evaluate_res = maybe_call_evaluate(
                   ^^^^^^^^^^^^^^^^^^^^
  File "C:\Users\HP\anaconda3\envs\FedLearnCD\Lib\site-packages\flwr\client\client.py", line 254, in maybe_call_evaluate
    return client.evaluate(evaluate_ins)
           ^^^^^^^^^^^^^^^^^^^^^^^^^^^^^
  File "C:\Users\HP\anaconda3\envs\FedLearnCD\Lib\site-packages\flwr\client\numpy_client.py", line 262, in _evaluate
    results = self.numpy_client.evaluate(parameters, ins.config)  # type: ignore
              ^^^^^^^^^^^^^^^^^^^^^^^^^^^^^^^^^^^^^^^^^^^^^^^^^^
  File "C:\Users\HP\Documents\FedAvgWithDrift\client.py", line 61, in evaluate
    return float(loss), len(self.valloadders), {'accurcay':accuracy}
                            ^^^^^^^^^^^^^^^^
AttributeError: 'FlowerClient' object has no attribute 'valloadders'

The above exception was the direct cause of the following exception:

[36mray::ClientAppActor.run()[39m (pid=6536, ip=127.0.0.1, actor_id=14f677eaa3c4366b55bf407501000000, repr=<flwr.simulation.ray_transport.ray_actor.ClientAppActor object at 0x000001D1AFF26290>)
  File "python\ray\_raylet.pyx", line 1881, in ray._raylet.execute_task
  File "python\ray\_raylet.pyx", line 1982, in ray._raylet.execute_task
  File "python\ray\_raylet.pyx", line 1887, in ray._raylet.execute_task
  File "python\ray\_raylet.pyx", line 1828, in ray._raylet.execute_task.function_executor
  File "C:\Users\HP\anaconda3\envs\FedLearnCD\Lib\site-packages\ray\_private\function_manager.py", line 691, in actor_method_executor
    return method(__ray_actor, *args, **kwargs)
           ^^^^^^^^^^^^^^^^^^^^^^^^^^^^^^^^^^^^
  File "C:\Users\HP\anaconda3\envs\FedLearnCD\Lib\site-packages\ray\util\tracing\tracing_helper.py", line 467, in _resume_span
    return method(self, *_args, **_kwargs)
           ^^^^^^^^^^^^^^^^^^^^^^^^^^^^^^^
  File "C:\Users\HP\anaconda3\envs\FedLearnCD\Lib\site-packages\flwr\simulation\ray_transport\ray_actor.py", line 64, in run
    raise ClientAppException(str(ex)) from ex
flwr.client.client_app.ClientAppException: 
Exception ClientAppException occurred. Message: 'FlowerClient' object has no attribute 'valloadders'
[2024-05-04 19:06:11,280][flwr][ERROR] - Traceback (most recent call last):
  File "C:\Users\HP\anaconda3\envs\FedLearnCD\Lib\site-packages\flwr\simulation\ray_transport\ray_client_proxy.py", line 73, in _submit_job
    out_mssg, updated_context = self.actor_pool.get_client_result(
                                ^^^^^^^^^^^^^^^^^^^^^^^^^^^^^^^^^^
  File "C:\Users\HP\anaconda3\envs\FedLearnCD\Lib\site-packages\flwr\simulation\ray_transport\ray_actor.py", line 399, in get_client_result
    return self._fetch_future_result(cid)
           ^^^^^^^^^^^^^^^^^^^^^^^^^^^^^^
  File "C:\Users\HP\anaconda3\envs\FedLearnCD\Lib\site-packages\flwr\simulation\ray_transport\ray_actor.py", line 280, in _fetch_future_result
    res_cid, out_mssg, updated_context = ray.get(
                                         ^^^^^^^^
  File "C:\Users\HP\anaconda3\envs\FedLearnCD\Lib\site-packages\ray\_private\auto_init_hook.py", line 21, in auto_init_wrapper
    return fn(*args, **kwargs)
           ^^^^^^^^^^^^^^^^^^^
  File "C:\Users\HP\anaconda3\envs\FedLearnCD\Lib\site-packages\ray\_private\client_mode_hook.py", line 103, in wrapper
    return func(*args, **kwargs)
           ^^^^^^^^^^^^^^^^^^^^^
  File "C:\Users\HP\anaconda3\envs\FedLearnCD\Lib\site-packages\ray\_private\worker.py", line 2623, in get
    values, debugger_breakpoint = worker.get_objects(object_refs, timeout=timeout)
                                  ^^^^^^^^^^^^^^^^^^^^^^^^^^^^^^^^^^^^^^^^^^^^^^^^
  File "C:\Users\HP\anaconda3\envs\FedLearnCD\Lib\site-packages\ray\_private\worker.py", line 861, in get_objects
    raise value.as_instanceof_cause()
ray.exceptions.RayTaskError(ClientAppException): [36mray::ClientAppActor.run()[39m (pid=5092, ip=127.0.0.1, actor_id=7a73e292a6008c781ec56f8101000000, repr=<flwr.simulation.ray_transport.ray_actor.ClientAppActor object at 0x00000254ABDFFA10>)
                  ^^^^^^^^^^^^^^^^^^^^^^^^^^^^^^^^^^^^^
  File "C:\Users\HP\anaconda3\envs\FedLearnCD\Lib\site-packages\flwr\client\client_app.py", line 98, in __call__
    return self._call(message, context)
           ^^^^^^^^^^^^^^^^^^^^^^^^^^^^
  File "C:\Users\HP\anaconda3\envs\FedLearnCD\Lib\site-packages\flwr\client\client_app.py", line 81, in ffn
    out_message = handle_legacy_message_from_msgtype(
                  ^^^^^^^^^^^^^^^^^^^^^^^^^^^^^^^^^^^
  File "C:\Users\HP\anaconda3\envs\FedLearnCD\Lib\site-packages\flwr\client\message_handler\message_handler.py", line 137, in handle_legacy_message_from_msgtype
    evaluate_res = maybe_call_evaluate(
                   ^^^^^^^^^^^^^^^^^^^^
  File "C:\Users\HP\anaconda3\envs\FedLearnCD\Lib\site-packages\flwr\client\client.py", line 254, in maybe_call_evaluate
    return client.evaluate(evaluate_ins)
           ^^^^^^^^^^^^^^^^^^^^^^^^^^^^^
  File "C:\Users\HP\anaconda3\envs\FedLearnCD\Lib\site-packages\flwr\client\numpy_client.py", line 262, in _evaluate
    results = self.numpy_client.evaluate(parameters, ins.config)  # type: ignore
              ^^^^^^^^^^^^^^^^^^^^^^^^^^^^^^^^^^^^^^^^^^^^^^^^^^
  File "C:\Users\HP\Documents\FedAvgWithDrift\client.py", line 61, in evaluate
    return float(loss), len(self.valloadders), {'accurcay':accuracy}
                            ^^^^^^^^^^^^^^^^
AttributeError: 'FlowerClient' object has no attribute 'valloadders'

The above exception was the direct cause of the following exception:

[36mray::ClientAppActor.run()[39m (pid=5092, ip=127.0.0.1, actor_id=7a73e292a6008c781ec56f8101000000, repr=<flwr.simulation.ray_transport.ray_actor.ClientAppActor object at 0x00000254ABDFFA10>)
  File "python\ray\_raylet.pyx", line 1881, in ray._raylet.execute_task
  File "python\ray\_raylet.pyx", line 1982, in ray._raylet.execute_task
  File "python\ray\_raylet.pyx", line 1887, in ray._raylet.execute_task
  File "python\ray\_raylet.pyx", line 1828, in ray._raylet.execute_task.function_executor
  File "C:\Users\HP\anaconda3\envs\FedLearnCD\Lib\site-packages\ray\_private\function_manager.py", line 691, in actor_method_executor
    return method(__ray_actor, *args, **kwargs)
           ^^^^^^^^^^^^^^^^^^^^^^^^^^^^^^^^^^^^
  File "C:\Users\HP\anaconda3\envs\FedLearnCD\Lib\site-packages\ray\util\tracing\tracing_helper.py", line 467, in _resume_span
    return method(self, *_args, **_kwargs)
           ^^^^^^^^^^^^^^^^^^^^^^^^^^^^^^^
  File "C:\Users\HP\anaconda3\envs\FedLearnCD\Lib\site-packages\flwr\simulation\ray_transport\ray_actor.py", line 64, in run
    raise ClientAppException(str(ex)) from ex
flwr.client.client_app.ClientAppException: 
Exception ClientAppException occurred. Message: 'FlowerClient' object has no attribute 'valloadders'

[2024-05-04 19:06:11,304][flwr][ERROR] - [36mray::ClientAppActor.run()[39m (pid=5092, ip=127.0.0.1, actor_id=7a73e292a6008c781ec56f8101000000, repr=<flwr.simulation.ray_transport.ray_actor.ClientAppActor object at 0x00000254ABDFFA10>)
                  ^^^^^^^^^^^^^^^^^^^^^^^^^^^^^^^^^^^^^
  File "C:\Users\HP\anaconda3\envs\FedLearnCD\Lib\site-packages\flwr\client\client_app.py", line 98, in __call__
    return self._call(message, context)
           ^^^^^^^^^^^^^^^^^^^^^^^^^^^^
  File "C:\Users\HP\anaconda3\envs\FedLearnCD\Lib\site-packages\flwr\client\client_app.py", line 81, in ffn
    out_message = handle_legacy_message_from_msgtype(
                  ^^^^^^^^^^^^^^^^^^^^^^^^^^^^^^^^^^^
  File "C:\Users\HP\anaconda3\envs\FedLearnCD\Lib\site-packages\flwr\client\message_handler\message_handler.py", line 137, in handle_legacy_message_from_msgtype
    evaluate_res = maybe_call_evaluate(
                   ^^^^^^^^^^^^^^^^^^^^
  File "C:\Users\HP\anaconda3\envs\FedLearnCD\Lib\site-packages\flwr\client\client.py", line 254, in maybe_call_evaluate
    return client.evaluate(evaluate_ins)
           ^^^^^^^^^^^^^^^^^^^^^^^^^^^^^
  File "C:\Users\HP\anaconda3\envs\FedLearnCD\Lib\site-packages\flwr\client\numpy_client.py", line 262, in _evaluate
    results = self.numpy_client.evaluate(parameters, ins.config)  # type: ignore
              ^^^^^^^^^^^^^^^^^^^^^^^^^^^^^^^^^^^^^^^^^^^^^^^^^^
  File "C:\Users\HP\Documents\FedAvgWithDrift\client.py", line 61, in evaluate
    return float(loss), len(self.valloadders), {'accurcay':accuracy}
                            ^^^^^^^^^^^^^^^^
AttributeError: 'FlowerClient' object has no attribute 'valloadders'

The above exception was the direct cause of the following exception:

[36mray::ClientAppActor.run()[39m (pid=5092, ip=127.0.0.1, actor_id=7a73e292a6008c781ec56f8101000000, repr=<flwr.simulation.ray_transport.ray_actor.ClientAppActor object at 0x00000254ABDFFA10>)
  File "python\ray\_raylet.pyx", line 1881, in ray._raylet.execute_task
  File "python\ray\_raylet.pyx", line 1982, in ray._raylet.execute_task
  File "python\ray\_raylet.pyx", line 1887, in ray._raylet.execute_task
  File "python\ray\_raylet.pyx", line 1828, in ray._raylet.execute_task.function_executor
  File "C:\Users\HP\anaconda3\envs\FedLearnCD\Lib\site-packages\ray\_private\function_manager.py", line 691, in actor_method_executor
    return method(__ray_actor, *args, **kwargs)
           ^^^^^^^^^^^^^^^^^^^^^^^^^^^^^^^^^^^^
  File "C:\Users\HP\anaconda3\envs\FedLearnCD\Lib\site-packages\ray\util\tracing\tracing_helper.py", line 467, in _resume_span
    return method(self, *_args, **_kwargs)
           ^^^^^^^^^^^^^^^^^^^^^^^^^^^^^^^
  File "C:\Users\HP\anaconda3\envs\FedLearnCD\Lib\site-packages\flwr\simulation\ray_transport\ray_actor.py", line 64, in run
    raise ClientAppException(str(ex)) from ex
flwr.client.client_app.ClientAppException: 
Exception ClientAppException occurred. Message: 'FlowerClient' object has no attribute 'valloadders'
[2024-05-04 19:06:16,153][flwr][ERROR] - Traceback (most recent call last):
  File "C:\Users\HP\anaconda3\envs\FedLearnCD\Lib\site-packages\flwr\simulation\ray_transport\ray_client_proxy.py", line 73, in _submit_job
    out_mssg, updated_context = self.actor_pool.get_client_result(
                                ^^^^^^^^^^^^^^^^^^^^^^^^^^^^^^^^^^
  File "C:\Users\HP\anaconda3\envs\FedLearnCD\Lib\site-packages\flwr\simulation\ray_transport\ray_actor.py", line 399, in get_client_result
    return self._fetch_future_result(cid)
           ^^^^^^^^^^^^^^^^^^^^^^^^^^^^^^
  File "C:\Users\HP\anaconda3\envs\FedLearnCD\Lib\site-packages\flwr\simulation\ray_transport\ray_actor.py", line 280, in _fetch_future_result
    res_cid, out_mssg, updated_context = ray.get(
                                         ^^^^^^^^
  File "C:\Users\HP\anaconda3\envs\FedLearnCD\Lib\site-packages\ray\_private\auto_init_hook.py", line 21, in auto_init_wrapper
    return fn(*args, **kwargs)
           ^^^^^^^^^^^^^^^^^^^
  File "C:\Users\HP\anaconda3\envs\FedLearnCD\Lib\site-packages\ray\_private\client_mode_hook.py", line 103, in wrapper
    return func(*args, **kwargs)
           ^^^^^^^^^^^^^^^^^^^^^
  File "C:\Users\HP\anaconda3\envs\FedLearnCD\Lib\site-packages\ray\_private\worker.py", line 2623, in get
    values, debugger_breakpoint = worker.get_objects(object_refs, timeout=timeout)
                                  ^^^^^^^^^^^^^^^^^^^^^^^^^^^^^^^^^^^^^^^^^^^^^^^^
  File "C:\Users\HP\anaconda3\envs\FedLearnCD\Lib\site-packages\ray\_private\worker.py", line 861, in get_objects
    raise value.as_instanceof_cause()
ray.exceptions.RayTaskError(ClientAppException): [36mray::ClientAppActor.run()[39m (pid=6532, ip=127.0.0.1, actor_id=abb66b9749a687783d54edf901000000, repr=<flwr.simulation.ray_transport.ray_actor.ClientAppActor object at 0x000001DEE96B15D0>)
                  ^^^^^^^^^^^^^^^^^^^^^^^^^^^^^^^^^^^^^
  File "C:\Users\HP\anaconda3\envs\FedLearnCD\Lib\site-packages\flwr\client\client_app.py", line 98, in __call__
    return self._call(message, context)
           ^^^^^^^^^^^^^^^^^^^^^^^^^^^^
  File "C:\Users\HP\anaconda3\envs\FedLearnCD\Lib\site-packages\flwr\client\client_app.py", line 81, in ffn
    out_message = handle_legacy_message_from_msgtype(
                  ^^^^^^^^^^^^^^^^^^^^^^^^^^^^^^^^^^^
  File "C:\Users\HP\anaconda3\envs\FedLearnCD\Lib\site-packages\flwr\client\message_handler\message_handler.py", line 137, in handle_legacy_message_from_msgtype
    evaluate_res = maybe_call_evaluate(
                   ^^^^^^^^^^^^^^^^^^^^
  File "C:\Users\HP\anaconda3\envs\FedLearnCD\Lib\site-packages\flwr\client\client.py", line 254, in maybe_call_evaluate
    return client.evaluate(evaluate_ins)
           ^^^^^^^^^^^^^^^^^^^^^^^^^^^^^
  File "C:\Users\HP\anaconda3\envs\FedLearnCD\Lib\site-packages\flwr\client\numpy_client.py", line 262, in _evaluate
    results = self.numpy_client.evaluate(parameters, ins.config)  # type: ignore
              ^^^^^^^^^^^^^^^^^^^^^^^^^^^^^^^^^^^^^^^^^^^^^^^^^^
  File "C:\Users\HP\Documents\FedAvgWithDrift\client.py", line 61, in evaluate
    return float(loss), len(self.valloadders), {'accurcay':accuracy}
                            ^^^^^^^^^^^^^^^^
AttributeError: 'FlowerClient' object has no attribute 'valloadders'

The above exception was the direct cause of the following exception:

[36mray::ClientAppActor.run()[39m (pid=6532, ip=127.0.0.1, actor_id=abb66b9749a687783d54edf901000000, repr=<flwr.simulation.ray_transport.ray_actor.ClientAppActor object at 0x000001DEE96B15D0>)
  File "python\ray\_raylet.pyx", line 1881, in ray._raylet.execute_task
  File "python\ray\_raylet.pyx", line 1982, in ray._raylet.execute_task
  File "python\ray\_raylet.pyx", line 1887, in ray._raylet.execute_task
  File "python\ray\_raylet.pyx", line 1828, in ray._raylet.execute_task.function_executor
  File "C:\Users\HP\anaconda3\envs\FedLearnCD\Lib\site-packages\ray\_private\function_manager.py", line 691, in actor_method_executor
    return method(__ray_actor, *args, **kwargs)
           ^^^^^^^^^^^^^^^^^^^^^^^^^^^^^^^^^^^^
  File "C:\Users\HP\anaconda3\envs\FedLearnCD\Lib\site-packages\ray\util\tracing\tracing_helper.py", line 467, in _resume_span
    return method(self, *_args, **_kwargs)
           ^^^^^^^^^^^^^^^^^^^^^^^^^^^^^^^
  File "C:\Users\HP\anaconda3\envs\FedLearnCD\Lib\site-packages\flwr\simulation\ray_transport\ray_actor.py", line 64, in run
    raise ClientAppException(str(ex)) from ex
flwr.client.client_app.ClientAppException: 
Exception ClientAppException occurred. Message: 'FlowerClient' object has no attribute 'valloadders'

[2024-05-04 19:06:16,170][flwr][ERROR] - [36mray::ClientAppActor.run()[39m (pid=6532, ip=127.0.0.1, actor_id=abb66b9749a687783d54edf901000000, repr=<flwr.simulation.ray_transport.ray_actor.ClientAppActor object at 0x000001DEE96B15D0>)
                  ^^^^^^^^^^^^^^^^^^^^^^^^^^^^^^^^^^^^^
  File "C:\Users\HP\anaconda3\envs\FedLearnCD\Lib\site-packages\flwr\client\client_app.py", line 98, in __call__
    return self._call(message, context)
           ^^^^^^^^^^^^^^^^^^^^^^^^^^^^
  File "C:\Users\HP\anaconda3\envs\FedLearnCD\Lib\site-packages\flwr\client\client_app.py", line 81, in ffn
    out_message = handle_legacy_message_from_msgtype(
                  ^^^^^^^^^^^^^^^^^^^^^^^^^^^^^^^^^^^
  File "C:\Users\HP\anaconda3\envs\FedLearnCD\Lib\site-packages\flwr\client\message_handler\message_handler.py", line 137, in handle_legacy_message_from_msgtype
    evaluate_res = maybe_call_evaluate(
                   ^^^^^^^^^^^^^^^^^^^^
  File "C:\Users\HP\anaconda3\envs\FedLearnCD\Lib\site-packages\flwr\client\client.py", line 254, in maybe_call_evaluate
    return client.evaluate(evaluate_ins)
           ^^^^^^^^^^^^^^^^^^^^^^^^^^^^^
  File "C:\Users\HP\anaconda3\envs\FedLearnCD\Lib\site-packages\flwr\client\numpy_client.py", line 262, in _evaluate
    results = self.numpy_client.evaluate(parameters, ins.config)  # type: ignore
              ^^^^^^^^^^^^^^^^^^^^^^^^^^^^^^^^^^^^^^^^^^^^^^^^^^
  File "C:\Users\HP\Documents\FedAvgWithDrift\client.py", line 61, in evaluate
    return float(loss), len(self.valloadders), {'accurcay':accuracy}
                            ^^^^^^^^^^^^^^^^
AttributeError: 'FlowerClient' object has no attribute 'valloadders'

The above exception was the direct cause of the following exception:

[36mray::ClientAppActor.run()[39m (pid=6532, ip=127.0.0.1, actor_id=abb66b9749a687783d54edf901000000, repr=<flwr.simulation.ray_transport.ray_actor.ClientAppActor object at 0x000001DEE96B15D0>)
  File "python\ray\_raylet.pyx", line 1881, in ray._raylet.execute_task
  File "python\ray\_raylet.pyx", line 1982, in ray._raylet.execute_task
  File "python\ray\_raylet.pyx", line 1887, in ray._raylet.execute_task
  File "python\ray\_raylet.pyx", line 1828, in ray._raylet.execute_task.function_executor
  File "C:\Users\HP\anaconda3\envs\FedLearnCD\Lib\site-packages\ray\_private\function_manager.py", line 691, in actor_method_executor
    return method(__ray_actor, *args, **kwargs)
           ^^^^^^^^^^^^^^^^^^^^^^^^^^^^^^^^^^^^
  File "C:\Users\HP\anaconda3\envs\FedLearnCD\Lib\site-packages\ray\util\tracing\tracing_helper.py", line 467, in _resume_span
    return method(self, *_args, **_kwargs)
           ^^^^^^^^^^^^^^^^^^^^^^^^^^^^^^^
  File "C:\Users\HP\anaconda3\envs\FedLearnCD\Lib\site-packages\flwr\simulation\ray_transport\ray_actor.py", line 64, in run
    raise ClientAppException(str(ex)) from ex
flwr.client.client_app.ClientAppException: 
Exception ClientAppException occurred. Message: 'FlowerClient' object has no attribute 'valloadders'
[2024-05-04 19:06:16,186][flwr][INFO] - aggregate_evaluate: received 0 results and 5 failures
[2024-05-04 19:06:16,186][flwr][INFO] - 
[2024-05-04 19:06:16,186][flwr][INFO] - [ROUND 2]
[2024-05-04 19:06:16,186][flwr][INFO] - Sampling failed: number of available clients (5) is less than number of requested clients (10).
[2024-05-04 19:06:16,186][flwr][INFO] - configure_fit: no clients selected, cancel
[2024-05-04 19:06:21,119][flwr][INFO] - fit progress: (2, 182.11450600624084, {'accuracy': 0.1}, 64.3959162000101)
[2024-05-04 19:06:21,119][flwr][INFO] - configure_evaluate: strategy sampled 5 clients (out of 5)
[2024-05-04 19:06:48,039][flwr][ERROR] - Traceback (most recent call last):
  File "C:\Users\HP\anaconda3\envs\FedLearnCD\Lib\site-packages\flwr\simulation\ray_transport\ray_client_proxy.py", line 73, in _submit_job
    out_mssg, updated_context = self.actor_pool.get_client_result(
                                ^^^^^^^^^^^^^^^^^^^^^^^^^^^^^^^^^^
  File "C:\Users\HP\anaconda3\envs\FedLearnCD\Lib\site-packages\flwr\simulation\ray_transport\ray_actor.py", line 399, in get_client_result
    return self._fetch_future_result(cid)
           ^^^^^^^^^^^^^^^^^^^^^^^^^^^^^^
  File "C:\Users\HP\anaconda3\envs\FedLearnCD\Lib\site-packages\flwr\simulation\ray_transport\ray_actor.py", line 280, in _fetch_future_result
    res_cid, out_mssg, updated_context = ray.get(
                                         ^^^^^^^^
  File "C:\Users\HP\anaconda3\envs\FedLearnCD\Lib\site-packages\ray\_private\auto_init_hook.py", line 21, in auto_init_wrapper
    return fn(*args, **kwargs)
           ^^^^^^^^^^^^^^^^^^^
  File "C:\Users\HP\anaconda3\envs\FedLearnCD\Lib\site-packages\ray\_private\client_mode_hook.py", line 103, in wrapper
    return func(*args, **kwargs)
           ^^^^^^^^^^^^^^^^^^^^^
  File "C:\Users\HP\anaconda3\envs\FedLearnCD\Lib\site-packages\ray\_private\worker.py", line 2623, in get
    values, debugger_breakpoint = worker.get_objects(object_refs, timeout=timeout)
                                  ^^^^^^^^^^^^^^^^^^^^^^^^^^^^^^^^^^^^^^^^^^^^^^^^
  File "C:\Users\HP\anaconda3\envs\FedLearnCD\Lib\site-packages\ray\_private\worker.py", line 861, in get_objects
    raise value.as_instanceof_cause()
ray.exceptions.RayTaskError(ClientAppException): [36mray::ClientAppActor.run()[39m (pid=5088, ip=127.0.0.1, actor_id=201d4d61ad7bdf07591019d601000000, repr=<flwr.simulation.ray_transport.ray_actor.ClientAppActor object at 0x0000021AFA356350>)
                  ^^^^^^^^^^^^^^^^^^^^^^^^^^^^^^^^^^^^^
  File "C:\Users\HP\anaconda3\envs\FedLearnCD\Lib\site-packages\flwr\client\client_app.py", line 98, in __call__
    return self._call(message, context)
           ^^^^^^^^^^^^^^^^^^^^^^^^^^^^
  File "C:\Users\HP\anaconda3\envs\FedLearnCD\Lib\site-packages\flwr\client\client_app.py", line 81, in ffn
    out_message = handle_legacy_message_from_msgtype(
                  ^^^^^^^^^^^^^^^^^^^^^^^^^^^^^^^^^^^
  File "C:\Users\HP\anaconda3\envs\FedLearnCD\Lib\site-packages\flwr\client\message_handler\message_handler.py", line 137, in handle_legacy_message_from_msgtype
    evaluate_res = maybe_call_evaluate(
                   ^^^^^^^^^^^^^^^^^^^^
  File "C:\Users\HP\anaconda3\envs\FedLearnCD\Lib\site-packages\flwr\client\client.py", line 254, in maybe_call_evaluate
    return client.evaluate(evaluate_ins)
           ^^^^^^^^^^^^^^^^^^^^^^^^^^^^^
  File "C:\Users\HP\anaconda3\envs\FedLearnCD\Lib\site-packages\flwr\client\numpy_client.py", line 262, in _evaluate
    results = self.numpy_client.evaluate(parameters, ins.config)  # type: ignore
              ^^^^^^^^^^^^^^^^^^^^^^^^^^^^^^^^^^^^^^^^^^^^^^^^^^
  File "C:\Users\HP\Documents\FedAvgWithDrift\client.py", line 59, in evaluate
    loss, accuracy =  test(self.model, self.valloader, self.device)
                      ^^^^^^^^^^^^^^^^^^^^^^^^^^^^^^^^^^^^^^^^^^^^^
  File "C:\Users\HP\Documents\FedAvgWithDrift\model.py", line 50, in test
    for data in testloader:
  File "C:\Users\HP\anaconda3\envs\FedLearnCD\Lib\site-packages\torch\utils\data\dataloader.py", line 439, in __iter__
    return self._get_iterator()
           ^^^^^^^^^^^^^^^^^^^^
  File "C:\Users\HP\anaconda3\envs\FedLearnCD\Lib\site-packages\torch\utils\data\dataloader.py", line 387, in _get_iterator
    return _MultiProcessingDataLoaderIter(self)
           ^^^^^^^^^^^^^^^^^^^^^^^^^^^^^^^^^^^^
  File "C:\Users\HP\anaconda3\envs\FedLearnCD\Lib\site-packages\torch\utils\data\dataloader.py", line 1040, in __init__
    w.start()
  File "C:\Users\HP\anaconda3\envs\FedLearnCD\Lib\multiprocessing\process.py", line 121, in start
    self._popen = self._Popen(self)
                  ^^^^^^^^^^^^^^^^^
  File "C:\Users\HP\anaconda3\envs\FedLearnCD\Lib\multiprocessing\context.py", line 224, in _Popen
    return _default_context.get_context().Process._Popen(process_obj)
           ^^^^^^^^^^^^^^^^^^^^^^^^^^^^^^^^^^^^^^^^^^^^^^^^^^^^^^^^^^
  File "C:\Users\HP\anaconda3\envs\FedLearnCD\Lib\multiprocessing\context.py", line 336, in _Popen
    return Popen(process_obj)
           ^^^^^^^^^^^^^^^^^^
  File "C:\Users\HP\anaconda3\envs\FedLearnCD\Lib\multiprocessing\popen_spawn_win32.py", line 95, in __init__
    reduction.dump(process_obj, to_child)
  File "C:\Users\HP\anaconda3\envs\FedLearnCD\Lib\multiprocessing\reduction.py", line 60, in dump
    ForkingPickler(file, protocol).dump(obj)
OSError: [Errno 22] Invalid argument

The above exception was the direct cause of the following exception:

[36mray::ClientAppActor.run()[39m (pid=5088, ip=127.0.0.1, actor_id=201d4d61ad7bdf07591019d601000000, repr=<flwr.simulation.ray_transport.ray_actor.ClientAppActor object at 0x0000021AFA356350>)
  File "python\ray\_raylet.pyx", line 1881, in ray._raylet.execute_task
  File "python\ray\_raylet.pyx", line 1982, in ray._raylet.execute_task
  File "python\ray\_raylet.pyx", line 1887, in ray._raylet.execute_task
  File "python\ray\_raylet.pyx", line 1828, in ray._raylet.execute_task.function_executor
  File "C:\Users\HP\anaconda3\envs\FedLearnCD\Lib\site-packages\ray\_private\function_manager.py", line 691, in actor_method_executor
    return method(__ray_actor, *args, **kwargs)
           ^^^^^^^^^^^^^^^^^^^^^^^^^^^^^^^^^^^^
  File "C:\Users\HP\anaconda3\envs\FedLearnCD\Lib\site-packages\ray\util\tracing\tracing_helper.py", line 467, in _resume_span
    return method(self, *_args, **_kwargs)
           ^^^^^^^^^^^^^^^^^^^^^^^^^^^^^^^
  File "C:\Users\HP\anaconda3\envs\FedLearnCD\Lib\site-packages\flwr\simulation\ray_transport\ray_actor.py", line 64, in run
    raise ClientAppException(str(ex)) from ex
flwr.client.client_app.ClientAppException: 
Exception ClientAppException occurred. Message: [Errno 22] Invalid argument

[2024-05-04 19:06:48,042][flwr][ERROR] - Traceback (most recent call last):
  File "C:\Users\HP\anaconda3\envs\FedLearnCD\Lib\site-packages\flwr\simulation\ray_transport\ray_client_proxy.py", line 73, in _submit_job
    out_mssg, updated_context = self.actor_pool.get_client_result(
                                ^^^^^^^^^^^^^^^^^^^^^^^^^^^^^^^^^^
  File "C:\Users\HP\anaconda3\envs\FedLearnCD\Lib\site-packages\flwr\simulation\ray_transport\ray_actor.py", line 399, in get_client_result
    return self._fetch_future_result(cid)
           ^^^^^^^^^^^^^^^^^^^^^^^^^^^^^^
  File "C:\Users\HP\anaconda3\envs\FedLearnCD\Lib\site-packages\flwr\simulation\ray_transport\ray_actor.py", line 280, in _fetch_future_result
    res_cid, out_mssg, updated_context = ray.get(
                                         ^^^^^^^^
  File "C:\Users\HP\anaconda3\envs\FedLearnCD\Lib\site-packages\ray\_private\auto_init_hook.py", line 21, in auto_init_wrapper
    return fn(*args, **kwargs)
           ^^^^^^^^^^^^^^^^^^^
  File "C:\Users\HP\anaconda3\envs\FedLearnCD\Lib\site-packages\ray\_private\client_mode_hook.py", line 103, in wrapper
    return func(*args, **kwargs)
           ^^^^^^^^^^^^^^^^^^^^^
  File "C:\Users\HP\anaconda3\envs\FedLearnCD\Lib\site-packages\ray\_private\worker.py", line 2623, in get
    values, debugger_breakpoint = worker.get_objects(object_refs, timeout=timeout)
                                  ^^^^^^^^^^^^^^^^^^^^^^^^^^^^^^^^^^^^^^^^^^^^^^^^
  File "C:\Users\HP\anaconda3\envs\FedLearnCD\Lib\site-packages\ray\_private\worker.py", line 861, in get_objects
    raise value.as_instanceof_cause()
ray.exceptions.RayTaskError(ClientAppException): [36mray::ClientAppActor.run()[39m (pid=6532, ip=127.0.0.1, actor_id=abb66b9749a687783d54edf901000000, repr=<flwr.simulation.ray_transport.ray_actor.ClientAppActor object at 0x000001DEE96B15D0>)
                  ^^^^^^^^^^^^^^^^^^^^^^^^^^^^^^^^^^^^^
  File "C:\Users\HP\anaconda3\envs\FedLearnCD\Lib\site-packages\flwr\client\client_app.py", line 98, in __call__
    return self._call(message, context)
           ^^^^^^^^^^^^^^^^^^^^^^^^^^^^
  File "C:\Users\HP\anaconda3\envs\FedLearnCD\Lib\site-packages\flwr\client\client_app.py", line 81, in ffn
    out_message = handle_legacy_message_from_msgtype(
                  ^^^^^^^^^^^^^^^^^^^^^^^^^^^^^^^^^^^
  File "C:\Users\HP\anaconda3\envs\FedLearnCD\Lib\site-packages\flwr\client\message_handler\message_handler.py", line 137, in handle_legacy_message_from_msgtype
    evaluate_res = maybe_call_evaluate(
                   ^^^^^^^^^^^^^^^^^^^^
  File "C:\Users\HP\anaconda3\envs\FedLearnCD\Lib\site-packages\flwr\client\client.py", line 254, in maybe_call_evaluate
    return client.evaluate(evaluate_ins)
           ^^^^^^^^^^^^^^^^^^^^^^^^^^^^^
  File "C:\Users\HP\anaconda3\envs\FedLearnCD\Lib\site-packages\flwr\client\numpy_client.py", line 262, in _evaluate
    results = self.numpy_client.evaluate(parameters, ins.config)  # type: ignore
              ^^^^^^^^^^^^^^^^^^^^^^^^^^^^^^^^^^^^^^^^^^^^^^^^^^
  File "C:\Users\HP\Documents\FedAvgWithDrift\client.py", line 61, in evaluate
    return float(loss), len(self.valloadders), {'accurcay':accuracy}
                            ^^^^^^^^^^^^^^^^
AttributeError: 'FlowerClient' object has no attribute 'valloadders'

The above exception was the direct cause of the following exception:

[36mray::ClientAppActor.run()[39m (pid=6532, ip=127.0.0.1, actor_id=abb66b9749a687783d54edf901000000, repr=<flwr.simulation.ray_transport.ray_actor.ClientAppActor object at 0x000001DEE96B15D0>)
  File "python\ray\_raylet.pyx", line 1881, in ray._raylet.execute_task
  File "python\ray\_raylet.pyx", line 1982, in ray._raylet.execute_task
  File "python\ray\_raylet.pyx", line 1887, in ray._raylet.execute_task
  File "python\ray\_raylet.pyx", line 1828, in ray._raylet.execute_task.function_executor
  File "C:\Users\HP\anaconda3\envs\FedLearnCD\Lib\site-packages\ray\_private\function_manager.py", line 691, in actor_method_executor
    return method(__ray_actor, *args, **kwargs)
           ^^^^^^^^^^^^^^^^^^^^^^^^^^^^^^^^^^^^
  File "C:\Users\HP\anaconda3\envs\FedLearnCD\Lib\site-packages\ray\util\tracing\tracing_helper.py", line 467, in _resume_span
    return method(self, *_args, **_kwargs)
           ^^^^^^^^^^^^^^^^^^^^^^^^^^^^^^^
  File "C:\Users\HP\anaconda3\envs\FedLearnCD\Lib\site-packages\flwr\simulation\ray_transport\ray_actor.py", line 64, in run
    raise ClientAppException(str(ex)) from ex
flwr.client.client_app.ClientAppException: 
Exception ClientAppException occurred. Message: 'FlowerClient' object has no attribute 'valloadders'

[2024-05-04 19:06:48,092][flwr][ERROR] - [36mray::ClientAppActor.run()[39m (pid=5088, ip=127.0.0.1, actor_id=201d4d61ad7bdf07591019d601000000, repr=<flwr.simulation.ray_transport.ray_actor.ClientAppActor object at 0x0000021AFA356350>)
                  ^^^^^^^^^^^^^^^^^^^^^^^^^^^^^^^^^^^^^
  File "C:\Users\HP\anaconda3\envs\FedLearnCD\Lib\site-packages\flwr\client\client_app.py", line 98, in __call__
    return self._call(message, context)
           ^^^^^^^^^^^^^^^^^^^^^^^^^^^^
  File "C:\Users\HP\anaconda3\envs\FedLearnCD\Lib\site-packages\flwr\client\client_app.py", line 81, in ffn
    out_message = handle_legacy_message_from_msgtype(
                  ^^^^^^^^^^^^^^^^^^^^^^^^^^^^^^^^^^^
  File "C:\Users\HP\anaconda3\envs\FedLearnCD\Lib\site-packages\flwr\client\message_handler\message_handler.py", line 137, in handle_legacy_message_from_msgtype
    evaluate_res = maybe_call_evaluate(
                   ^^^^^^^^^^^^^^^^^^^^
  File "C:\Users\HP\anaconda3\envs\FedLearnCD\Lib\site-packages\flwr\client\client.py", line 254, in maybe_call_evaluate
    return client.evaluate(evaluate_ins)
           ^^^^^^^^^^^^^^^^^^^^^^^^^^^^^
  File "C:\Users\HP\anaconda3\envs\FedLearnCD\Lib\site-packages\flwr\client\numpy_client.py", line 262, in _evaluate
    results = self.numpy_client.evaluate(parameters, ins.config)  # type: ignore
              ^^^^^^^^^^^^^^^^^^^^^^^^^^^^^^^^^^^^^^^^^^^^^^^^^^
  File "C:\Users\HP\Documents\FedAvgWithDrift\client.py", line 59, in evaluate
    loss, accuracy =  test(self.model, self.valloader, self.device)
                      ^^^^^^^^^^^^^^^^^^^^^^^^^^^^^^^^^^^^^^^^^^^^^
  File "C:\Users\HP\Documents\FedAvgWithDrift\model.py", line 50, in test
    for data in testloader:
  File "C:\Users\HP\anaconda3\envs\FedLearnCD\Lib\site-packages\torch\utils\data\dataloader.py", line 439, in __iter__
    return self._get_iterator()
           ^^^^^^^^^^^^^^^^^^^^
  File "C:\Users\HP\anaconda3\envs\FedLearnCD\Lib\site-packages\torch\utils\data\dataloader.py", line 387, in _get_iterator
    return _MultiProcessingDataLoaderIter(self)
           ^^^^^^^^^^^^^^^^^^^^^^^^^^^^^^^^^^^^
  File "C:\Users\HP\anaconda3\envs\FedLearnCD\Lib\site-packages\torch\utils\data\dataloader.py", line 1040, in __init__
    w.start()
  File "C:\Users\HP\anaconda3\envs\FedLearnCD\Lib\multiprocessing\process.py", line 121, in start
    self._popen = self._Popen(self)
                  ^^^^^^^^^^^^^^^^^
  File "C:\Users\HP\anaconda3\envs\FedLearnCD\Lib\multiprocessing\context.py", line 224, in _Popen
    return _default_context.get_context().Process._Popen(process_obj)
           ^^^^^^^^^^^^^^^^^^^^^^^^^^^^^^^^^^^^^^^^^^^^^^^^^^^^^^^^^^
  File "C:\Users\HP\anaconda3\envs\FedLearnCD\Lib\multiprocessing\context.py", line 336, in _Popen
    return Popen(process_obj)
           ^^^^^^^^^^^^^^^^^^
  File "C:\Users\HP\anaconda3\envs\FedLearnCD\Lib\multiprocessing\popen_spawn_win32.py", line 95, in __init__
    reduction.dump(process_obj, to_child)
  File "C:\Users\HP\anaconda3\envs\FedLearnCD\Lib\multiprocessing\reduction.py", line 60, in dump
    ForkingPickler(file, protocol).dump(obj)
OSError: [Errno 22] Invalid argument

The above exception was the direct cause of the following exception:

[36mray::ClientAppActor.run()[39m (pid=5088, ip=127.0.0.1, actor_id=201d4d61ad7bdf07591019d601000000, repr=<flwr.simulation.ray_transport.ray_actor.ClientAppActor object at 0x0000021AFA356350>)
  File "python\ray\_raylet.pyx", line 1881, in ray._raylet.execute_task
  File "python\ray\_raylet.pyx", line 1982, in ray._raylet.execute_task
  File "python\ray\_raylet.pyx", line 1887, in ray._raylet.execute_task
  File "python\ray\_raylet.pyx", line 1828, in ray._raylet.execute_task.function_executor
  File "C:\Users\HP\anaconda3\envs\FedLearnCD\Lib\site-packages\ray\_private\function_manager.py", line 691, in actor_method_executor
    return method(__ray_actor, *args, **kwargs)
           ^^^^^^^^^^^^^^^^^^^^^^^^^^^^^^^^^^^^
  File "C:\Users\HP\anaconda3\envs\FedLearnCD\Lib\site-packages\ray\util\tracing\tracing_helper.py", line 467, in _resume_span
    return method(self, *_args, **_kwargs)
           ^^^^^^^^^^^^^^^^^^^^^^^^^^^^^^^
  File "C:\Users\HP\anaconda3\envs\FedLearnCD\Lib\site-packages\flwr\simulation\ray_transport\ray_actor.py", line 64, in run
    raise ClientAppException(str(ex)) from ex
flwr.client.client_app.ClientAppException: 
Exception ClientAppException occurred. Message: [Errno 22] Invalid argument
[2024-05-04 19:06:48,141][flwr][ERROR] - [36mray::ClientAppActor.run()[39m (pid=6532, ip=127.0.0.1, actor_id=abb66b9749a687783d54edf901000000, repr=<flwr.simulation.ray_transport.ray_actor.ClientAppActor object at 0x000001DEE96B15D0>)
                  ^^^^^^^^^^^^^^^^^^^^^^^^^^^^^^^^^^^^^
  File "C:\Users\HP\anaconda3\envs\FedLearnCD\Lib\site-packages\flwr\client\client_app.py", line 98, in __call__
    return self._call(message, context)
           ^^^^^^^^^^^^^^^^^^^^^^^^^^^^
  File "C:\Users\HP\anaconda3\envs\FedLearnCD\Lib\site-packages\flwr\client\client_app.py", line 81, in ffn
    out_message = handle_legacy_message_from_msgtype(
                  ^^^^^^^^^^^^^^^^^^^^^^^^^^^^^^^^^^^
  File "C:\Users\HP\anaconda3\envs\FedLearnCD\Lib\site-packages\flwr\client\message_handler\message_handler.py", line 137, in handle_legacy_message_from_msgtype
    evaluate_res = maybe_call_evaluate(
                   ^^^^^^^^^^^^^^^^^^^^
  File "C:\Users\HP\anaconda3\envs\FedLearnCD\Lib\site-packages\flwr\client\client.py", line 254, in maybe_call_evaluate
    return client.evaluate(evaluate_ins)
           ^^^^^^^^^^^^^^^^^^^^^^^^^^^^^
  File "C:\Users\HP\anaconda3\envs\FedLearnCD\Lib\site-packages\flwr\client\numpy_client.py", line 262, in _evaluate
    results = self.numpy_client.evaluate(parameters, ins.config)  # type: ignore
              ^^^^^^^^^^^^^^^^^^^^^^^^^^^^^^^^^^^^^^^^^^^^^^^^^^
  File "C:\Users\HP\Documents\FedAvgWithDrift\client.py", line 61, in evaluate
    return float(loss), len(self.valloadders), {'accurcay':accuracy}
                            ^^^^^^^^^^^^^^^^
AttributeError: 'FlowerClient' object has no attribute 'valloadders'

The above exception was the direct cause of the following exception:

[36mray::ClientAppActor.run()[39m (pid=6532, ip=127.0.0.1, actor_id=abb66b9749a687783d54edf901000000, repr=<flwr.simulation.ray_transport.ray_actor.ClientAppActor object at 0x000001DEE96B15D0>)
  File "python\ray\_raylet.pyx", line 1881, in ray._raylet.execute_task
  File "python\ray\_raylet.pyx", line 1982, in ray._raylet.execute_task
  File "python\ray\_raylet.pyx", line 1887, in ray._raylet.execute_task
  File "python\ray\_raylet.pyx", line 1828, in ray._raylet.execute_task.function_executor
  File "C:\Users\HP\anaconda3\envs\FedLearnCD\Lib\site-packages\ray\_private\function_manager.py", line 691, in actor_method_executor
    return method(__ray_actor, *args, **kwargs)
           ^^^^^^^^^^^^^^^^^^^^^^^^^^^^^^^^^^^^
  File "C:\Users\HP\anaconda3\envs\FedLearnCD\Lib\site-packages\ray\util\tracing\tracing_helper.py", line 467, in _resume_span
    return method(self, *_args, **_kwargs)
           ^^^^^^^^^^^^^^^^^^^^^^^^^^^^^^^
  File "C:\Users\HP\anaconda3\envs\FedLearnCD\Lib\site-packages\flwr\simulation\ray_transport\ray_actor.py", line 64, in run
    raise ClientAppException(str(ex)) from ex
flwr.client.client_app.ClientAppException: 
Exception ClientAppException occurred. Message: 'FlowerClient' object has no attribute 'valloadders'
[2024-05-04 19:06:55,686][flwr][ERROR] - Traceback (most recent call last):
  File "C:\Users\HP\anaconda3\envs\FedLearnCD\Lib\site-packages\flwr\simulation\ray_transport\ray_client_proxy.py", line 73, in _submit_job
    out_mssg, updated_context = self.actor_pool.get_client_result(
                                ^^^^^^^^^^^^^^^^^^^^^^^^^^^^^^^^^^
  File "C:\Users\HP\anaconda3\envs\FedLearnCD\Lib\site-packages\flwr\simulation\ray_transport\ray_actor.py", line 399, in get_client_result
    return self._fetch_future_result(cid)
           ^^^^^^^^^^^^^^^^^^^^^^^^^^^^^^
  File "C:\Users\HP\anaconda3\envs\FedLearnCD\Lib\site-packages\flwr\simulation\ray_transport\ray_actor.py", line 280, in _fetch_future_result
    res_cid, out_mssg, updated_context = ray.get(
                                         ^^^^^^^^
  File "C:\Users\HP\anaconda3\envs\FedLearnCD\Lib\site-packages\ray\_private\auto_init_hook.py", line 21, in auto_init_wrapper
    return fn(*args, **kwargs)
           ^^^^^^^^^^^^^^^^^^^
  File "C:\Users\HP\anaconda3\envs\FedLearnCD\Lib\site-packages\ray\_private\client_mode_hook.py", line 103, in wrapper
    return func(*args, **kwargs)
           ^^^^^^^^^^^^^^^^^^^^^
  File "C:\Users\HP\anaconda3\envs\FedLearnCD\Lib\site-packages\ray\_private\worker.py", line 2623, in get
    values, debugger_breakpoint = worker.get_objects(object_refs, timeout=timeout)
                                  ^^^^^^^^^^^^^^^^^^^^^^^^^^^^^^^^^^^^^^^^^^^^^^^^
  File "C:\Users\HP\anaconda3\envs\FedLearnCD\Lib\site-packages\ray\_private\worker.py", line 861, in get_objects
    raise value.as_instanceof_cause()
ray.exceptions.RayTaskError(ClientAppException): [36mray::ClientAppActor.run()[39m (pid=5092, ip=127.0.0.1, actor_id=7a73e292a6008c781ec56f8101000000, repr=<flwr.simulation.ray_transport.ray_actor.ClientAppActor object at 0x00000254ABDFFA10>)
                  ^^^^^^^^^^^^^^^^^^^^^^^^^^^^^^^^^^^^^
  File "C:\Users\HP\anaconda3\envs\FedLearnCD\Lib\site-packages\flwr\client\client_app.py", line 98, in __call__
    return self._call(message, context)
           ^^^^^^^^^^^^^^^^^^^^^^^^^^^^
  File "C:\Users\HP\anaconda3\envs\FedLearnCD\Lib\site-packages\flwr\client\client_app.py", line 81, in ffn
    out_message = handle_legacy_message_from_msgtype(
                  ^^^^^^^^^^^^^^^^^^^^^^^^^^^^^^^^^^^
  File "C:\Users\HP\anaconda3\envs\FedLearnCD\Lib\site-packages\flwr\client\message_handler\message_handler.py", line 137, in handle_legacy_message_from_msgtype
    evaluate_res = maybe_call_evaluate(
                   ^^^^^^^^^^^^^^^^^^^^
  File "C:\Users\HP\anaconda3\envs\FedLearnCD\Lib\site-packages\flwr\client\client.py", line 254, in maybe_call_evaluate
    return client.evaluate(evaluate_ins)
           ^^^^^^^^^^^^^^^^^^^^^^^^^^^^^
  File "C:\Users\HP\anaconda3\envs\FedLearnCD\Lib\site-packages\flwr\client\numpy_client.py", line 262, in _evaluate
    results = self.numpy_client.evaluate(parameters, ins.config)  # type: ignore
              ^^^^^^^^^^^^^^^^^^^^^^^^^^^^^^^^^^^^^^^^^^^^^^^^^^
  File "C:\Users\HP\Documents\FedAvgWithDrift\client.py", line 61, in evaluate
    return float(loss), len(self.valloadders), {'accurcay':accuracy}
                            ^^^^^^^^^^^^^^^^
AttributeError: 'FlowerClient' object has no attribute 'valloadders'

The above exception was the direct cause of the following exception:

[36mray::ClientAppActor.run()[39m (pid=5092, ip=127.0.0.1, actor_id=7a73e292a6008c781ec56f8101000000, repr=<flwr.simulation.ray_transport.ray_actor.ClientAppActor object at 0x00000254ABDFFA10>)
  File "python\ray\_raylet.pyx", line 1881, in ray._raylet.execute_task
  File "python\ray\_raylet.pyx", line 1982, in ray._raylet.execute_task
  File "python\ray\_raylet.pyx", line 1887, in ray._raylet.execute_task
  File "python\ray\_raylet.pyx", line 1828, in ray._raylet.execute_task.function_executor
  File "C:\Users\HP\anaconda3\envs\FedLearnCD\Lib\site-packages\ray\_private\function_manager.py", line 691, in actor_method_executor
    return method(__ray_actor, *args, **kwargs)
           ^^^^^^^^^^^^^^^^^^^^^^^^^^^^^^^^^^^^
  File "C:\Users\HP\anaconda3\envs\FedLearnCD\Lib\site-packages\ray\util\tracing\tracing_helper.py", line 467, in _resume_span
    return method(self, *_args, **_kwargs)
           ^^^^^^^^^^^^^^^^^^^^^^^^^^^^^^^
  File "C:\Users\HP\anaconda3\envs\FedLearnCD\Lib\site-packages\flwr\simulation\ray_transport\ray_actor.py", line 64, in run
    raise ClientAppException(str(ex)) from ex
flwr.client.client_app.ClientAppException: 
Exception ClientAppException occurred. Message: 'FlowerClient' object has no attribute 'valloadders'

[2024-05-04 19:06:55,720][flwr][ERROR] - [36mray::ClientAppActor.run()[39m (pid=5092, ip=127.0.0.1, actor_id=7a73e292a6008c781ec56f8101000000, repr=<flwr.simulation.ray_transport.ray_actor.ClientAppActor object at 0x00000254ABDFFA10>)
                  ^^^^^^^^^^^^^^^^^^^^^^^^^^^^^^^^^^^^^
  File "C:\Users\HP\anaconda3\envs\FedLearnCD\Lib\site-packages\flwr\client\client_app.py", line 98, in __call__
    return self._call(message, context)
           ^^^^^^^^^^^^^^^^^^^^^^^^^^^^
  File "C:\Users\HP\anaconda3\envs\FedLearnCD\Lib\site-packages\flwr\client\client_app.py", line 81, in ffn
    out_message = handle_legacy_message_from_msgtype(
                  ^^^^^^^^^^^^^^^^^^^^^^^^^^^^^^^^^^^
  File "C:\Users\HP\anaconda3\envs\FedLearnCD\Lib\site-packages\flwr\client\message_handler\message_handler.py", line 137, in handle_legacy_message_from_msgtype
    evaluate_res = maybe_call_evaluate(
                   ^^^^^^^^^^^^^^^^^^^^
  File "C:\Users\HP\anaconda3\envs\FedLearnCD\Lib\site-packages\flwr\client\client.py", line 254, in maybe_call_evaluate
    return client.evaluate(evaluate_ins)
           ^^^^^^^^^^^^^^^^^^^^^^^^^^^^^
  File "C:\Users\HP\anaconda3\envs\FedLearnCD\Lib\site-packages\flwr\client\numpy_client.py", line 262, in _evaluate
    results = self.numpy_client.evaluate(parameters, ins.config)  # type: ignore
              ^^^^^^^^^^^^^^^^^^^^^^^^^^^^^^^^^^^^^^^^^^^^^^^^^^
  File "C:\Users\HP\Documents\FedAvgWithDrift\client.py", line 61, in evaluate
    return float(loss), len(self.valloadders), {'accurcay':accuracy}
                            ^^^^^^^^^^^^^^^^
AttributeError: 'FlowerClient' object has no attribute 'valloadders'

The above exception was the direct cause of the following exception:

[36mray::ClientAppActor.run()[39m (pid=5092, ip=127.0.0.1, actor_id=7a73e292a6008c781ec56f8101000000, repr=<flwr.simulation.ray_transport.ray_actor.ClientAppActor object at 0x00000254ABDFFA10>)
  File "python\ray\_raylet.pyx", line 1881, in ray._raylet.execute_task
  File "python\ray\_raylet.pyx", line 1982, in ray._raylet.execute_task
  File "python\ray\_raylet.pyx", line 1887, in ray._raylet.execute_task
  File "python\ray\_raylet.pyx", line 1828, in ray._raylet.execute_task.function_executor
  File "C:\Users\HP\anaconda3\envs\FedLearnCD\Lib\site-packages\ray\_private\function_manager.py", line 691, in actor_method_executor
    return method(__ray_actor, *args, **kwargs)
           ^^^^^^^^^^^^^^^^^^^^^^^^^^^^^^^^^^^^
  File "C:\Users\HP\anaconda3\envs\FedLearnCD\Lib\site-packages\ray\util\tracing\tracing_helper.py", line 467, in _resume_span
    return method(self, *_args, **_kwargs)
           ^^^^^^^^^^^^^^^^^^^^^^^^^^^^^^^
  File "C:\Users\HP\anaconda3\envs\FedLearnCD\Lib\site-packages\flwr\simulation\ray_transport\ray_actor.py", line 64, in run
    raise ClientAppException(str(ex)) from ex
flwr.client.client_app.ClientAppException: 
Exception ClientAppException occurred. Message: 'FlowerClient' object has no attribute 'valloadders'
[2024-05-04 19:07:00,260][flwr][ERROR] - Traceback (most recent call last):
  File "C:\Users\HP\anaconda3\envs\FedLearnCD\Lib\site-packages\flwr\simulation\ray_transport\ray_client_proxy.py", line 73, in _submit_job
    out_mssg, updated_context = self.actor_pool.get_client_result(
                                ^^^^^^^^^^^^^^^^^^^^^^^^^^^^^^^^^^
  File "C:\Users\HP\anaconda3\envs\FedLearnCD\Lib\site-packages\flwr\simulation\ray_transport\ray_actor.py", line 399, in get_client_result
    return self._fetch_future_result(cid)
           ^^^^^^^^^^^^^^^^^^^^^^^^^^^^^^
  File "C:\Users\HP\anaconda3\envs\FedLearnCD\Lib\site-packages\flwr\simulation\ray_transport\ray_actor.py", line 280, in _fetch_future_result
    res_cid, out_mssg, updated_context = ray.get(
                                         ^^^^^^^^
  File "C:\Users\HP\anaconda3\envs\FedLearnCD\Lib\site-packages\ray\_private\auto_init_hook.py", line 21, in auto_init_wrapper
    return fn(*args, **kwargs)
           ^^^^^^^^^^^^^^^^^^^
  File "C:\Users\HP\anaconda3\envs\FedLearnCD\Lib\site-packages\ray\_private\client_mode_hook.py", line 103, in wrapper
    return func(*args, **kwargs)
           ^^^^^^^^^^^^^^^^^^^^^
  File "C:\Users\HP\anaconda3\envs\FedLearnCD\Lib\site-packages\ray\_private\worker.py", line 2623, in get
    values, debugger_breakpoint = worker.get_objects(object_refs, timeout=timeout)
                                  ^^^^^^^^^^^^^^^^^^^^^^^^^^^^^^^^^^^^^^^^^^^^^^^^
  File "C:\Users\HP\anaconda3\envs\FedLearnCD\Lib\site-packages\ray\_private\worker.py", line 861, in get_objects
    raise value.as_instanceof_cause()
ray.exceptions.RayTaskError(ClientAppException): [36mray::ClientAppActor.run()[39m (pid=6536, ip=127.0.0.1, actor_id=14f677eaa3c4366b55bf407501000000, repr=<flwr.simulation.ray_transport.ray_actor.ClientAppActor object at 0x000001D1AFF26290>)
                  ^^^^^^^^^^^^^^^^^^^^^^^^^^^^^^^^^^^^^
  File "C:\Users\HP\anaconda3\envs\FedLearnCD\Lib\site-packages\flwr\client\client_app.py", line 98, in __call__
    return self._call(message, context)
           ^^^^^^^^^^^^^^^^^^^^^^^^^^^^
  File "C:\Users\HP\anaconda3\envs\FedLearnCD\Lib\site-packages\flwr\client\client_app.py", line 81, in ffn
    out_message = handle_legacy_message_from_msgtype(
                  ^^^^^^^^^^^^^^^^^^^^^^^^^^^^^^^^^^^
  File "C:\Users\HP\anaconda3\envs\FedLearnCD\Lib\site-packages\flwr\client\message_handler\message_handler.py", line 137, in handle_legacy_message_from_msgtype
    evaluate_res = maybe_call_evaluate(
                   ^^^^^^^^^^^^^^^^^^^^
  File "C:\Users\HP\anaconda3\envs\FedLearnCD\Lib\site-packages\flwr\client\client.py", line 254, in maybe_call_evaluate
    return client.evaluate(evaluate_ins)
           ^^^^^^^^^^^^^^^^^^^^^^^^^^^^^
  File "C:\Users\HP\anaconda3\envs\FedLearnCD\Lib\site-packages\flwr\client\numpy_client.py", line 262, in _evaluate
    results = self.numpy_client.evaluate(parameters, ins.config)  # type: ignore
              ^^^^^^^^^^^^^^^^^^^^^^^^^^^^^^^^^^^^^^^^^^^^^^^^^^
  File "C:\Users\HP\Documents\FedAvgWithDrift\client.py", line 61, in evaluate
    return float(loss), len(self.valloadders), {'accurcay':accuracy}
                            ^^^^^^^^^^^^^^^^
AttributeError: 'FlowerClient' object has no attribute 'valloadders'

The above exception was the direct cause of the following exception:

[36mray::ClientAppActor.run()[39m (pid=6536, ip=127.0.0.1, actor_id=14f677eaa3c4366b55bf407501000000, repr=<flwr.simulation.ray_transport.ray_actor.ClientAppActor object at 0x000001D1AFF26290>)
  File "python\ray\_raylet.pyx", line 1881, in ray._raylet.execute_task
  File "python\ray\_raylet.pyx", line 1982, in ray._raylet.execute_task
  File "python\ray\_raylet.pyx", line 1887, in ray._raylet.execute_task
  File "python\ray\_raylet.pyx", line 1828, in ray._raylet.execute_task.function_executor
  File "C:\Users\HP\anaconda3\envs\FedLearnCD\Lib\site-packages\ray\_private\function_manager.py", line 691, in actor_method_executor
    return method(__ray_actor, *args, **kwargs)
           ^^^^^^^^^^^^^^^^^^^^^^^^^^^^^^^^^^^^
  File "C:\Users\HP\anaconda3\envs\FedLearnCD\Lib\site-packages\ray\util\tracing\tracing_helper.py", line 467, in _resume_span
    return method(self, *_args, **_kwargs)
           ^^^^^^^^^^^^^^^^^^^^^^^^^^^^^^^
  File "C:\Users\HP\anaconda3\envs\FedLearnCD\Lib\site-packages\flwr\simulation\ray_transport\ray_actor.py", line 64, in run
    raise ClientAppException(str(ex)) from ex
flwr.client.client_app.ClientAppException: 
Exception ClientAppException occurred. Message: 'FlowerClient' object has no attribute 'valloadders'

[2024-05-04 19:07:00,280][flwr][ERROR] - [36mray::ClientAppActor.run()[39m (pid=6536, ip=127.0.0.1, actor_id=14f677eaa3c4366b55bf407501000000, repr=<flwr.simulation.ray_transport.ray_actor.ClientAppActor object at 0x000001D1AFF26290>)
                  ^^^^^^^^^^^^^^^^^^^^^^^^^^^^^^^^^^^^^
  File "C:\Users\HP\anaconda3\envs\FedLearnCD\Lib\site-packages\flwr\client\client_app.py", line 98, in __call__
    return self._call(message, context)
           ^^^^^^^^^^^^^^^^^^^^^^^^^^^^
  File "C:\Users\HP\anaconda3\envs\FedLearnCD\Lib\site-packages\flwr\client\client_app.py", line 81, in ffn
    out_message = handle_legacy_message_from_msgtype(
                  ^^^^^^^^^^^^^^^^^^^^^^^^^^^^^^^^^^^
  File "C:\Users\HP\anaconda3\envs\FedLearnCD\Lib\site-packages\flwr\client\message_handler\message_handler.py", line 137, in handle_legacy_message_from_msgtype
    evaluate_res = maybe_call_evaluate(
                   ^^^^^^^^^^^^^^^^^^^^
  File "C:\Users\HP\anaconda3\envs\FedLearnCD\Lib\site-packages\flwr\client\client.py", line 254, in maybe_call_evaluate
    return client.evaluate(evaluate_ins)
           ^^^^^^^^^^^^^^^^^^^^^^^^^^^^^
  File "C:\Users\HP\anaconda3\envs\FedLearnCD\Lib\site-packages\flwr\client\numpy_client.py", line 262, in _evaluate
    results = self.numpy_client.evaluate(parameters, ins.config)  # type: ignore
              ^^^^^^^^^^^^^^^^^^^^^^^^^^^^^^^^^^^^^^^^^^^^^^^^^^
  File "C:\Users\HP\Documents\FedAvgWithDrift\client.py", line 61, in evaluate
    return float(loss), len(self.valloadders), {'accurcay':accuracy}
                            ^^^^^^^^^^^^^^^^
AttributeError: 'FlowerClient' object has no attribute 'valloadders'

The above exception was the direct cause of the following exception:

[36mray::ClientAppActor.run()[39m (pid=6536, ip=127.0.0.1, actor_id=14f677eaa3c4366b55bf407501000000, repr=<flwr.simulation.ray_transport.ray_actor.ClientAppActor object at 0x000001D1AFF26290>)
  File "python\ray\_raylet.pyx", line 1881, in ray._raylet.execute_task
  File "python\ray\_raylet.pyx", line 1982, in ray._raylet.execute_task
  File "python\ray\_raylet.pyx", line 1887, in ray._raylet.execute_task
  File "python\ray\_raylet.pyx", line 1828, in ray._raylet.execute_task.function_executor
  File "C:\Users\HP\anaconda3\envs\FedLearnCD\Lib\site-packages\ray\_private\function_manager.py", line 691, in actor_method_executor
    return method(__ray_actor, *args, **kwargs)
           ^^^^^^^^^^^^^^^^^^^^^^^^^^^^^^^^^^^^
  File "C:\Users\HP\anaconda3\envs\FedLearnCD\Lib\site-packages\ray\util\tracing\tracing_helper.py", line 467, in _resume_span
    return method(self, *_args, **_kwargs)
           ^^^^^^^^^^^^^^^^^^^^^^^^^^^^^^^
  File "C:\Users\HP\anaconda3\envs\FedLearnCD\Lib\site-packages\flwr\simulation\ray_transport\ray_actor.py", line 64, in run
    raise ClientAppException(str(ex)) from ex
flwr.client.client_app.ClientAppException: 
Exception ClientAppException occurred. Message: 'FlowerClient' object has no attribute 'valloadders'
[2024-05-04 19:07:06,848][flwr][ERROR] - Traceback (most recent call last):
  File "C:\Users\HP\anaconda3\envs\FedLearnCD\Lib\site-packages\flwr\simulation\ray_transport\ray_client_proxy.py", line 73, in _submit_job
    out_mssg, updated_context = self.actor_pool.get_client_result(
                                ^^^^^^^^^^^^^^^^^^^^^^^^^^^^^^^^^^
  File "C:\Users\HP\anaconda3\envs\FedLearnCD\Lib\site-packages\flwr\simulation\ray_transport\ray_actor.py", line 399, in get_client_result
    return self._fetch_future_result(cid)
           ^^^^^^^^^^^^^^^^^^^^^^^^^^^^^^
  File "C:\Users\HP\anaconda3\envs\FedLearnCD\Lib\site-packages\flwr\simulation\ray_transport\ray_actor.py", line 280, in _fetch_future_result
    res_cid, out_mssg, updated_context = ray.get(
                                         ^^^^^^^^
  File "C:\Users\HP\anaconda3\envs\FedLearnCD\Lib\site-packages\ray\_private\auto_init_hook.py", line 21, in auto_init_wrapper
    return fn(*args, **kwargs)
           ^^^^^^^^^^^^^^^^^^^
  File "C:\Users\HP\anaconda3\envs\FedLearnCD\Lib\site-packages\ray\_private\client_mode_hook.py", line 103, in wrapper
    return func(*args, **kwargs)
           ^^^^^^^^^^^^^^^^^^^^^
  File "C:\Users\HP\anaconda3\envs\FedLearnCD\Lib\site-packages\ray\_private\worker.py", line 2623, in get
    values, debugger_breakpoint = worker.get_objects(object_refs, timeout=timeout)
                                  ^^^^^^^^^^^^^^^^^^^^^^^^^^^^^^^^^^^^^^^^^^^^^^^^
  File "C:\Users\HP\anaconda3\envs\FedLearnCD\Lib\site-packages\ray\_private\worker.py", line 861, in get_objects
    raise value.as_instanceof_cause()
ray.exceptions.RayTaskError(ClientAppException): [36mray::ClientAppActor.run()[39m (pid=15152, ip=127.0.0.1, actor_id=71dd2c767790f01f0571c8c701000000, repr=<flwr.simulation.ray_transport.ray_actor.ClientAppActor object at 0x000001CAD7736850>)
                  ^^^^^^^^^^^^^^^^^^^^^^^^^^^^^^^^^^^^^
  File "C:\Users\HP\anaconda3\envs\FedLearnCD\Lib\site-packages\flwr\client\client_app.py", line 98, in __call__
    return self._call(message, context)
           ^^^^^^^^^^^^^^^^^^^^^^^^^^^^
  File "C:\Users\HP\anaconda3\envs\FedLearnCD\Lib\site-packages\flwr\client\client_app.py", line 81, in ffn
    out_message = handle_legacy_message_from_msgtype(
                  ^^^^^^^^^^^^^^^^^^^^^^^^^^^^^^^^^^^
  File "C:\Users\HP\anaconda3\envs\FedLearnCD\Lib\site-packages\flwr\client\message_handler\message_handler.py", line 137, in handle_legacy_message_from_msgtype
    evaluate_res = maybe_call_evaluate(
                   ^^^^^^^^^^^^^^^^^^^^
  File "C:\Users\HP\anaconda3\envs\FedLearnCD\Lib\site-packages\flwr\client\client.py", line 254, in maybe_call_evaluate
    return client.evaluate(evaluate_ins)
           ^^^^^^^^^^^^^^^^^^^^^^^^^^^^^
  File "C:\Users\HP\anaconda3\envs\FedLearnCD\Lib\site-packages\flwr\client\numpy_client.py", line 262, in _evaluate
    results = self.numpy_client.evaluate(parameters, ins.config)  # type: ignore
              ^^^^^^^^^^^^^^^^^^^^^^^^^^^^^^^^^^^^^^^^^^^^^^^^^^
  File "C:\Users\HP\Documents\FedAvgWithDrift\client.py", line 61, in evaluate
    return float(loss), len(self.valloadders), {'accurcay':accuracy}
                            ^^^^^^^^^^^^^^^^
AttributeError: 'FlowerClient' object has no attribute 'valloadders'

The above exception was the direct cause of the following exception:

[36mray::ClientAppActor.run()[39m (pid=15152, ip=127.0.0.1, actor_id=71dd2c767790f01f0571c8c701000000, repr=<flwr.simulation.ray_transport.ray_actor.ClientAppActor object at 0x000001CAD7736850>)
  File "python\ray\_raylet.pyx", line 1881, in ray._raylet.execute_task
  File "python\ray\_raylet.pyx", line 1982, in ray._raylet.execute_task
  File "python\ray\_raylet.pyx", line 1887, in ray._raylet.execute_task
  File "python\ray\_raylet.pyx", line 1828, in ray._raylet.execute_task.function_executor
  File "C:\Users\HP\anaconda3\envs\FedLearnCD\Lib\site-packages\ray\_private\function_manager.py", line 691, in actor_method_executor
    return method(__ray_actor, *args, **kwargs)
           ^^^^^^^^^^^^^^^^^^^^^^^^^^^^^^^^^^^^
  File "C:\Users\HP\anaconda3\envs\FedLearnCD\Lib\site-packages\ray\util\tracing\tracing_helper.py", line 467, in _resume_span
    return method(self, *_args, **_kwargs)
           ^^^^^^^^^^^^^^^^^^^^^^^^^^^^^^^
  File "C:\Users\HP\anaconda3\envs\FedLearnCD\Lib\site-packages\flwr\simulation\ray_transport\ray_actor.py", line 64, in run
    raise ClientAppException(str(ex)) from ex
flwr.client.client_app.ClientAppException: 
Exception ClientAppException occurred. Message: 'FlowerClient' object has no attribute 'valloadders'

[2024-05-04 19:07:06,862][flwr][ERROR] - [36mray::ClientAppActor.run()[39m (pid=15152, ip=127.0.0.1, actor_id=71dd2c767790f01f0571c8c701000000, repr=<flwr.simulation.ray_transport.ray_actor.ClientAppActor object at 0x000001CAD7736850>)
                  ^^^^^^^^^^^^^^^^^^^^^^^^^^^^^^^^^^^^^
  File "C:\Users\HP\anaconda3\envs\FedLearnCD\Lib\site-packages\flwr\client\client_app.py", line 98, in __call__
    return self._call(message, context)
           ^^^^^^^^^^^^^^^^^^^^^^^^^^^^
  File "C:\Users\HP\anaconda3\envs\FedLearnCD\Lib\site-packages\flwr\client\client_app.py", line 81, in ffn
    out_message = handle_legacy_message_from_msgtype(
                  ^^^^^^^^^^^^^^^^^^^^^^^^^^^^^^^^^^^
  File "C:\Users\HP\anaconda3\envs\FedLearnCD\Lib\site-packages\flwr\client\message_handler\message_handler.py", line 137, in handle_legacy_message_from_msgtype
    evaluate_res = maybe_call_evaluate(
                   ^^^^^^^^^^^^^^^^^^^^
  File "C:\Users\HP\anaconda3\envs\FedLearnCD\Lib\site-packages\flwr\client\client.py", line 254, in maybe_call_evaluate
    return client.evaluate(evaluate_ins)
           ^^^^^^^^^^^^^^^^^^^^^^^^^^^^^
  File "C:\Users\HP\anaconda3\envs\FedLearnCD\Lib\site-packages\flwr\client\numpy_client.py", line 262, in _evaluate
    results = self.numpy_client.evaluate(parameters, ins.config)  # type: ignore
              ^^^^^^^^^^^^^^^^^^^^^^^^^^^^^^^^^^^^^^^^^^^^^^^^^^
  File "C:\Users\HP\Documents\FedAvgWithDrift\client.py", line 61, in evaluate
    return float(loss), len(self.valloadders), {'accurcay':accuracy}
                            ^^^^^^^^^^^^^^^^
AttributeError: 'FlowerClient' object has no attribute 'valloadders'

The above exception was the direct cause of the following exception:

[36mray::ClientAppActor.run()[39m (pid=15152, ip=127.0.0.1, actor_id=71dd2c767790f01f0571c8c701000000, repr=<flwr.simulation.ray_transport.ray_actor.ClientAppActor object at 0x000001CAD7736850>)
  File "python\ray\_raylet.pyx", line 1881, in ray._raylet.execute_task
  File "python\ray\_raylet.pyx", line 1982, in ray._raylet.execute_task
  File "python\ray\_raylet.pyx", line 1887, in ray._raylet.execute_task
  File "python\ray\_raylet.pyx", line 1828, in ray._raylet.execute_task.function_executor
  File "C:\Users\HP\anaconda3\envs\FedLearnCD\Lib\site-packages\ray\_private\function_manager.py", line 691, in actor_method_executor
    return method(__ray_actor, *args, **kwargs)
           ^^^^^^^^^^^^^^^^^^^^^^^^^^^^^^^^^^^^
  File "C:\Users\HP\anaconda3\envs\FedLearnCD\Lib\site-packages\ray\util\tracing\tracing_helper.py", line 467, in _resume_span
    return method(self, *_args, **_kwargs)
           ^^^^^^^^^^^^^^^^^^^^^^^^^^^^^^^
  File "C:\Users\HP\anaconda3\envs\FedLearnCD\Lib\site-packages\flwr\simulation\ray_transport\ray_actor.py", line 64, in run
    raise ClientAppException(str(ex)) from ex
flwr.client.client_app.ClientAppException: 
Exception ClientAppException occurred. Message: 'FlowerClient' object has no attribute 'valloadders'
[2024-05-04 19:07:06,879][flwr][INFO] - aggregate_evaluate: received 0 results and 5 failures
[2024-05-04 19:07:06,881][flwr][INFO] - 
[2024-05-04 19:07:06,881][flwr][INFO] - [ROUND 3]
[2024-05-04 19:07:06,882][flwr][INFO] - Sampling failed: number of available clients (5) is less than number of requested clients (10).
[2024-05-04 19:07:06,883][flwr][INFO] - configure_fit: no clients selected, cancel
[2024-05-04 19:07:11,593][flwr][INFO] - fit progress: (3, 182.11450600624084, {'accuracy': 0.1}, 114.8600626999978)
[2024-05-04 19:07:11,593][flwr][INFO] - configure_evaluate: strategy sampled 5 clients (out of 5)
[2024-05-04 19:07:45,617][flwr][ERROR] - Traceback (most recent call last):
  File "C:\Users\HP\anaconda3\envs\FedLearnCD\Lib\site-packages\flwr\simulation\ray_transport\ray_client_proxy.py", line 73, in _submit_job
    out_mssg, updated_context = self.actor_pool.get_client_result(
                                ^^^^^^^^^^^^^^^^^^^^^^^^^^^^^^^^^^
  File "C:\Users\HP\anaconda3\envs\FedLearnCD\Lib\site-packages\flwr\simulation\ray_transport\ray_actor.py", line 399, in get_client_result
    return self._fetch_future_result(cid)
           ^^^^^^^^^^^^^^^^^^^^^^^^^^^^^^
  File "C:\Users\HP\anaconda3\envs\FedLearnCD\Lib\site-packages\flwr\simulation\ray_transport\ray_actor.py", line 280, in _fetch_future_result
    res_cid, out_mssg, updated_context = ray.get(
                                         ^^^^^^^^
  File "C:\Users\HP\anaconda3\envs\FedLearnCD\Lib\site-packages\ray\_private\auto_init_hook.py", line 21, in auto_init_wrapper
    return fn(*args, **kwargs)
           ^^^^^^^^^^^^^^^^^^^
  File "C:\Users\HP\anaconda3\envs\FedLearnCD\Lib\site-packages\ray\_private\client_mode_hook.py", line 103, in wrapper
    return func(*args, **kwargs)
           ^^^^^^^^^^^^^^^^^^^^^
  File "C:\Users\HP\anaconda3\envs\FedLearnCD\Lib\site-packages\ray\_private\worker.py", line 2623, in get
    values, debugger_breakpoint = worker.get_objects(object_refs, timeout=timeout)
                                  ^^^^^^^^^^^^^^^^^^^^^^^^^^^^^^^^^^^^^^^^^^^^^^^^
  File "C:\Users\HP\anaconda3\envs\FedLearnCD\Lib\site-packages\ray\_private\worker.py", line 861, in get_objects
    raise value.as_instanceof_cause()
ray.exceptions.RayTaskError(ClientAppException): [36mray::ClientAppActor.run()[39m (pid=15152, ip=127.0.0.1, actor_id=71dd2c767790f01f0571c8c701000000, repr=<flwr.simulation.ray_transport.ray_actor.ClientAppActor object at 0x000001CAD7736850>)
                  ^^^^^^^^^^^^^^^^^^^^^^^^^^^^^^^^^^^^^
  File "C:\Users\HP\anaconda3\envs\FedLearnCD\Lib\site-packages\flwr\client\client_app.py", line 98, in __call__
    return self._call(message, context)
           ^^^^^^^^^^^^^^^^^^^^^^^^^^^^
  File "C:\Users\HP\anaconda3\envs\FedLearnCD\Lib\site-packages\flwr\client\client_app.py", line 81, in ffn
    out_message = handle_legacy_message_from_msgtype(
                  ^^^^^^^^^^^^^^^^^^^^^^^^^^^^^^^^^^^
  File "C:\Users\HP\anaconda3\envs\FedLearnCD\Lib\site-packages\flwr\client\message_handler\message_handler.py", line 137, in handle_legacy_message_from_msgtype
    evaluate_res = maybe_call_evaluate(
                   ^^^^^^^^^^^^^^^^^^^^
  File "C:\Users\HP\anaconda3\envs\FedLearnCD\Lib\site-packages\flwr\client\client.py", line 254, in maybe_call_evaluate
    return client.evaluate(evaluate_ins)
           ^^^^^^^^^^^^^^^^^^^^^^^^^^^^^
  File "C:\Users\HP\anaconda3\envs\FedLearnCD\Lib\site-packages\flwr\client\numpy_client.py", line 262, in _evaluate
    results = self.numpy_client.evaluate(parameters, ins.config)  # type: ignore
              ^^^^^^^^^^^^^^^^^^^^^^^^^^^^^^^^^^^^^^^^^^^^^^^^^^
  File "C:\Users\HP\Documents\FedAvgWithDrift\client.py", line 61, in evaluate
    return float(loss), len(self.valloadders), {'accurcay':accuracy}
                            ^^^^^^^^^^^^^^^^
AttributeError: 'FlowerClient' object has no attribute 'valloadders'

The above exception was the direct cause of the following exception:

[36mray::ClientAppActor.run()[39m (pid=15152, ip=127.0.0.1, actor_id=71dd2c767790f01f0571c8c701000000, repr=<flwr.simulation.ray_transport.ray_actor.ClientAppActor object at 0x000001CAD7736850>)
  File "python\ray\_raylet.pyx", line 1881, in ray._raylet.execute_task
  File "python\ray\_raylet.pyx", line 1982, in ray._raylet.execute_task
  File "python\ray\_raylet.pyx", line 1887, in ray._raylet.execute_task
  File "python\ray\_raylet.pyx", line 1828, in ray._raylet.execute_task.function_executor
  File "C:\Users\HP\anaconda3\envs\FedLearnCD\Lib\site-packages\ray\_private\function_manager.py", line 691, in actor_method_executor
    return method(__ray_actor, *args, **kwargs)
           ^^^^^^^^^^^^^^^^^^^^^^^^^^^^^^^^^^^^
  File "C:\Users\HP\anaconda3\envs\FedLearnCD\Lib\site-packages\ray\util\tracing\tracing_helper.py", line 467, in _resume_span
    return method(self, *_args, **_kwargs)
           ^^^^^^^^^^^^^^^^^^^^^^^^^^^^^^^
  File "C:\Users\HP\anaconda3\envs\FedLearnCD\Lib\site-packages\flwr\simulation\ray_transport\ray_actor.py", line 64, in run
    raise ClientAppException(str(ex)) from ex
flwr.client.client_app.ClientAppException: 
Exception ClientAppException occurred. Message: 'FlowerClient' object has no attribute 'valloadders'

[2024-05-04 19:07:45,685][flwr][ERROR] - [36mray::ClientAppActor.run()[39m (pid=15152, ip=127.0.0.1, actor_id=71dd2c767790f01f0571c8c701000000, repr=<flwr.simulation.ray_transport.ray_actor.ClientAppActor object at 0x000001CAD7736850>)
                  ^^^^^^^^^^^^^^^^^^^^^^^^^^^^^^^^^^^^^
  File "C:\Users\HP\anaconda3\envs\FedLearnCD\Lib\site-packages\flwr\client\client_app.py", line 98, in __call__
    return self._call(message, context)
           ^^^^^^^^^^^^^^^^^^^^^^^^^^^^
  File "C:\Users\HP\anaconda3\envs\FedLearnCD\Lib\site-packages\flwr\client\client_app.py", line 81, in ffn
    out_message = handle_legacy_message_from_msgtype(
                  ^^^^^^^^^^^^^^^^^^^^^^^^^^^^^^^^^^^
  File "C:\Users\HP\anaconda3\envs\FedLearnCD\Lib\site-packages\flwr\client\message_handler\message_handler.py", line 137, in handle_legacy_message_from_msgtype
    evaluate_res = maybe_call_evaluate(
                   ^^^^^^^^^^^^^^^^^^^^
  File "C:\Users\HP\anaconda3\envs\FedLearnCD\Lib\site-packages\flwr\client\client.py", line 254, in maybe_call_evaluate
    return client.evaluate(evaluate_ins)
           ^^^^^^^^^^^^^^^^^^^^^^^^^^^^^
  File "C:\Users\HP\anaconda3\envs\FedLearnCD\Lib\site-packages\flwr\client\numpy_client.py", line 262, in _evaluate
    results = self.numpy_client.evaluate(parameters, ins.config)  # type: ignore
              ^^^^^^^^^^^^^^^^^^^^^^^^^^^^^^^^^^^^^^^^^^^^^^^^^^
  File "C:\Users\HP\Documents\FedAvgWithDrift\client.py", line 61, in evaluate
    return float(loss), len(self.valloadders), {'accurcay':accuracy}
                            ^^^^^^^^^^^^^^^^
AttributeError: 'FlowerClient' object has no attribute 'valloadders'

The above exception was the direct cause of the following exception:

[36mray::ClientAppActor.run()[39m (pid=15152, ip=127.0.0.1, actor_id=71dd2c767790f01f0571c8c701000000, repr=<flwr.simulation.ray_transport.ray_actor.ClientAppActor object at 0x000001CAD7736850>)
  File "python\ray\_raylet.pyx", line 1881, in ray._raylet.execute_task
  File "python\ray\_raylet.pyx", line 1982, in ray._raylet.execute_task
  File "python\ray\_raylet.pyx", line 1887, in ray._raylet.execute_task
  File "python\ray\_raylet.pyx", line 1828, in ray._raylet.execute_task.function_executor
  File "C:\Users\HP\anaconda3\envs\FedLearnCD\Lib\site-packages\ray\_private\function_manager.py", line 691, in actor_method_executor
    return method(__ray_actor, *args, **kwargs)
           ^^^^^^^^^^^^^^^^^^^^^^^^^^^^^^^^^^^^
  File "C:\Users\HP\anaconda3\envs\FedLearnCD\Lib\site-packages\ray\util\tracing\tracing_helper.py", line 467, in _resume_span
    return method(self, *_args, **_kwargs)
           ^^^^^^^^^^^^^^^^^^^^^^^^^^^^^^^
  File "C:\Users\HP\anaconda3\envs\FedLearnCD\Lib\site-packages\flwr\simulation\ray_transport\ray_actor.py", line 64, in run
    raise ClientAppException(str(ex)) from ex
flwr.client.client_app.ClientAppException: 
Exception ClientAppException occurred. Message: 'FlowerClient' object has no attribute 'valloadders'
[2024-05-04 19:07:46,565][flwr][ERROR] - Traceback (most recent call last):
  File "C:\Users\HP\anaconda3\envs\FedLearnCD\Lib\site-packages\flwr\simulation\ray_transport\ray_client_proxy.py", line 73, in _submit_job
    out_mssg, updated_context = self.actor_pool.get_client_result(
                                ^^^^^^^^^^^^^^^^^^^^^^^^^^^^^^^^^^
  File "C:\Users\HP\anaconda3\envs\FedLearnCD\Lib\site-packages\flwr\simulation\ray_transport\ray_actor.py", line 399, in get_client_result
    return self._fetch_future_result(cid)
           ^^^^^^^^^^^^^^^^^^^^^^^^^^^^^^
  File "C:\Users\HP\anaconda3\envs\FedLearnCD\Lib\site-packages\flwr\simulation\ray_transport\ray_actor.py", line 280, in _fetch_future_result
    res_cid, out_mssg, updated_context = ray.get(
                                         ^^^^^^^^
  File "C:\Users\HP\anaconda3\envs\FedLearnCD\Lib\site-packages\ray\_private\auto_init_hook.py", line 21, in auto_init_wrapper
    return fn(*args, **kwargs)
           ^^^^^^^^^^^^^^^^^^^
  File "C:\Users\HP\anaconda3\envs\FedLearnCD\Lib\site-packages\ray\_private\client_mode_hook.py", line 103, in wrapper
    return func(*args, **kwargs)
           ^^^^^^^^^^^^^^^^^^^^^
  File "C:\Users\HP\anaconda3\envs\FedLearnCD\Lib\site-packages\ray\_private\worker.py", line 2623, in get
    values, debugger_breakpoint = worker.get_objects(object_refs, timeout=timeout)
                                  ^^^^^^^^^^^^^^^^^^^^^^^^^^^^^^^^^^^^^^^^^^^^^^^^
  File "C:\Users\HP\anaconda3\envs\FedLearnCD\Lib\site-packages\ray\_private\worker.py", line 861, in get_objects
    raise value.as_instanceof_cause()
ray.exceptions.RayTaskError(ClientAppException): [36mray::ClientAppActor.run()[39m (pid=6536, ip=127.0.0.1, actor_id=14f677eaa3c4366b55bf407501000000, repr=<flwr.simulation.ray_transport.ray_actor.ClientAppActor object at 0x000001D1AFF26290>)
                  ^^^^^^^^^^^^^^^^^^^^^^^^^^^^^^^^^^^^^
  File "C:\Users\HP\anaconda3\envs\FedLearnCD\Lib\site-packages\flwr\client\client_app.py", line 98, in __call__
    return self._call(message, context)
           ^^^^^^^^^^^^^^^^^^^^^^^^^^^^
  File "C:\Users\HP\anaconda3\envs\FedLearnCD\Lib\site-packages\flwr\client\client_app.py", line 81, in ffn
    out_message = handle_legacy_message_from_msgtype(
                  ^^^^^^^^^^^^^^^^^^^^^^^^^^^^^^^^^^^
  File "C:\Users\HP\anaconda3\envs\FedLearnCD\Lib\site-packages\flwr\client\message_handler\message_handler.py", line 137, in handle_legacy_message_from_msgtype
    evaluate_res = maybe_call_evaluate(
                   ^^^^^^^^^^^^^^^^^^^^
  File "C:\Users\HP\anaconda3\envs\FedLearnCD\Lib\site-packages\flwr\client\client.py", line 254, in maybe_call_evaluate
    return client.evaluate(evaluate_ins)
           ^^^^^^^^^^^^^^^^^^^^^^^^^^^^^
  File "C:\Users\HP\anaconda3\envs\FedLearnCD\Lib\site-packages\flwr\client\numpy_client.py", line 262, in _evaluate
    results = self.numpy_client.evaluate(parameters, ins.config)  # type: ignore
              ^^^^^^^^^^^^^^^^^^^^^^^^^^^^^^^^^^^^^^^^^^^^^^^^^^
  File "C:\Users\HP\Documents\FedAvgWithDrift\client.py", line 61, in evaluate
    return float(loss), len(self.valloadders), {'accurcay':accuracy}
                            ^^^^^^^^^^^^^^^^
AttributeError: 'FlowerClient' object has no attribute 'valloadders'

The above exception was the direct cause of the following exception:

[36mray::ClientAppActor.run()[39m (pid=6536, ip=127.0.0.1, actor_id=14f677eaa3c4366b55bf407501000000, repr=<flwr.simulation.ray_transport.ray_actor.ClientAppActor object at 0x000001D1AFF26290>)
  File "python\ray\_raylet.pyx", line 1881, in ray._raylet.execute_task
  File "python\ray\_raylet.pyx", line 1982, in ray._raylet.execute_task
  File "python\ray\_raylet.pyx", line 1887, in ray._raylet.execute_task
  File "python\ray\_raylet.pyx", line 1828, in ray._raylet.execute_task.function_executor
  File "C:\Users\HP\anaconda3\envs\FedLearnCD\Lib\site-packages\ray\_private\function_manager.py", line 691, in actor_method_executor
    return method(__ray_actor, *args, **kwargs)
           ^^^^^^^^^^^^^^^^^^^^^^^^^^^^^^^^^^^^
  File "C:\Users\HP\anaconda3\envs\FedLearnCD\Lib\site-packages\ray\util\tracing\tracing_helper.py", line 467, in _resume_span
    return method(self, *_args, **_kwargs)
           ^^^^^^^^^^^^^^^^^^^^^^^^^^^^^^^
  File "C:\Users\HP\anaconda3\envs\FedLearnCD\Lib\site-packages\flwr\simulation\ray_transport\ray_actor.py", line 64, in run
    raise ClientAppException(str(ex)) from ex
flwr.client.client_app.ClientAppException: 
Exception ClientAppException occurred. Message: 'FlowerClient' object has no attribute 'valloadders'

[2024-05-04 19:07:46,589][flwr][ERROR] - [36mray::ClientAppActor.run()[39m (pid=6536, ip=127.0.0.1, actor_id=14f677eaa3c4366b55bf407501000000, repr=<flwr.simulation.ray_transport.ray_actor.ClientAppActor object at 0x000001D1AFF26290>)
                  ^^^^^^^^^^^^^^^^^^^^^^^^^^^^^^^^^^^^^
  File "C:\Users\HP\anaconda3\envs\FedLearnCD\Lib\site-packages\flwr\client\client_app.py", line 98, in __call__
    return self._call(message, context)
           ^^^^^^^^^^^^^^^^^^^^^^^^^^^^
  File "C:\Users\HP\anaconda3\envs\FedLearnCD\Lib\site-packages\flwr\client\client_app.py", line 81, in ffn
    out_message = handle_legacy_message_from_msgtype(
                  ^^^^^^^^^^^^^^^^^^^^^^^^^^^^^^^^^^^
  File "C:\Users\HP\anaconda3\envs\FedLearnCD\Lib\site-packages\flwr\client\message_handler\message_handler.py", line 137, in handle_legacy_message_from_msgtype
    evaluate_res = maybe_call_evaluate(
                   ^^^^^^^^^^^^^^^^^^^^
  File "C:\Users\HP\anaconda3\envs\FedLearnCD\Lib\site-packages\flwr\client\client.py", line 254, in maybe_call_evaluate
    return client.evaluate(evaluate_ins)
           ^^^^^^^^^^^^^^^^^^^^^^^^^^^^^
  File "C:\Users\HP\anaconda3\envs\FedLearnCD\Lib\site-packages\flwr\client\numpy_client.py", line 262, in _evaluate
    results = self.numpy_client.evaluate(parameters, ins.config)  # type: ignore
              ^^^^^^^^^^^^^^^^^^^^^^^^^^^^^^^^^^^^^^^^^^^^^^^^^^
  File "C:\Users\HP\Documents\FedAvgWithDrift\client.py", line 61, in evaluate
    return float(loss), len(self.valloadders), {'accurcay':accuracy}
                            ^^^^^^^^^^^^^^^^
AttributeError: 'FlowerClient' object has no attribute 'valloadders'

The above exception was the direct cause of the following exception:

[36mray::ClientAppActor.run()[39m (pid=6536, ip=127.0.0.1, actor_id=14f677eaa3c4366b55bf407501000000, repr=<flwr.simulation.ray_transport.ray_actor.ClientAppActor object at 0x000001D1AFF26290>)
  File "python\ray\_raylet.pyx", line 1881, in ray._raylet.execute_task
  File "python\ray\_raylet.pyx", line 1982, in ray._raylet.execute_task
  File "python\ray\_raylet.pyx", line 1887, in ray._raylet.execute_task
  File "python\ray\_raylet.pyx", line 1828, in ray._raylet.execute_task.function_executor
  File "C:\Users\HP\anaconda3\envs\FedLearnCD\Lib\site-packages\ray\_private\function_manager.py", line 691, in actor_method_executor
    return method(__ray_actor, *args, **kwargs)
           ^^^^^^^^^^^^^^^^^^^^^^^^^^^^^^^^^^^^
  File "C:\Users\HP\anaconda3\envs\FedLearnCD\Lib\site-packages\ray\util\tracing\tracing_helper.py", line 467, in _resume_span
    return method(self, *_args, **_kwargs)
           ^^^^^^^^^^^^^^^^^^^^^^^^^^^^^^^
  File "C:\Users\HP\anaconda3\envs\FedLearnCD\Lib\site-packages\flwr\simulation\ray_transport\ray_actor.py", line 64, in run
    raise ClientAppException(str(ex)) from ex
flwr.client.client_app.ClientAppException: 
Exception ClientAppException occurred. Message: 'FlowerClient' object has no attribute 'valloadders'
[2024-05-04 19:07:55,351][flwr][ERROR] - Traceback (most recent call last):
  File "C:\Users\HP\anaconda3\envs\FedLearnCD\Lib\site-packages\flwr\simulation\ray_transport\ray_client_proxy.py", line 73, in _submit_job
    out_mssg, updated_context = self.actor_pool.get_client_result(
                                ^^^^^^^^^^^^^^^^^^^^^^^^^^^^^^^^^^
  File "C:\Users\HP\anaconda3\envs\FedLearnCD\Lib\site-packages\flwr\simulation\ray_transport\ray_actor.py", line 399, in get_client_result
    return self._fetch_future_result(cid)
           ^^^^^^^^^^^^^^^^^^^^^^^^^^^^^^
  File "C:\Users\HP\anaconda3\envs\FedLearnCD\Lib\site-packages\flwr\simulation\ray_transport\ray_actor.py", line 280, in _fetch_future_result
    res_cid, out_mssg, updated_context = ray.get(
                                         ^^^^^^^^
  File "C:\Users\HP\anaconda3\envs\FedLearnCD\Lib\site-packages\ray\_private\auto_init_hook.py", line 21, in auto_init_wrapper
    return fn(*args, **kwargs)
           ^^^^^^^^^^^^^^^^^^^
  File "C:\Users\HP\anaconda3\envs\FedLearnCD\Lib\site-packages\ray\_private\client_mode_hook.py", line 103, in wrapper
    return func(*args, **kwargs)
           ^^^^^^^^^^^^^^^^^^^^^
  File "C:\Users\HP\anaconda3\envs\FedLearnCD\Lib\site-packages\ray\_private\worker.py", line 2623, in get
    values, debugger_breakpoint = worker.get_objects(object_refs, timeout=timeout)
                                  ^^^^^^^^^^^^^^^^^^^^^^^^^^^^^^^^^^^^^^^^^^^^^^^^
  File "C:\Users\HP\anaconda3\envs\FedLearnCD\Lib\site-packages\ray\_private\worker.py", line 861, in get_objects
    raise value.as_instanceof_cause()
ray.exceptions.RayTaskError(ClientAppException): [36mray::ClientAppActor.run()[39m (pid=6532, ip=127.0.0.1, actor_id=abb66b9749a687783d54edf901000000, repr=<flwr.simulation.ray_transport.ray_actor.ClientAppActor object at 0x000001DEE96B15D0>)
                  ^^^^^^^^^^^^^^^^^^^^^^^^^^^^^^^^^^^^^
  File "C:\Users\HP\anaconda3\envs\FedLearnCD\Lib\site-packages\flwr\client\client_app.py", line 98, in __call__
    return self._call(message, context)
           ^^^^^^^^^^^^^^^^^^^^^^^^^^^^
  File "C:\Users\HP\anaconda3\envs\FedLearnCD\Lib\site-packages\flwr\client\client_app.py", line 81, in ffn
    out_message = handle_legacy_message_from_msgtype(
                  ^^^^^^^^^^^^^^^^^^^^^^^^^^^^^^^^^^^
  File "C:\Users\HP\anaconda3\envs\FedLearnCD\Lib\site-packages\flwr\client\message_handler\message_handler.py", line 137, in handle_legacy_message_from_msgtype
    evaluate_res = maybe_call_evaluate(
                   ^^^^^^^^^^^^^^^^^^^^
  File "C:\Users\HP\anaconda3\envs\FedLearnCD\Lib\site-packages\flwr\client\client.py", line 254, in maybe_call_evaluate
    return client.evaluate(evaluate_ins)
           ^^^^^^^^^^^^^^^^^^^^^^^^^^^^^
  File "C:\Users\HP\anaconda3\envs\FedLearnCD\Lib\site-packages\flwr\client\numpy_client.py", line 262, in _evaluate
    results = self.numpy_client.evaluate(parameters, ins.config)  # type: ignore
              ^^^^^^^^^^^^^^^^^^^^^^^^^^^^^^^^^^^^^^^^^^^^^^^^^^
  File "C:\Users\HP\Documents\FedAvgWithDrift\client.py", line 61, in evaluate
    return float(loss), len(self.valloadders), {'accurcay':accuracy}
                            ^^^^^^^^^^^^^^^^
AttributeError: 'FlowerClient' object has no attribute 'valloadders'

The above exception was the direct cause of the following exception:

[36mray::ClientAppActor.run()[39m (pid=6532, ip=127.0.0.1, actor_id=abb66b9749a687783d54edf901000000, repr=<flwr.simulation.ray_transport.ray_actor.ClientAppActor object at 0x000001DEE96B15D0>)
  File "python\ray\_raylet.pyx", line 1881, in ray._raylet.execute_task
  File "python\ray\_raylet.pyx", line 1982, in ray._raylet.execute_task
  File "python\ray\_raylet.pyx", line 1887, in ray._raylet.execute_task
  File "python\ray\_raylet.pyx", line 1828, in ray._raylet.execute_task.function_executor
  File "C:\Users\HP\anaconda3\envs\FedLearnCD\Lib\site-packages\ray\_private\function_manager.py", line 691, in actor_method_executor
    return method(__ray_actor, *args, **kwargs)
           ^^^^^^^^^^^^^^^^^^^^^^^^^^^^^^^^^^^^
  File "C:\Users\HP\anaconda3\envs\FedLearnCD\Lib\site-packages\ray\util\tracing\tracing_helper.py", line 467, in _resume_span
    return method(self, *_args, **_kwargs)
           ^^^^^^^^^^^^^^^^^^^^^^^^^^^^^^^
  File "C:\Users\HP\anaconda3\envs\FedLearnCD\Lib\site-packages\flwr\simulation\ray_transport\ray_actor.py", line 64, in run
    raise ClientAppException(str(ex)) from ex
flwr.client.client_app.ClientAppException: 
Exception ClientAppException occurred. Message: 'FlowerClient' object has no attribute 'valloadders'

[2024-05-04 19:07:55,386][flwr][ERROR] - [36mray::ClientAppActor.run()[39m (pid=6532, ip=127.0.0.1, actor_id=abb66b9749a687783d54edf901000000, repr=<flwr.simulation.ray_transport.ray_actor.ClientAppActor object at 0x000001DEE96B15D0>)
                  ^^^^^^^^^^^^^^^^^^^^^^^^^^^^^^^^^^^^^
  File "C:\Users\HP\anaconda3\envs\FedLearnCD\Lib\site-packages\flwr\client\client_app.py", line 98, in __call__
    return self._call(message, context)
           ^^^^^^^^^^^^^^^^^^^^^^^^^^^^
  File "C:\Users\HP\anaconda3\envs\FedLearnCD\Lib\site-packages\flwr\client\client_app.py", line 81, in ffn
    out_message = handle_legacy_message_from_msgtype(
                  ^^^^^^^^^^^^^^^^^^^^^^^^^^^^^^^^^^^
  File "C:\Users\HP\anaconda3\envs\FedLearnCD\Lib\site-packages\flwr\client\message_handler\message_handler.py", line 137, in handle_legacy_message_from_msgtype
    evaluate_res = maybe_call_evaluate(
                   ^^^^^^^^^^^^^^^^^^^^
  File "C:\Users\HP\anaconda3\envs\FedLearnCD\Lib\site-packages\flwr\client\client.py", line 254, in maybe_call_evaluate
    return client.evaluate(evaluate_ins)
           ^^^^^^^^^^^^^^^^^^^^^^^^^^^^^
  File "C:\Users\HP\anaconda3\envs\FedLearnCD\Lib\site-packages\flwr\client\numpy_client.py", line 262, in _evaluate
    results = self.numpy_client.evaluate(parameters, ins.config)  # type: ignore
              ^^^^^^^^^^^^^^^^^^^^^^^^^^^^^^^^^^^^^^^^^^^^^^^^^^
  File "C:\Users\HP\Documents\FedAvgWithDrift\client.py", line 61, in evaluate
    return float(loss), len(self.valloadders), {'accurcay':accuracy}
                            ^^^^^^^^^^^^^^^^
AttributeError: 'FlowerClient' object has no attribute 'valloadders'

The above exception was the direct cause of the following exception:

[36mray::ClientAppActor.run()[39m (pid=6532, ip=127.0.0.1, actor_id=abb66b9749a687783d54edf901000000, repr=<flwr.simulation.ray_transport.ray_actor.ClientAppActor object at 0x000001DEE96B15D0>)
  File "python\ray\_raylet.pyx", line 1881, in ray._raylet.execute_task
  File "python\ray\_raylet.pyx", line 1982, in ray._raylet.execute_task
  File "python\ray\_raylet.pyx", line 1887, in ray._raylet.execute_task
  File "python\ray\_raylet.pyx", line 1828, in ray._raylet.execute_task.function_executor
  File "C:\Users\HP\anaconda3\envs\FedLearnCD\Lib\site-packages\ray\_private\function_manager.py", line 691, in actor_method_executor
    return method(__ray_actor, *args, **kwargs)
           ^^^^^^^^^^^^^^^^^^^^^^^^^^^^^^^^^^^^
  File "C:\Users\HP\anaconda3\envs\FedLearnCD\Lib\site-packages\ray\util\tracing\tracing_helper.py", line 467, in _resume_span
    return method(self, *_args, **_kwargs)
           ^^^^^^^^^^^^^^^^^^^^^^^^^^^^^^^
  File "C:\Users\HP\anaconda3\envs\FedLearnCD\Lib\site-packages\flwr\simulation\ray_transport\ray_actor.py", line 64, in run
    raise ClientAppException(str(ex)) from ex
flwr.client.client_app.ClientAppException: 
Exception ClientAppException occurred. Message: 'FlowerClient' object has no attribute 'valloadders'
[2024-05-04 19:07:55,747][flwr][ERROR] - Traceback (most recent call last):
  File "C:\Users\HP\anaconda3\envs\FedLearnCD\Lib\site-packages\flwr\simulation\ray_transport\ray_client_proxy.py", line 73, in _submit_job
    out_mssg, updated_context = self.actor_pool.get_client_result(
                                ^^^^^^^^^^^^^^^^^^^^^^^^^^^^^^^^^^
  File "C:\Users\HP\anaconda3\envs\FedLearnCD\Lib\site-packages\flwr\simulation\ray_transport\ray_actor.py", line 399, in get_client_result
    return self._fetch_future_result(cid)
           ^^^^^^^^^^^^^^^^^^^^^^^^^^^^^^
  File "C:\Users\HP\anaconda3\envs\FedLearnCD\Lib\site-packages\flwr\simulation\ray_transport\ray_actor.py", line 280, in _fetch_future_result
    res_cid, out_mssg, updated_context = ray.get(
                                         ^^^^^^^^
  File "C:\Users\HP\anaconda3\envs\FedLearnCD\Lib\site-packages\ray\_private\auto_init_hook.py", line 21, in auto_init_wrapper
    return fn(*args, **kwargs)
           ^^^^^^^^^^^^^^^^^^^
  File "C:\Users\HP\anaconda3\envs\FedLearnCD\Lib\site-packages\ray\_private\client_mode_hook.py", line 103, in wrapper
    return func(*args, **kwargs)
           ^^^^^^^^^^^^^^^^^^^^^
  File "C:\Users\HP\anaconda3\envs\FedLearnCD\Lib\site-packages\ray\_private\worker.py", line 2623, in get
    values, debugger_breakpoint = worker.get_objects(object_refs, timeout=timeout)
                                  ^^^^^^^^^^^^^^^^^^^^^^^^^^^^^^^^^^^^^^^^^^^^^^^^
  File "C:\Users\HP\anaconda3\envs\FedLearnCD\Lib\site-packages\ray\_private\worker.py", line 861, in get_objects
    raise value.as_instanceof_cause()
ray.exceptions.RayTaskError(ClientAppException): [36mray::ClientAppActor.run()[39m (pid=5092, ip=127.0.0.1, actor_id=7a73e292a6008c781ec56f8101000000, repr=<flwr.simulation.ray_transport.ray_actor.ClientAppActor object at 0x00000254ABDFFA10>)
                  ^^^^^^^^^^^^^^^^^^^^^^^^^^^^^^^^^^^^^
  File "C:\Users\HP\anaconda3\envs\FedLearnCD\Lib\site-packages\flwr\client\client_app.py", line 98, in __call__
    return self._call(message, context)
           ^^^^^^^^^^^^^^^^^^^^^^^^^^^^
  File "C:\Users\HP\anaconda3\envs\FedLearnCD\Lib\site-packages\flwr\client\client_app.py", line 81, in ffn
    out_message = handle_legacy_message_from_msgtype(
                  ^^^^^^^^^^^^^^^^^^^^^^^^^^^^^^^^^^^
  File "C:\Users\HP\anaconda3\envs\FedLearnCD\Lib\site-packages\flwr\client\message_handler\message_handler.py", line 137, in handle_legacy_message_from_msgtype
    evaluate_res = maybe_call_evaluate(
                   ^^^^^^^^^^^^^^^^^^^^
  File "C:\Users\HP\anaconda3\envs\FedLearnCD\Lib\site-packages\flwr\client\client.py", line 254, in maybe_call_evaluate
    return client.evaluate(evaluate_ins)
           ^^^^^^^^^^^^^^^^^^^^^^^^^^^^^
  File "C:\Users\HP\anaconda3\envs\FedLearnCD\Lib\site-packages\flwr\client\numpy_client.py", line 262, in _evaluate
    results = self.numpy_client.evaluate(parameters, ins.config)  # type: ignore
              ^^^^^^^^^^^^^^^^^^^^^^^^^^^^^^^^^^^^^^^^^^^^^^^^^^
  File "C:\Users\HP\Documents\FedAvgWithDrift\client.py", line 61, in evaluate
    return float(loss), len(self.valloadders), {'accurcay':accuracy}
                            ^^^^^^^^^^^^^^^^
AttributeError: 'FlowerClient' object has no attribute 'valloadders'

The above exception was the direct cause of the following exception:

[36mray::ClientAppActor.run()[39m (pid=5092, ip=127.0.0.1, actor_id=7a73e292a6008c781ec56f8101000000, repr=<flwr.simulation.ray_transport.ray_actor.ClientAppActor object at 0x00000254ABDFFA10>)
  File "python\ray\_raylet.pyx", line 1881, in ray._raylet.execute_task
  File "python\ray\_raylet.pyx", line 1982, in ray._raylet.execute_task
  File "python\ray\_raylet.pyx", line 1887, in ray._raylet.execute_task
  File "python\ray\_raylet.pyx", line 1828, in ray._raylet.execute_task.function_executor
  File "C:\Users\HP\anaconda3\envs\FedLearnCD\Lib\site-packages\ray\_private\function_manager.py", line 691, in actor_method_executor
    return method(__ray_actor, *args, **kwargs)
           ^^^^^^^^^^^^^^^^^^^^^^^^^^^^^^^^^^^^
  File "C:\Users\HP\anaconda3\envs\FedLearnCD\Lib\site-packages\ray\util\tracing\tracing_helper.py", line 467, in _resume_span
    return method(self, *_args, **_kwargs)
           ^^^^^^^^^^^^^^^^^^^^^^^^^^^^^^^
  File "C:\Users\HP\anaconda3\envs\FedLearnCD\Lib\site-packages\flwr\simulation\ray_transport\ray_actor.py", line 64, in run
    raise ClientAppException(str(ex)) from ex
flwr.client.client_app.ClientAppException: 
Exception ClientAppException occurred. Message: 'FlowerClient' object has no attribute 'valloadders'

[2024-05-04 19:07:55,774][flwr][ERROR] - [36mray::ClientAppActor.run()[39m (pid=5092, ip=127.0.0.1, actor_id=7a73e292a6008c781ec56f8101000000, repr=<flwr.simulation.ray_transport.ray_actor.ClientAppActor object at 0x00000254ABDFFA10>)
                  ^^^^^^^^^^^^^^^^^^^^^^^^^^^^^^^^^^^^^
  File "C:\Users\HP\anaconda3\envs\FedLearnCD\Lib\site-packages\flwr\client\client_app.py", line 98, in __call__
    return self._call(message, context)
           ^^^^^^^^^^^^^^^^^^^^^^^^^^^^
  File "C:\Users\HP\anaconda3\envs\FedLearnCD\Lib\site-packages\flwr\client\client_app.py", line 81, in ffn
    out_message = handle_legacy_message_from_msgtype(
                  ^^^^^^^^^^^^^^^^^^^^^^^^^^^^^^^^^^^
  File "C:\Users\HP\anaconda3\envs\FedLearnCD\Lib\site-packages\flwr\client\message_handler\message_handler.py", line 137, in handle_legacy_message_from_msgtype
    evaluate_res = maybe_call_evaluate(
                   ^^^^^^^^^^^^^^^^^^^^
  File "C:\Users\HP\anaconda3\envs\FedLearnCD\Lib\site-packages\flwr\client\client.py", line 254, in maybe_call_evaluate
    return client.evaluate(evaluate_ins)
           ^^^^^^^^^^^^^^^^^^^^^^^^^^^^^
  File "C:\Users\HP\anaconda3\envs\FedLearnCD\Lib\site-packages\flwr\client\numpy_client.py", line 262, in _evaluate
    results = self.numpy_client.evaluate(parameters, ins.config)  # type: ignore
              ^^^^^^^^^^^^^^^^^^^^^^^^^^^^^^^^^^^^^^^^^^^^^^^^^^
  File "C:\Users\HP\Documents\FedAvgWithDrift\client.py", line 61, in evaluate
    return float(loss), len(self.valloadders), {'accurcay':accuracy}
                            ^^^^^^^^^^^^^^^^
AttributeError: 'FlowerClient' object has no attribute 'valloadders'

The above exception was the direct cause of the following exception:

[36mray::ClientAppActor.run()[39m (pid=5092, ip=127.0.0.1, actor_id=7a73e292a6008c781ec56f8101000000, repr=<flwr.simulation.ray_transport.ray_actor.ClientAppActor object at 0x00000254ABDFFA10>)
  File "python\ray\_raylet.pyx", line 1881, in ray._raylet.execute_task
  File "python\ray\_raylet.pyx", line 1982, in ray._raylet.execute_task
  File "python\ray\_raylet.pyx", line 1887, in ray._raylet.execute_task
  File "python\ray\_raylet.pyx", line 1828, in ray._raylet.execute_task.function_executor
  File "C:\Users\HP\anaconda3\envs\FedLearnCD\Lib\site-packages\ray\_private\function_manager.py", line 691, in actor_method_executor
    return method(__ray_actor, *args, **kwargs)
           ^^^^^^^^^^^^^^^^^^^^^^^^^^^^^^^^^^^^
  File "C:\Users\HP\anaconda3\envs\FedLearnCD\Lib\site-packages\ray\util\tracing\tracing_helper.py", line 467, in _resume_span
    return method(self, *_args, **_kwargs)
           ^^^^^^^^^^^^^^^^^^^^^^^^^^^^^^^
  File "C:\Users\HP\anaconda3\envs\FedLearnCD\Lib\site-packages\flwr\simulation\ray_transport\ray_actor.py", line 64, in run
    raise ClientAppException(str(ex)) from ex
flwr.client.client_app.ClientAppException: 
Exception ClientAppException occurred. Message: 'FlowerClient' object has no attribute 'valloadders'
[2024-05-04 19:08:02,937][flwr][ERROR] - Traceback (most recent call last):
  File "C:\Users\HP\anaconda3\envs\FedLearnCD\Lib\site-packages\flwr\simulation\ray_transport\ray_client_proxy.py", line 73, in _submit_job
    out_mssg, updated_context = self.actor_pool.get_client_result(
                                ^^^^^^^^^^^^^^^^^^^^^^^^^^^^^^^^^^
  File "C:\Users\HP\anaconda3\envs\FedLearnCD\Lib\site-packages\flwr\simulation\ray_transport\ray_actor.py", line 399, in get_client_result
    return self._fetch_future_result(cid)
           ^^^^^^^^^^^^^^^^^^^^^^^^^^^^^^
  File "C:\Users\HP\anaconda3\envs\FedLearnCD\Lib\site-packages\flwr\simulation\ray_transport\ray_actor.py", line 280, in _fetch_future_result
    res_cid, out_mssg, updated_context = ray.get(
                                         ^^^^^^^^
  File "C:\Users\HP\anaconda3\envs\FedLearnCD\Lib\site-packages\ray\_private\auto_init_hook.py", line 21, in auto_init_wrapper
    return fn(*args, **kwargs)
           ^^^^^^^^^^^^^^^^^^^
  File "C:\Users\HP\anaconda3\envs\FedLearnCD\Lib\site-packages\ray\_private\client_mode_hook.py", line 103, in wrapper
    return func(*args, **kwargs)
           ^^^^^^^^^^^^^^^^^^^^^
  File "C:\Users\HP\anaconda3\envs\FedLearnCD\Lib\site-packages\ray\_private\worker.py", line 2623, in get
    values, debugger_breakpoint = worker.get_objects(object_refs, timeout=timeout)
                                  ^^^^^^^^^^^^^^^^^^^^^^^^^^^^^^^^^^^^^^^^^^^^^^^^
  File "C:\Users\HP\anaconda3\envs\FedLearnCD\Lib\site-packages\ray\_private\worker.py", line 861, in get_objects
    raise value.as_instanceof_cause()
ray.exceptions.RayTaskError(ClientAppException): [36mray::ClientAppActor.run()[39m (pid=5088, ip=127.0.0.1, actor_id=201d4d61ad7bdf07591019d601000000, repr=<flwr.simulation.ray_transport.ray_actor.ClientAppActor object at 0x0000021AFA356350>)
                  ^^^^^^^^^^^^^^^^^^^^^^^^^^^^^^^^^^^^^
  File "C:\Users\HP\anaconda3\envs\FedLearnCD\Lib\site-packages\flwr\client\client_app.py", line 98, in __call__
    return self._call(message, context)
           ^^^^^^^^^^^^^^^^^^^^^^^^^^^^
  File "C:\Users\HP\anaconda3\envs\FedLearnCD\Lib\site-packages\flwr\client\client_app.py", line 81, in ffn
    out_message = handle_legacy_message_from_msgtype(
                  ^^^^^^^^^^^^^^^^^^^^^^^^^^^^^^^^^^^
  File "C:\Users\HP\anaconda3\envs\FedLearnCD\Lib\site-packages\flwr\client\message_handler\message_handler.py", line 137, in handle_legacy_message_from_msgtype
    evaluate_res = maybe_call_evaluate(
                   ^^^^^^^^^^^^^^^^^^^^
  File "C:\Users\HP\anaconda3\envs\FedLearnCD\Lib\site-packages\flwr\client\client.py", line 254, in maybe_call_evaluate
    return client.evaluate(evaluate_ins)
           ^^^^^^^^^^^^^^^^^^^^^^^^^^^^^
  File "C:\Users\HP\anaconda3\envs\FedLearnCD\Lib\site-packages\flwr\client\numpy_client.py", line 262, in _evaluate
    results = self.numpy_client.evaluate(parameters, ins.config)  # type: ignore
              ^^^^^^^^^^^^^^^^^^^^^^^^^^^^^^^^^^^^^^^^^^^^^^^^^^
  File "C:\Users\HP\Documents\FedAvgWithDrift\client.py", line 61, in evaluate
    return float(loss), len(self.valloadders), {'accurcay':accuracy}
                            ^^^^^^^^^^^^^^^^
AttributeError: 'FlowerClient' object has no attribute 'valloadders'

The above exception was the direct cause of the following exception:

[36mray::ClientAppActor.run()[39m (pid=5088, ip=127.0.0.1, actor_id=201d4d61ad7bdf07591019d601000000, repr=<flwr.simulation.ray_transport.ray_actor.ClientAppActor object at 0x0000021AFA356350>)
  File "python\ray\_raylet.pyx", line 1881, in ray._raylet.execute_task
  File "python\ray\_raylet.pyx", line 1982, in ray._raylet.execute_task
  File "python\ray\_raylet.pyx", line 1887, in ray._raylet.execute_task
  File "python\ray\_raylet.pyx", line 1828, in ray._raylet.execute_task.function_executor
  File "C:\Users\HP\anaconda3\envs\FedLearnCD\Lib\site-packages\ray\_private\function_manager.py", line 691, in actor_method_executor
    return method(__ray_actor, *args, **kwargs)
           ^^^^^^^^^^^^^^^^^^^^^^^^^^^^^^^^^^^^
  File "C:\Users\HP\anaconda3\envs\FedLearnCD\Lib\site-packages\ray\util\tracing\tracing_helper.py", line 467, in _resume_span
    return method(self, *_args, **_kwargs)
           ^^^^^^^^^^^^^^^^^^^^^^^^^^^^^^^
  File "C:\Users\HP\anaconda3\envs\FedLearnCD\Lib\site-packages\flwr\simulation\ray_transport\ray_actor.py", line 64, in run
    raise ClientAppException(str(ex)) from ex
flwr.client.client_app.ClientAppException: 
Exception ClientAppException occurred. Message: 'FlowerClient' object has no attribute 'valloadders'

[2024-05-04 19:08:02,958][flwr][ERROR] - [36mray::ClientAppActor.run()[39m (pid=5088, ip=127.0.0.1, actor_id=201d4d61ad7bdf07591019d601000000, repr=<flwr.simulation.ray_transport.ray_actor.ClientAppActor object at 0x0000021AFA356350>)
                  ^^^^^^^^^^^^^^^^^^^^^^^^^^^^^^^^^^^^^
  File "C:\Users\HP\anaconda3\envs\FedLearnCD\Lib\site-packages\flwr\client\client_app.py", line 98, in __call__
    return self._call(message, context)
           ^^^^^^^^^^^^^^^^^^^^^^^^^^^^
  File "C:\Users\HP\anaconda3\envs\FedLearnCD\Lib\site-packages\flwr\client\client_app.py", line 81, in ffn
    out_message = handle_legacy_message_from_msgtype(
                  ^^^^^^^^^^^^^^^^^^^^^^^^^^^^^^^^^^^
  File "C:\Users\HP\anaconda3\envs\FedLearnCD\Lib\site-packages\flwr\client\message_handler\message_handler.py", line 137, in handle_legacy_message_from_msgtype
    evaluate_res = maybe_call_evaluate(
                   ^^^^^^^^^^^^^^^^^^^^
  File "C:\Users\HP\anaconda3\envs\FedLearnCD\Lib\site-packages\flwr\client\client.py", line 254, in maybe_call_evaluate
    return client.evaluate(evaluate_ins)
           ^^^^^^^^^^^^^^^^^^^^^^^^^^^^^
  File "C:\Users\HP\anaconda3\envs\FedLearnCD\Lib\site-packages\flwr\client\numpy_client.py", line 262, in _evaluate
    results = self.numpy_client.evaluate(parameters, ins.config)  # type: ignore
              ^^^^^^^^^^^^^^^^^^^^^^^^^^^^^^^^^^^^^^^^^^^^^^^^^^
  File "C:\Users\HP\Documents\FedAvgWithDrift\client.py", line 61, in evaluate
    return float(loss), len(self.valloadders), {'accurcay':accuracy}
                            ^^^^^^^^^^^^^^^^
AttributeError: 'FlowerClient' object has no attribute 'valloadders'

The above exception was the direct cause of the following exception:

[36mray::ClientAppActor.run()[39m (pid=5088, ip=127.0.0.1, actor_id=201d4d61ad7bdf07591019d601000000, repr=<flwr.simulation.ray_transport.ray_actor.ClientAppActor object at 0x0000021AFA356350>)
  File "python\ray\_raylet.pyx", line 1881, in ray._raylet.execute_task
  File "python\ray\_raylet.pyx", line 1982, in ray._raylet.execute_task
  File "python\ray\_raylet.pyx", line 1887, in ray._raylet.execute_task
  File "python\ray\_raylet.pyx", line 1828, in ray._raylet.execute_task.function_executor
  File "C:\Users\HP\anaconda3\envs\FedLearnCD\Lib\site-packages\ray\_private\function_manager.py", line 691, in actor_method_executor
    return method(__ray_actor, *args, **kwargs)
           ^^^^^^^^^^^^^^^^^^^^^^^^^^^^^^^^^^^^
  File "C:\Users\HP\anaconda3\envs\FedLearnCD\Lib\site-packages\ray\util\tracing\tracing_helper.py", line 467, in _resume_span
    return method(self, *_args, **_kwargs)
           ^^^^^^^^^^^^^^^^^^^^^^^^^^^^^^^
  File "C:\Users\HP\anaconda3\envs\FedLearnCD\Lib\site-packages\flwr\simulation\ray_transport\ray_actor.py", line 64, in run
    raise ClientAppException(str(ex)) from ex
flwr.client.client_app.ClientAppException: 
Exception ClientAppException occurred. Message: 'FlowerClient' object has no attribute 'valloadders'
[2024-05-04 19:08:02,968][flwr][INFO] - aggregate_evaluate: received 0 results and 5 failures
[2024-05-04 19:08:02,968][flwr][INFO] - 
[2024-05-04 19:08:02,968][flwr][INFO] - [ROUND 4]
[2024-05-04 19:08:02,968][flwr][INFO] - Sampling failed: number of available clients (5) is less than number of requested clients (10).
[2024-05-04 19:08:02,976][flwr][INFO] - configure_fit: no clients selected, cancel
[2024-05-04 19:08:08,492][flwr][INFO] - fit progress: (4, 182.11450600624084, {'accuracy': 0.1}, 171.75640500000736)
[2024-05-04 19:08:08,493][flwr][INFO] - configure_evaluate: strategy sampled 5 clients (out of 5)
[2024-05-04 19:08:30,400][flwr][ERROR] - Traceback (most recent call last):
  File "C:\Users\HP\anaconda3\envs\FedLearnCD\Lib\site-packages\flwr\simulation\ray_transport\ray_client_proxy.py", line 73, in _submit_job
    out_mssg, updated_context = self.actor_pool.get_client_result(
                                ^^^^^^^^^^^^^^^^^^^^^^^^^^^^^^^^^^
  File "C:\Users\HP\anaconda3\envs\FedLearnCD\Lib\site-packages\flwr\simulation\ray_transport\ray_actor.py", line 399, in get_client_result
    return self._fetch_future_result(cid)
           ^^^^^^^^^^^^^^^^^^^^^^^^^^^^^^
  File "C:\Users\HP\anaconda3\envs\FedLearnCD\Lib\site-packages\flwr\simulation\ray_transport\ray_actor.py", line 280, in _fetch_future_result
    res_cid, out_mssg, updated_context = ray.get(
                                         ^^^^^^^^
  File "C:\Users\HP\anaconda3\envs\FedLearnCD\Lib\site-packages\ray\_private\auto_init_hook.py", line 21, in auto_init_wrapper
    return fn(*args, **kwargs)
           ^^^^^^^^^^^^^^^^^^^
  File "C:\Users\HP\anaconda3\envs\FedLearnCD\Lib\site-packages\ray\_private\client_mode_hook.py", line 103, in wrapper
    return func(*args, **kwargs)
           ^^^^^^^^^^^^^^^^^^^^^
  File "C:\Users\HP\anaconda3\envs\FedLearnCD\Lib\site-packages\ray\_private\worker.py", line 2623, in get
    values, debugger_breakpoint = worker.get_objects(object_refs, timeout=timeout)
                                  ^^^^^^^^^^^^^^^^^^^^^^^^^^^^^^^^^^^^^^^^^^^^^^^^
  File "C:\Users\HP\anaconda3\envs\FedLearnCD\Lib\site-packages\ray\_private\worker.py", line 861, in get_objects
    raise value.as_instanceof_cause()
ray.exceptions.RayTaskError(ClientAppException): [36mray::ClientAppActor.run()[39m (pid=6536, ip=127.0.0.1, actor_id=14f677eaa3c4366b55bf407501000000, repr=<flwr.simulation.ray_transport.ray_actor.ClientAppActor object at 0x000001D1AFF26290>)
                  ^^^^^^^^^^^^^^^^^^^^^^^^^^^^^^^^^^^^^
  File "C:\Users\HP\anaconda3\envs\FedLearnCD\Lib\site-packages\flwr\client\client_app.py", line 98, in __call__
    return self._call(message, context)
           ^^^^^^^^^^^^^^^^^^^^^^^^^^^^
  File "C:\Users\HP\anaconda3\envs\FedLearnCD\Lib\site-packages\flwr\client\client_app.py", line 81, in ffn
    out_message = handle_legacy_message_from_msgtype(
                  ^^^^^^^^^^^^^^^^^^^^^^^^^^^^^^^^^^^
  File "C:\Users\HP\anaconda3\envs\FedLearnCD\Lib\site-packages\flwr\client\message_handler\message_handler.py", line 137, in handle_legacy_message_from_msgtype
    evaluate_res = maybe_call_evaluate(
                   ^^^^^^^^^^^^^^^^^^^^
  File "C:\Users\HP\anaconda3\envs\FedLearnCD\Lib\site-packages\flwr\client\client.py", line 254, in maybe_call_evaluate
    return client.evaluate(evaluate_ins)
           ^^^^^^^^^^^^^^^^^^^^^^^^^^^^^
  File "C:\Users\HP\anaconda3\envs\FedLearnCD\Lib\site-packages\flwr\client\numpy_client.py", line 262, in _evaluate
    results = self.numpy_client.evaluate(parameters, ins.config)  # type: ignore
              ^^^^^^^^^^^^^^^^^^^^^^^^^^^^^^^^^^^^^^^^^^^^^^^^^^
  File "C:\Users\HP\Documents\FedAvgWithDrift\client.py", line 59, in evaluate
    loss, accuracy =  test(self.model, self.valloader, self.device)
                      ^^^^^^^^^^^^^^^^^^^^^^^^^^^^^^^^^^^^^^^^^^^^^
  File "C:\Users\HP\Documents\FedAvgWithDrift\model.py", line 50, in test
    for data in testloader:
  File "C:\Users\HP\anaconda3\envs\FedLearnCD\Lib\site-packages\torch\utils\data\dataloader.py", line 439, in __iter__
    return self._get_iterator()
           ^^^^^^^^^^^^^^^^^^^^
  File "C:\Users\HP\anaconda3\envs\FedLearnCD\Lib\site-packages\torch\utils\data\dataloader.py", line 387, in _get_iterator
    return _MultiProcessingDataLoaderIter(self)
           ^^^^^^^^^^^^^^^^^^^^^^^^^^^^^^^^^^^^
  File "C:\Users\HP\anaconda3\envs\FedLearnCD\Lib\site-packages\torch\utils\data\dataloader.py", line 1040, in __init__
    w.start()
  File "C:\Users\HP\anaconda3\envs\FedLearnCD\Lib\multiprocessing\process.py", line 121, in start
    self._popen = self._Popen(self)
                  ^^^^^^^^^^^^^^^^^
  File "C:\Users\HP\anaconda3\envs\FedLearnCD\Lib\multiprocessing\context.py", line 224, in _Popen
    return _default_context.get_context().Process._Popen(process_obj)
           ^^^^^^^^^^^^^^^^^^^^^^^^^^^^^^^^^^^^^^^^^^^^^^^^^^^^^^^^^^
  File "C:\Users\HP\anaconda3\envs\FedLearnCD\Lib\multiprocessing\context.py", line 336, in _Popen
    return Popen(process_obj)
           ^^^^^^^^^^^^^^^^^^
  File "C:\Users\HP\anaconda3\envs\FedLearnCD\Lib\multiprocessing\popen_spawn_win32.py", line 95, in __init__
    reduction.dump(process_obj, to_child)
  File "C:\Users\HP\anaconda3\envs\FedLearnCD\Lib\multiprocessing\reduction.py", line 60, in dump
    ForkingPickler(file, protocol).dump(obj)
OSError: [Errno 22] Invalid argument

The above exception was the direct cause of the following exception:

[36mray::ClientAppActor.run()[39m (pid=6536, ip=127.0.0.1, actor_id=14f677eaa3c4366b55bf407501000000, repr=<flwr.simulation.ray_transport.ray_actor.ClientAppActor object at 0x000001D1AFF26290>)
  File "python\ray\_raylet.pyx", line 1881, in ray._raylet.execute_task
  File "python\ray\_raylet.pyx", line 1982, in ray._raylet.execute_task
  File "python\ray\_raylet.pyx", line 1887, in ray._raylet.execute_task
  File "python\ray\_raylet.pyx", line 1828, in ray._raylet.execute_task.function_executor
  File "C:\Users\HP\anaconda3\envs\FedLearnCD\Lib\site-packages\ray\_private\function_manager.py", line 691, in actor_method_executor
    return method(__ray_actor, *args, **kwargs)
           ^^^^^^^^^^^^^^^^^^^^^^^^^^^^^^^^^^^^
  File "C:\Users\HP\anaconda3\envs\FedLearnCD\Lib\site-packages\ray\util\tracing\tracing_helper.py", line 467, in _resume_span
    return method(self, *_args, **_kwargs)
           ^^^^^^^^^^^^^^^^^^^^^^^^^^^^^^^
  File "C:\Users\HP\anaconda3\envs\FedLearnCD\Lib\site-packages\flwr\simulation\ray_transport\ray_actor.py", line 64, in run
    raise ClientAppException(str(ex)) from ex
flwr.client.client_app.ClientAppException: 
Exception ClientAppException occurred. Message: [Errno 22] Invalid argument

[2024-05-04 19:08:30,621][flwr][ERROR] - [36mray::ClientAppActor.run()[39m (pid=6536, ip=127.0.0.1, actor_id=14f677eaa3c4366b55bf407501000000, repr=<flwr.simulation.ray_transport.ray_actor.ClientAppActor object at 0x000001D1AFF26290>)
                  ^^^^^^^^^^^^^^^^^^^^^^^^^^^^^^^^^^^^^
  File "C:\Users\HP\anaconda3\envs\FedLearnCD\Lib\site-packages\flwr\client\client_app.py", line 98, in __call__
    return self._call(message, context)
           ^^^^^^^^^^^^^^^^^^^^^^^^^^^^
  File "C:\Users\HP\anaconda3\envs\FedLearnCD\Lib\site-packages\flwr\client\client_app.py", line 81, in ffn
    out_message = handle_legacy_message_from_msgtype(
                  ^^^^^^^^^^^^^^^^^^^^^^^^^^^^^^^^^^^
  File "C:\Users\HP\anaconda3\envs\FedLearnCD\Lib\site-packages\flwr\client\message_handler\message_handler.py", line 137, in handle_legacy_message_from_msgtype
    evaluate_res = maybe_call_evaluate(
                   ^^^^^^^^^^^^^^^^^^^^
  File "C:\Users\HP\anaconda3\envs\FedLearnCD\Lib\site-packages\flwr\client\client.py", line 254, in maybe_call_evaluate
    return client.evaluate(evaluate_ins)
           ^^^^^^^^^^^^^^^^^^^^^^^^^^^^^
  File "C:\Users\HP\anaconda3\envs\FedLearnCD\Lib\site-packages\flwr\client\numpy_client.py", line 262, in _evaluate
    results = self.numpy_client.evaluate(parameters, ins.config)  # type: ignore
              ^^^^^^^^^^^^^^^^^^^^^^^^^^^^^^^^^^^^^^^^^^^^^^^^^^
  File "C:\Users\HP\Documents\FedAvgWithDrift\client.py", line 59, in evaluate
    loss, accuracy =  test(self.model, self.valloader, self.device)
                      ^^^^^^^^^^^^^^^^^^^^^^^^^^^^^^^^^^^^^^^^^^^^^
  File "C:\Users\HP\Documents\FedAvgWithDrift\model.py", line 50, in test
    for data in testloader:
  File "C:\Users\HP\anaconda3\envs\FedLearnCD\Lib\site-packages\torch\utils\data\dataloader.py", line 439, in __iter__
    return self._get_iterator()
           ^^^^^^^^^^^^^^^^^^^^
  File "C:\Users\HP\anaconda3\envs\FedLearnCD\Lib\site-packages\torch\utils\data\dataloader.py", line 387, in _get_iterator
    return _MultiProcessingDataLoaderIter(self)
           ^^^^^^^^^^^^^^^^^^^^^^^^^^^^^^^^^^^^
  File "C:\Users\HP\anaconda3\envs\FedLearnCD\Lib\site-packages\torch\utils\data\dataloader.py", line 1040, in __init__
    w.start()
  File "C:\Users\HP\anaconda3\envs\FedLearnCD\Lib\multiprocessing\process.py", line 121, in start
    self._popen = self._Popen(self)
                  ^^^^^^^^^^^^^^^^^
  File "C:\Users\HP\anaconda3\envs\FedLearnCD\Lib\multiprocessing\context.py", line 224, in _Popen
    return _default_context.get_context().Process._Popen(process_obj)
           ^^^^^^^^^^^^^^^^^^^^^^^^^^^^^^^^^^^^^^^^^^^^^^^^^^^^^^^^^^
  File "C:\Users\HP\anaconda3\envs\FedLearnCD\Lib\multiprocessing\context.py", line 336, in _Popen
    return Popen(process_obj)
           ^^^^^^^^^^^^^^^^^^
  File "C:\Users\HP\anaconda3\envs\FedLearnCD\Lib\multiprocessing\popen_spawn_win32.py", line 95, in __init__
    reduction.dump(process_obj, to_child)
  File "C:\Users\HP\anaconda3\envs\FedLearnCD\Lib\multiprocessing\reduction.py", line 60, in dump
    ForkingPickler(file, protocol).dump(obj)
OSError: [Errno 22] Invalid argument

The above exception was the direct cause of the following exception:

[36mray::ClientAppActor.run()[39m (pid=6536, ip=127.0.0.1, actor_id=14f677eaa3c4366b55bf407501000000, repr=<flwr.simulation.ray_transport.ray_actor.ClientAppActor object at 0x000001D1AFF26290>)
  File "python\ray\_raylet.pyx", line 1881, in ray._raylet.execute_task
  File "python\ray\_raylet.pyx", line 1982, in ray._raylet.execute_task
  File "python\ray\_raylet.pyx", line 1887, in ray._raylet.execute_task
  File "python\ray\_raylet.pyx", line 1828, in ray._raylet.execute_task.function_executor
  File "C:\Users\HP\anaconda3\envs\FedLearnCD\Lib\site-packages\ray\_private\function_manager.py", line 691, in actor_method_executor
    return method(__ray_actor, *args, **kwargs)
           ^^^^^^^^^^^^^^^^^^^^^^^^^^^^^^^^^^^^
  File "C:\Users\HP\anaconda3\envs\FedLearnCD\Lib\site-packages\ray\util\tracing\tracing_helper.py", line 467, in _resume_span
    return method(self, *_args, **_kwargs)
           ^^^^^^^^^^^^^^^^^^^^^^^^^^^^^^^
  File "C:\Users\HP\anaconda3\envs\FedLearnCD\Lib\site-packages\flwr\simulation\ray_transport\ray_actor.py", line 64, in run
    raise ClientAppException(str(ex)) from ex
flwr.client.client_app.ClientAppException: 
Exception ClientAppException occurred. Message: [Errno 22] Invalid argument
[2024-05-04 19:08:39,661][flwr][ERROR] - Traceback (most recent call last):
  File "C:\Users\HP\anaconda3\envs\FedLearnCD\Lib\site-packages\flwr\simulation\ray_transport\ray_client_proxy.py", line 73, in _submit_job
    out_mssg, updated_context = self.actor_pool.get_client_result(
                                ^^^^^^^^^^^^^^^^^^^^^^^^^^^^^^^^^^
  File "C:\Users\HP\anaconda3\envs\FedLearnCD\Lib\site-packages\flwr\simulation\ray_transport\ray_actor.py", line 399, in get_client_result
    return self._fetch_future_result(cid)
           ^^^^^^^^^^^^^^^^^^^^^^^^^^^^^^
  File "C:\Users\HP\anaconda3\envs\FedLearnCD\Lib\site-packages\flwr\simulation\ray_transport\ray_actor.py", line 280, in _fetch_future_result
    res_cid, out_mssg, updated_context = ray.get(
                                         ^^^^^^^^
  File "C:\Users\HP\anaconda3\envs\FedLearnCD\Lib\site-packages\ray\_private\auto_init_hook.py", line 21, in auto_init_wrapper
    return fn(*args, **kwargs)
           ^^^^^^^^^^^^^^^^^^^
  File "C:\Users\HP\anaconda3\envs\FedLearnCD\Lib\site-packages\ray\_private\client_mode_hook.py", line 103, in wrapper
    return func(*args, **kwargs)
           ^^^^^^^^^^^^^^^^^^^^^
  File "C:\Users\HP\anaconda3\envs\FedLearnCD\Lib\site-packages\ray\_private\worker.py", line 2623, in get
    values, debugger_breakpoint = worker.get_objects(object_refs, timeout=timeout)
                                  ^^^^^^^^^^^^^^^^^^^^^^^^^^^^^^^^^^^^^^^^^^^^^^^^
  File "C:\Users\HP\anaconda3\envs\FedLearnCD\Lib\site-packages\ray\_private\worker.py", line 861, in get_objects
    raise value.as_instanceof_cause()
ray.exceptions.RayTaskError(ClientAppException): [36mray::ClientAppActor.run()[39m (pid=5088, ip=127.0.0.1, actor_id=201d4d61ad7bdf07591019d601000000, repr=<flwr.simulation.ray_transport.ray_actor.ClientAppActor object at 0x0000021AFA356350>)
                  ^^^^^^^^^^^^^^^^^^^^^^^^^^^^^^^^^^^^^
  File "C:\Users\HP\anaconda3\envs\FedLearnCD\Lib\site-packages\flwr\client\client_app.py", line 98, in __call__
    return self._call(message, context)
           ^^^^^^^^^^^^^^^^^^^^^^^^^^^^
  File "C:\Users\HP\anaconda3\envs\FedLearnCD\Lib\site-packages\flwr\client\client_app.py", line 81, in ffn
    out_message = handle_legacy_message_from_msgtype(
                  ^^^^^^^^^^^^^^^^^^^^^^^^^^^^^^^^^^^
  File "C:\Users\HP\anaconda3\envs\FedLearnCD\Lib\site-packages\flwr\client\message_handler\message_handler.py", line 137, in handle_legacy_message_from_msgtype
    evaluate_res = maybe_call_evaluate(
                   ^^^^^^^^^^^^^^^^^^^^
  File "C:\Users\HP\anaconda3\envs\FedLearnCD\Lib\site-packages\flwr\client\client.py", line 254, in maybe_call_evaluate
    return client.evaluate(evaluate_ins)
           ^^^^^^^^^^^^^^^^^^^^^^^^^^^^^
  File "C:\Users\HP\anaconda3\envs\FedLearnCD\Lib\site-packages\flwr\client\numpy_client.py", line 262, in _evaluate
    results = self.numpy_client.evaluate(parameters, ins.config)  # type: ignore
              ^^^^^^^^^^^^^^^^^^^^^^^^^^^^^^^^^^^^^^^^^^^^^^^^^^
  File "C:\Users\HP\Documents\FedAvgWithDrift\client.py", line 61, in evaluate
    return float(loss), len(self.valloadders), {'accurcay':accuracy}
                            ^^^^^^^^^^^^^^^^
AttributeError: 'FlowerClient' object has no attribute 'valloadders'

The above exception was the direct cause of the following exception:

[36mray::ClientAppActor.run()[39m (pid=5088, ip=127.0.0.1, actor_id=201d4d61ad7bdf07591019d601000000, repr=<flwr.simulation.ray_transport.ray_actor.ClientAppActor object at 0x0000021AFA356350>)
  File "python\ray\_raylet.pyx", line 1881, in ray._raylet.execute_task
  File "python\ray\_raylet.pyx", line 1982, in ray._raylet.execute_task
  File "python\ray\_raylet.pyx", line 1887, in ray._raylet.execute_task
  File "python\ray\_raylet.pyx", line 1828, in ray._raylet.execute_task.function_executor
  File "C:\Users\HP\anaconda3\envs\FedLearnCD\Lib\site-packages\ray\_private\function_manager.py", line 691, in actor_method_executor
    return method(__ray_actor, *args, **kwargs)
           ^^^^^^^^^^^^^^^^^^^^^^^^^^^^^^^^^^^^
  File "C:\Users\HP\anaconda3\envs\FedLearnCD\Lib\site-packages\ray\util\tracing\tracing_helper.py", line 467, in _resume_span
    return method(self, *_args, **_kwargs)
           ^^^^^^^^^^^^^^^^^^^^^^^^^^^^^^^
  File "C:\Users\HP\anaconda3\envs\FedLearnCD\Lib\site-packages\flwr\simulation\ray_transport\ray_actor.py", line 64, in run
    raise ClientAppException(str(ex)) from ex
flwr.client.client_app.ClientAppException: 
Exception ClientAppException occurred. Message: 'FlowerClient' object has no attribute 'valloadders'

[2024-05-04 19:08:39,699][flwr][ERROR] - [36mray::ClientAppActor.run()[39m (pid=5088, ip=127.0.0.1, actor_id=201d4d61ad7bdf07591019d601000000, repr=<flwr.simulation.ray_transport.ray_actor.ClientAppActor object at 0x0000021AFA356350>)
                  ^^^^^^^^^^^^^^^^^^^^^^^^^^^^^^^^^^^^^
  File "C:\Users\HP\anaconda3\envs\FedLearnCD\Lib\site-packages\flwr\client\client_app.py", line 98, in __call__
    return self._call(message, context)
           ^^^^^^^^^^^^^^^^^^^^^^^^^^^^
  File "C:\Users\HP\anaconda3\envs\FedLearnCD\Lib\site-packages\flwr\client\client_app.py", line 81, in ffn
    out_message = handle_legacy_message_from_msgtype(
                  ^^^^^^^^^^^^^^^^^^^^^^^^^^^^^^^^^^^
  File "C:\Users\HP\anaconda3\envs\FedLearnCD\Lib\site-packages\flwr\client\message_handler\message_handler.py", line 137, in handle_legacy_message_from_msgtype
    evaluate_res = maybe_call_evaluate(
                   ^^^^^^^^^^^^^^^^^^^^
  File "C:\Users\HP\anaconda3\envs\FedLearnCD\Lib\site-packages\flwr\client\client.py", line 254, in maybe_call_evaluate
    return client.evaluate(evaluate_ins)
           ^^^^^^^^^^^^^^^^^^^^^^^^^^^^^
  File "C:\Users\HP\anaconda3\envs\FedLearnCD\Lib\site-packages\flwr\client\numpy_client.py", line 262, in _evaluate
    results = self.numpy_client.evaluate(parameters, ins.config)  # type: ignore
              ^^^^^^^^^^^^^^^^^^^^^^^^^^^^^^^^^^^^^^^^^^^^^^^^^^
  File "C:\Users\HP\Documents\FedAvgWithDrift\client.py", line 61, in evaluate
    return float(loss), len(self.valloadders), {'accurcay':accuracy}
                            ^^^^^^^^^^^^^^^^
AttributeError: 'FlowerClient' object has no attribute 'valloadders'

The above exception was the direct cause of the following exception:

[36mray::ClientAppActor.run()[39m (pid=5088, ip=127.0.0.1, actor_id=201d4d61ad7bdf07591019d601000000, repr=<flwr.simulation.ray_transport.ray_actor.ClientAppActor object at 0x0000021AFA356350>)
  File "python\ray\_raylet.pyx", line 1881, in ray._raylet.execute_task
  File "python\ray\_raylet.pyx", line 1982, in ray._raylet.execute_task
  File "python\ray\_raylet.pyx", line 1887, in ray._raylet.execute_task
  File "python\ray\_raylet.pyx", line 1828, in ray._raylet.execute_task.function_executor
  File "C:\Users\HP\anaconda3\envs\FedLearnCD\Lib\site-packages\ray\_private\function_manager.py", line 691, in actor_method_executor
    return method(__ray_actor, *args, **kwargs)
           ^^^^^^^^^^^^^^^^^^^^^^^^^^^^^^^^^^^^
  File "C:\Users\HP\anaconda3\envs\FedLearnCD\Lib\site-packages\ray\util\tracing\tracing_helper.py", line 467, in _resume_span
    return method(self, *_args, **_kwargs)
           ^^^^^^^^^^^^^^^^^^^^^^^^^^^^^^^
  File "C:\Users\HP\anaconda3\envs\FedLearnCD\Lib\site-packages\flwr\simulation\ray_transport\ray_actor.py", line 64, in run
    raise ClientAppException(str(ex)) from ex
flwr.client.client_app.ClientAppException: 
Exception ClientAppException occurred. Message: 'FlowerClient' object has no attribute 'valloadders'
[2024-05-04 19:08:42,099][flwr][ERROR] - Traceback (most recent call last):
  File "C:\Users\HP\anaconda3\envs\FedLearnCD\Lib\site-packages\flwr\simulation\ray_transport\ray_client_proxy.py", line 73, in _submit_job
    out_mssg, updated_context = self.actor_pool.get_client_result(
                                ^^^^^^^^^^^^^^^^^^^^^^^^^^^^^^^^^^
  File "C:\Users\HP\anaconda3\envs\FedLearnCD\Lib\site-packages\flwr\simulation\ray_transport\ray_actor.py", line 399, in get_client_result
    return self._fetch_future_result(cid)
           ^^^^^^^^^^^^^^^^^^^^^^^^^^^^^^
  File "C:\Users\HP\anaconda3\envs\FedLearnCD\Lib\site-packages\flwr\simulation\ray_transport\ray_actor.py", line 280, in _fetch_future_result
    res_cid, out_mssg, updated_context = ray.get(
                                         ^^^^^^^^
  File "C:\Users\HP\anaconda3\envs\FedLearnCD\Lib\site-packages\ray\_private\auto_init_hook.py", line 21, in auto_init_wrapper
    return fn(*args, **kwargs)
           ^^^^^^^^^^^^^^^^^^^
  File "C:\Users\HP\anaconda3\envs\FedLearnCD\Lib\site-packages\ray\_private\client_mode_hook.py", line 103, in wrapper
    return func(*args, **kwargs)
           ^^^^^^^^^^^^^^^^^^^^^
  File "C:\Users\HP\anaconda3\envs\FedLearnCD\Lib\site-packages\ray\_private\worker.py", line 2623, in get
    values, debugger_breakpoint = worker.get_objects(object_refs, timeout=timeout)
                                  ^^^^^^^^^^^^^^^^^^^^^^^^^^^^^^^^^^^^^^^^^^^^^^^^
  File "C:\Users\HP\anaconda3\envs\FedLearnCD\Lib\site-packages\ray\_private\worker.py", line 861, in get_objects
    raise value.as_instanceof_cause()
ray.exceptions.RayTaskError(ClientAppException): [36mray::ClientAppActor.run()[39m (pid=5092, ip=127.0.0.1, actor_id=7a73e292a6008c781ec56f8101000000, repr=<flwr.simulation.ray_transport.ray_actor.ClientAppActor object at 0x00000254ABDFFA10>)
                  ^^^^^^^^^^^^^^^^^^^^^^^^^^^^^^^^^^^^^
  File "C:\Users\HP\anaconda3\envs\FedLearnCD\Lib\site-packages\flwr\client\client_app.py", line 98, in __call__
    return self._call(message, context)
           ^^^^^^^^^^^^^^^^^^^^^^^^^^^^
  File "C:\Users\HP\anaconda3\envs\FedLearnCD\Lib\site-packages\flwr\client\client_app.py", line 81, in ffn
    out_message = handle_legacy_message_from_msgtype(
                  ^^^^^^^^^^^^^^^^^^^^^^^^^^^^^^^^^^^
  File "C:\Users\HP\anaconda3\envs\FedLearnCD\Lib\site-packages\flwr\client\message_handler\message_handler.py", line 137, in handle_legacy_message_from_msgtype
    evaluate_res = maybe_call_evaluate(
                   ^^^^^^^^^^^^^^^^^^^^
  File "C:\Users\HP\anaconda3\envs\FedLearnCD\Lib\site-packages\flwr\client\client.py", line 254, in maybe_call_evaluate
    return client.evaluate(evaluate_ins)
           ^^^^^^^^^^^^^^^^^^^^^^^^^^^^^
  File "C:\Users\HP\anaconda3\envs\FedLearnCD\Lib\site-packages\flwr\client\numpy_client.py", line 262, in _evaluate
    results = self.numpy_client.evaluate(parameters, ins.config)  # type: ignore
              ^^^^^^^^^^^^^^^^^^^^^^^^^^^^^^^^^^^^^^^^^^^^^^^^^^
  File "C:\Users\HP\Documents\FedAvgWithDrift\client.py", line 61, in evaluate
    return float(loss), len(self.valloadders), {'accurcay':accuracy}
                            ^^^^^^^^^^^^^^^^
AttributeError: 'FlowerClient' object has no attribute 'valloadders'

The above exception was the direct cause of the following exception:

[36mray::ClientAppActor.run()[39m (pid=5092, ip=127.0.0.1, actor_id=7a73e292a6008c781ec56f8101000000, repr=<flwr.simulation.ray_transport.ray_actor.ClientAppActor object at 0x00000254ABDFFA10>)
  File "python\ray\_raylet.pyx", line 1881, in ray._raylet.execute_task
  File "python\ray\_raylet.pyx", line 1982, in ray._raylet.execute_task
  File "python\ray\_raylet.pyx", line 1887, in ray._raylet.execute_task
  File "python\ray\_raylet.pyx", line 1828, in ray._raylet.execute_task.function_executor
  File "C:\Users\HP\anaconda3\envs\FedLearnCD\Lib\site-packages\ray\_private\function_manager.py", line 691, in actor_method_executor
    return method(__ray_actor, *args, **kwargs)
           ^^^^^^^^^^^^^^^^^^^^^^^^^^^^^^^^^^^^
  File "C:\Users\HP\anaconda3\envs\FedLearnCD\Lib\site-packages\ray\util\tracing\tracing_helper.py", line 467, in _resume_span
    return method(self, *_args, **_kwargs)
           ^^^^^^^^^^^^^^^^^^^^^^^^^^^^^^^
  File "C:\Users\HP\anaconda3\envs\FedLearnCD\Lib\site-packages\flwr\simulation\ray_transport\ray_actor.py", line 64, in run
    raise ClientAppException(str(ex)) from ex
flwr.client.client_app.ClientAppException: 
Exception ClientAppException occurred. Message: 'FlowerClient' object has no attribute 'valloadders'

[2024-05-04 19:08:42,123][flwr][ERROR] - [36mray::ClientAppActor.run()[39m (pid=5092, ip=127.0.0.1, actor_id=7a73e292a6008c781ec56f8101000000, repr=<flwr.simulation.ray_transport.ray_actor.ClientAppActor object at 0x00000254ABDFFA10>)
                  ^^^^^^^^^^^^^^^^^^^^^^^^^^^^^^^^^^^^^
  File "C:\Users\HP\anaconda3\envs\FedLearnCD\Lib\site-packages\flwr\client\client_app.py", line 98, in __call__
    return self._call(message, context)
           ^^^^^^^^^^^^^^^^^^^^^^^^^^^^
  File "C:\Users\HP\anaconda3\envs\FedLearnCD\Lib\site-packages\flwr\client\client_app.py", line 81, in ffn
    out_message = handle_legacy_message_from_msgtype(
                  ^^^^^^^^^^^^^^^^^^^^^^^^^^^^^^^^^^^
  File "C:\Users\HP\anaconda3\envs\FedLearnCD\Lib\site-packages\flwr\client\message_handler\message_handler.py", line 137, in handle_legacy_message_from_msgtype
    evaluate_res = maybe_call_evaluate(
                   ^^^^^^^^^^^^^^^^^^^^
  File "C:\Users\HP\anaconda3\envs\FedLearnCD\Lib\site-packages\flwr\client\client.py", line 254, in maybe_call_evaluate
    return client.evaluate(evaluate_ins)
           ^^^^^^^^^^^^^^^^^^^^^^^^^^^^^
  File "C:\Users\HP\anaconda3\envs\FedLearnCD\Lib\site-packages\flwr\client\numpy_client.py", line 262, in _evaluate
    results = self.numpy_client.evaluate(parameters, ins.config)  # type: ignore
              ^^^^^^^^^^^^^^^^^^^^^^^^^^^^^^^^^^^^^^^^^^^^^^^^^^
  File "C:\Users\HP\Documents\FedAvgWithDrift\client.py", line 61, in evaluate
    return float(loss), len(self.valloadders), {'accurcay':accuracy}
                            ^^^^^^^^^^^^^^^^
AttributeError: 'FlowerClient' object has no attribute 'valloadders'

The above exception was the direct cause of the following exception:

[36mray::ClientAppActor.run()[39m (pid=5092, ip=127.0.0.1, actor_id=7a73e292a6008c781ec56f8101000000, repr=<flwr.simulation.ray_transport.ray_actor.ClientAppActor object at 0x00000254ABDFFA10>)
  File "python\ray\_raylet.pyx", line 1881, in ray._raylet.execute_task
  File "python\ray\_raylet.pyx", line 1982, in ray._raylet.execute_task
  File "python\ray\_raylet.pyx", line 1887, in ray._raylet.execute_task
  File "python\ray\_raylet.pyx", line 1828, in ray._raylet.execute_task.function_executor
  File "C:\Users\HP\anaconda3\envs\FedLearnCD\Lib\site-packages\ray\_private\function_manager.py", line 691, in actor_method_executor
    return method(__ray_actor, *args, **kwargs)
           ^^^^^^^^^^^^^^^^^^^^^^^^^^^^^^^^^^^^
  File "C:\Users\HP\anaconda3\envs\FedLearnCD\Lib\site-packages\ray\util\tracing\tracing_helper.py", line 467, in _resume_span
    return method(self, *_args, **_kwargs)
           ^^^^^^^^^^^^^^^^^^^^^^^^^^^^^^^
  File "C:\Users\HP\anaconda3\envs\FedLearnCD\Lib\site-packages\flwr\simulation\ray_transport\ray_actor.py", line 64, in run
    raise ClientAppException(str(ex)) from ex
flwr.client.client_app.ClientAppException: 
Exception ClientAppException occurred. Message: 'FlowerClient' object has no attribute 'valloadders'
[2024-05-04 19:08:46,255][flwr][ERROR] - Traceback (most recent call last):
  File "C:\Users\HP\anaconda3\envs\FedLearnCD\Lib\site-packages\flwr\simulation\ray_transport\ray_client_proxy.py", line 73, in _submit_job
    out_mssg, updated_context = self.actor_pool.get_client_result(
                                ^^^^^^^^^^^^^^^^^^^^^^^^^^^^^^^^^^
  File "C:\Users\HP\anaconda3\envs\FedLearnCD\Lib\site-packages\flwr\simulation\ray_transport\ray_actor.py", line 399, in get_client_result
    return self._fetch_future_result(cid)
           ^^^^^^^^^^^^^^^^^^^^^^^^^^^^^^
  File "C:\Users\HP\anaconda3\envs\FedLearnCD\Lib\site-packages\flwr\simulation\ray_transport\ray_actor.py", line 280, in _fetch_future_result
    res_cid, out_mssg, updated_context = ray.get(
                                         ^^^^^^^^
  File "C:\Users\HP\anaconda3\envs\FedLearnCD\Lib\site-packages\ray\_private\auto_init_hook.py", line 21, in auto_init_wrapper
    return fn(*args, **kwargs)
           ^^^^^^^^^^^^^^^^^^^
  File "C:\Users\HP\anaconda3\envs\FedLearnCD\Lib\site-packages\ray\_private\client_mode_hook.py", line 103, in wrapper
    return func(*args, **kwargs)
           ^^^^^^^^^^^^^^^^^^^^^
  File "C:\Users\HP\anaconda3\envs\FedLearnCD\Lib\site-packages\ray\_private\worker.py", line 2623, in get
    values, debugger_breakpoint = worker.get_objects(object_refs, timeout=timeout)
                                  ^^^^^^^^^^^^^^^^^^^^^^^^^^^^^^^^^^^^^^^^^^^^^^^^
  File "C:\Users\HP\anaconda3\envs\FedLearnCD\Lib\site-packages\ray\_private\worker.py", line 861, in get_objects
    raise value.as_instanceof_cause()
ray.exceptions.RayTaskError(ClientAppException): [36mray::ClientAppActor.run()[39m (pid=6532, ip=127.0.0.1, actor_id=abb66b9749a687783d54edf901000000, repr=<flwr.simulation.ray_transport.ray_actor.ClientAppActor object at 0x000001DEE96B15D0>)
                  ^^^^^^^^^^^^^^^^^^^^^^^^^^^^^^^^^^^^^
  File "C:\Users\HP\anaconda3\envs\FedLearnCD\Lib\site-packages\flwr\client\client_app.py", line 98, in __call__
    return self._call(message, context)
           ^^^^^^^^^^^^^^^^^^^^^^^^^^^^
  File "C:\Users\HP\anaconda3\envs\FedLearnCD\Lib\site-packages\flwr\client\client_app.py", line 81, in ffn
    out_message = handle_legacy_message_from_msgtype(
                  ^^^^^^^^^^^^^^^^^^^^^^^^^^^^^^^^^^^
  File "C:\Users\HP\anaconda3\envs\FedLearnCD\Lib\site-packages\flwr\client\message_handler\message_handler.py", line 137, in handle_legacy_message_from_msgtype
    evaluate_res = maybe_call_evaluate(
                   ^^^^^^^^^^^^^^^^^^^^
  File "C:\Users\HP\anaconda3\envs\FedLearnCD\Lib\site-packages\flwr\client\client.py", line 254, in maybe_call_evaluate
    return client.evaluate(evaluate_ins)
           ^^^^^^^^^^^^^^^^^^^^^^^^^^^^^
  File "C:\Users\HP\anaconda3\envs\FedLearnCD\Lib\site-packages\flwr\client\numpy_client.py", line 262, in _evaluate
    results = self.numpy_client.evaluate(parameters, ins.config)  # type: ignore
              ^^^^^^^^^^^^^^^^^^^^^^^^^^^^^^^^^^^^^^^^^^^^^^^^^^
  File "C:\Users\HP\Documents\FedAvgWithDrift\client.py", line 61, in evaluate
    return float(loss), len(self.valloadders), {'accurcay':accuracy}
                            ^^^^^^^^^^^^^^^^
AttributeError: 'FlowerClient' object has no attribute 'valloadders'

The above exception was the direct cause of the following exception:

[36mray::ClientAppActor.run()[39m (pid=6532, ip=127.0.0.1, actor_id=abb66b9749a687783d54edf901000000, repr=<flwr.simulation.ray_transport.ray_actor.ClientAppActor object at 0x000001DEE96B15D0>)
  File "python\ray\_raylet.pyx", line 1881, in ray._raylet.execute_task
  File "python\ray\_raylet.pyx", line 1982, in ray._raylet.execute_task
  File "python\ray\_raylet.pyx", line 1887, in ray._raylet.execute_task
  File "python\ray\_raylet.pyx", line 1828, in ray._raylet.execute_task.function_executor
  File "C:\Users\HP\anaconda3\envs\FedLearnCD\Lib\site-packages\ray\_private\function_manager.py", line 691, in actor_method_executor
    return method(__ray_actor, *args, **kwargs)
           ^^^^^^^^^^^^^^^^^^^^^^^^^^^^^^^^^^^^
  File "C:\Users\HP\anaconda3\envs\FedLearnCD\Lib\site-packages\ray\util\tracing\tracing_helper.py", line 467, in _resume_span
    return method(self, *_args, **_kwargs)
           ^^^^^^^^^^^^^^^^^^^^^^^^^^^^^^^
  File "C:\Users\HP\anaconda3\envs\FedLearnCD\Lib\site-packages\flwr\simulation\ray_transport\ray_actor.py", line 64, in run
    raise ClientAppException(str(ex)) from ex
flwr.client.client_app.ClientAppException: 
Exception ClientAppException occurred. Message: 'FlowerClient' object has no attribute 'valloadders'

[2024-05-04 19:08:46,287][flwr][ERROR] - [36mray::ClientAppActor.run()[39m (pid=6532, ip=127.0.0.1, actor_id=abb66b9749a687783d54edf901000000, repr=<flwr.simulation.ray_transport.ray_actor.ClientAppActor object at 0x000001DEE96B15D0>)
                  ^^^^^^^^^^^^^^^^^^^^^^^^^^^^^^^^^^^^^
  File "C:\Users\HP\anaconda3\envs\FedLearnCD\Lib\site-packages\flwr\client\client_app.py", line 98, in __call__
    return self._call(message, context)
           ^^^^^^^^^^^^^^^^^^^^^^^^^^^^
  File "C:\Users\HP\anaconda3\envs\FedLearnCD\Lib\site-packages\flwr\client\client_app.py", line 81, in ffn
    out_message = handle_legacy_message_from_msgtype(
                  ^^^^^^^^^^^^^^^^^^^^^^^^^^^^^^^^^^^
  File "C:\Users\HP\anaconda3\envs\FedLearnCD\Lib\site-packages\flwr\client\message_handler\message_handler.py", line 137, in handle_legacy_message_from_msgtype
    evaluate_res = maybe_call_evaluate(
                   ^^^^^^^^^^^^^^^^^^^^
  File "C:\Users\HP\anaconda3\envs\FedLearnCD\Lib\site-packages\flwr\client\client.py", line 254, in maybe_call_evaluate
    return client.evaluate(evaluate_ins)
           ^^^^^^^^^^^^^^^^^^^^^^^^^^^^^
  File "C:\Users\HP\anaconda3\envs\FedLearnCD\Lib\site-packages\flwr\client\numpy_client.py", line 262, in _evaluate
    results = self.numpy_client.evaluate(parameters, ins.config)  # type: ignore
              ^^^^^^^^^^^^^^^^^^^^^^^^^^^^^^^^^^^^^^^^^^^^^^^^^^
  File "C:\Users\HP\Documents\FedAvgWithDrift\client.py", line 61, in evaluate
    return float(loss), len(self.valloadders), {'accurcay':accuracy}
                            ^^^^^^^^^^^^^^^^
AttributeError: 'FlowerClient' object has no attribute 'valloadders'

The above exception was the direct cause of the following exception:

[36mray::ClientAppActor.run()[39m (pid=6532, ip=127.0.0.1, actor_id=abb66b9749a687783d54edf901000000, repr=<flwr.simulation.ray_transport.ray_actor.ClientAppActor object at 0x000001DEE96B15D0>)
  File "python\ray\_raylet.pyx", line 1881, in ray._raylet.execute_task
  File "python\ray\_raylet.pyx", line 1982, in ray._raylet.execute_task
  File "python\ray\_raylet.pyx", line 1887, in ray._raylet.execute_task
  File "python\ray\_raylet.pyx", line 1828, in ray._raylet.execute_task.function_executor
  File "C:\Users\HP\anaconda3\envs\FedLearnCD\Lib\site-packages\ray\_private\function_manager.py", line 691, in actor_method_executor
    return method(__ray_actor, *args, **kwargs)
           ^^^^^^^^^^^^^^^^^^^^^^^^^^^^^^^^^^^^
  File "C:\Users\HP\anaconda3\envs\FedLearnCD\Lib\site-packages\ray\util\tracing\tracing_helper.py", line 467, in _resume_span
    return method(self, *_args, **_kwargs)
           ^^^^^^^^^^^^^^^^^^^^^^^^^^^^^^^
  File "C:\Users\HP\anaconda3\envs\FedLearnCD\Lib\site-packages\flwr\simulation\ray_transport\ray_actor.py", line 64, in run
    raise ClientAppException(str(ex)) from ex
flwr.client.client_app.ClientAppException: 
Exception ClientAppException occurred. Message: 'FlowerClient' object has no attribute 'valloadders'
[2024-05-04 19:08:52,518][flwr][ERROR] - Traceback (most recent call last):
  File "C:\Users\HP\anaconda3\envs\FedLearnCD\Lib\site-packages\flwr\simulation\ray_transport\ray_client_proxy.py", line 73, in _submit_job
    out_mssg, updated_context = self.actor_pool.get_client_result(
                                ^^^^^^^^^^^^^^^^^^^^^^^^^^^^^^^^^^
  File "C:\Users\HP\anaconda3\envs\FedLearnCD\Lib\site-packages\flwr\simulation\ray_transport\ray_actor.py", line 399, in get_client_result
    return self._fetch_future_result(cid)
           ^^^^^^^^^^^^^^^^^^^^^^^^^^^^^^
  File "C:\Users\HP\anaconda3\envs\FedLearnCD\Lib\site-packages\flwr\simulation\ray_transport\ray_actor.py", line 280, in _fetch_future_result
    res_cid, out_mssg, updated_context = ray.get(
                                         ^^^^^^^^
  File "C:\Users\HP\anaconda3\envs\FedLearnCD\Lib\site-packages\ray\_private\auto_init_hook.py", line 21, in auto_init_wrapper
    return fn(*args, **kwargs)
           ^^^^^^^^^^^^^^^^^^^
  File "C:\Users\HP\anaconda3\envs\FedLearnCD\Lib\site-packages\ray\_private\client_mode_hook.py", line 103, in wrapper
    return func(*args, **kwargs)
           ^^^^^^^^^^^^^^^^^^^^^
  File "C:\Users\HP\anaconda3\envs\FedLearnCD\Lib\site-packages\ray\_private\worker.py", line 2623, in get
    values, debugger_breakpoint = worker.get_objects(object_refs, timeout=timeout)
                                  ^^^^^^^^^^^^^^^^^^^^^^^^^^^^^^^^^^^^^^^^^^^^^^^^
  File "C:\Users\HP\anaconda3\envs\FedLearnCD\Lib\site-packages\ray\_private\worker.py", line 861, in get_objects
    raise value.as_instanceof_cause()
ray.exceptions.RayTaskError(ClientAppException): [36mray::ClientAppActor.run()[39m (pid=15152, ip=127.0.0.1, actor_id=71dd2c767790f01f0571c8c701000000, repr=<flwr.simulation.ray_transport.ray_actor.ClientAppActor object at 0x000001CAD7736850>)
                  ^^^^^^^^^^^^^^^^^^^^^^^^^^^^^^^^^^^^^
  File "C:\Users\HP\anaconda3\envs\FedLearnCD\Lib\site-packages\flwr\client\client_app.py", line 98, in __call__
    return self._call(message, context)
           ^^^^^^^^^^^^^^^^^^^^^^^^^^^^
  File "C:\Users\HP\anaconda3\envs\FedLearnCD\Lib\site-packages\flwr\client\client_app.py", line 81, in ffn
    out_message = handle_legacy_message_from_msgtype(
                  ^^^^^^^^^^^^^^^^^^^^^^^^^^^^^^^^^^^
  File "C:\Users\HP\anaconda3\envs\FedLearnCD\Lib\site-packages\flwr\client\message_handler\message_handler.py", line 137, in handle_legacy_message_from_msgtype
    evaluate_res = maybe_call_evaluate(
                   ^^^^^^^^^^^^^^^^^^^^
  File "C:\Users\HP\anaconda3\envs\FedLearnCD\Lib\site-packages\flwr\client\client.py", line 254, in maybe_call_evaluate
    return client.evaluate(evaluate_ins)
           ^^^^^^^^^^^^^^^^^^^^^^^^^^^^^
  File "C:\Users\HP\anaconda3\envs\FedLearnCD\Lib\site-packages\flwr\client\numpy_client.py", line 262, in _evaluate
    results = self.numpy_client.evaluate(parameters, ins.config)  # type: ignore
              ^^^^^^^^^^^^^^^^^^^^^^^^^^^^^^^^^^^^^^^^^^^^^^^^^^
  File "C:\Users\HP\Documents\FedAvgWithDrift\client.py", line 61, in evaluate
    return float(loss), len(self.valloadders), {'accurcay':accuracy}
                            ^^^^^^^^^^^^^^^^
AttributeError: 'FlowerClient' object has no attribute 'valloadders'

The above exception was the direct cause of the following exception:

[36mray::ClientAppActor.run()[39m (pid=15152, ip=127.0.0.1, actor_id=71dd2c767790f01f0571c8c701000000, repr=<flwr.simulation.ray_transport.ray_actor.ClientAppActor object at 0x000001CAD7736850>)
  File "python\ray\_raylet.pyx", line 1881, in ray._raylet.execute_task
  File "python\ray\_raylet.pyx", line 1982, in ray._raylet.execute_task
  File "python\ray\_raylet.pyx", line 1887, in ray._raylet.execute_task
  File "python\ray\_raylet.pyx", line 1828, in ray._raylet.execute_task.function_executor
  File "C:\Users\HP\anaconda3\envs\FedLearnCD\Lib\site-packages\ray\_private\function_manager.py", line 691, in actor_method_executor
    return method(__ray_actor, *args, **kwargs)
           ^^^^^^^^^^^^^^^^^^^^^^^^^^^^^^^^^^^^
  File "C:\Users\HP\anaconda3\envs\FedLearnCD\Lib\site-packages\ray\util\tracing\tracing_helper.py", line 467, in _resume_span
    return method(self, *_args, **_kwargs)
           ^^^^^^^^^^^^^^^^^^^^^^^^^^^^^^^
  File "C:\Users\HP\anaconda3\envs\FedLearnCD\Lib\site-packages\flwr\simulation\ray_transport\ray_actor.py", line 64, in run
    raise ClientAppException(str(ex)) from ex
flwr.client.client_app.ClientAppException: 
Exception ClientAppException occurred. Message: 'FlowerClient' object has no attribute 'valloadders'

[2024-05-04 19:08:52,532][flwr][ERROR] - [36mray::ClientAppActor.run()[39m (pid=15152, ip=127.0.0.1, actor_id=71dd2c767790f01f0571c8c701000000, repr=<flwr.simulation.ray_transport.ray_actor.ClientAppActor object at 0x000001CAD7736850>)
                  ^^^^^^^^^^^^^^^^^^^^^^^^^^^^^^^^^^^^^
  File "C:\Users\HP\anaconda3\envs\FedLearnCD\Lib\site-packages\flwr\client\client_app.py", line 98, in __call__
    return self._call(message, context)
           ^^^^^^^^^^^^^^^^^^^^^^^^^^^^
  File "C:\Users\HP\anaconda3\envs\FedLearnCD\Lib\site-packages\flwr\client\client_app.py", line 81, in ffn
    out_message = handle_legacy_message_from_msgtype(
                  ^^^^^^^^^^^^^^^^^^^^^^^^^^^^^^^^^^^
  File "C:\Users\HP\anaconda3\envs\FedLearnCD\Lib\site-packages\flwr\client\message_handler\message_handler.py", line 137, in handle_legacy_message_from_msgtype
    evaluate_res = maybe_call_evaluate(
                   ^^^^^^^^^^^^^^^^^^^^
  File "C:\Users\HP\anaconda3\envs\FedLearnCD\Lib\site-packages\flwr\client\client.py", line 254, in maybe_call_evaluate
    return client.evaluate(evaluate_ins)
           ^^^^^^^^^^^^^^^^^^^^^^^^^^^^^
  File "C:\Users\HP\anaconda3\envs\FedLearnCD\Lib\site-packages\flwr\client\numpy_client.py", line 262, in _evaluate
    results = self.numpy_client.evaluate(parameters, ins.config)  # type: ignore
              ^^^^^^^^^^^^^^^^^^^^^^^^^^^^^^^^^^^^^^^^^^^^^^^^^^
  File "C:\Users\HP\Documents\FedAvgWithDrift\client.py", line 61, in evaluate
    return float(loss), len(self.valloadders), {'accurcay':accuracy}
                            ^^^^^^^^^^^^^^^^
AttributeError: 'FlowerClient' object has no attribute 'valloadders'

The above exception was the direct cause of the following exception:

[36mray::ClientAppActor.run()[39m (pid=15152, ip=127.0.0.1, actor_id=71dd2c767790f01f0571c8c701000000, repr=<flwr.simulation.ray_transport.ray_actor.ClientAppActor object at 0x000001CAD7736850>)
  File "python\ray\_raylet.pyx", line 1881, in ray._raylet.execute_task
  File "python\ray\_raylet.pyx", line 1982, in ray._raylet.execute_task
  File "python\ray\_raylet.pyx", line 1887, in ray._raylet.execute_task
  File "python\ray\_raylet.pyx", line 1828, in ray._raylet.execute_task.function_executor
  File "C:\Users\HP\anaconda3\envs\FedLearnCD\Lib\site-packages\ray\_private\function_manager.py", line 691, in actor_method_executor
    return method(__ray_actor, *args, **kwargs)
           ^^^^^^^^^^^^^^^^^^^^^^^^^^^^^^^^^^^^
  File "C:\Users\HP\anaconda3\envs\FedLearnCD\Lib\site-packages\ray\util\tracing\tracing_helper.py", line 467, in _resume_span
    return method(self, *_args, **_kwargs)
           ^^^^^^^^^^^^^^^^^^^^^^^^^^^^^^^
  File "C:\Users\HP\anaconda3\envs\FedLearnCD\Lib\site-packages\flwr\simulation\ray_transport\ray_actor.py", line 64, in run
    raise ClientAppException(str(ex)) from ex
flwr.client.client_app.ClientAppException: 
Exception ClientAppException occurred. Message: 'FlowerClient' object has no attribute 'valloadders'
[2024-05-04 19:08:52,543][flwr][INFO] - aggregate_evaluate: received 0 results and 5 failures
[2024-05-04 19:08:52,543][flwr][INFO] - 
[2024-05-04 19:08:52,546][flwr][INFO] - [ROUND 5]
[2024-05-04 19:08:52,547][flwr][INFO] - Sampling failed: number of available clients (5) is less than number of requested clients (10).
[2024-05-04 19:08:52,548][flwr][INFO] - configure_fit: no clients selected, cancel
[2024-05-04 19:08:58,091][flwr][INFO] - fit progress: (5, 182.11450600624084, {'accuracy': 0.1}, 221.3606235000043)
[2024-05-04 19:08:58,091][flwr][INFO] - configure_evaluate: strategy sampled 5 clients (out of 5)
